[2025-08-09 17:27:41 +0000] [14] [INFO] Starting gunicorn 20.1.0
[2025-08-09 17:27:41 +0000] [14] [INFO] Listening at: http://0.0.0.0:8000 (14)
[2025-08-09 17:27:41 +0000] [14] [INFO] Using worker: sync
[2025-08-09 17:27:41 +0000] [15] [INFO] Booting worker with pid: 15
[2025-08-09 17:27:41 +0000] [15] [ERROR] Exception in worker process
Traceback (most recent call last):
  File "/usr/local/lib/python3.10/site-packages/gunicorn/arbiter.py", line 589, in spawn_worker
    worker.init_process()
  File "/usr/local/lib/python3.10/site-packages/gunicorn/workers/base.py", line 134, in init_process
    self.load_wsgi()
  File "/usr/local/lib/python3.10/site-packages/gunicorn/workers/base.py", line 146, in load_wsgi
    self.wsgi = self.app.wsgi()
  File "/usr/local/lib/python3.10/site-packages/gunicorn/app/base.py", line 67, in wsgi
    self.callable = self.load()
  File "/usr/local/lib/python3.10/site-packages/gunicorn/app/wsgiapp.py", line 58, in load
    return self.load_wsgiapp()
  File "/usr/local/lib/python3.10/site-packages/gunicorn/app/wsgiapp.py", line 48, in load_wsgiapp
    return util.import_app(self.app_uri)
  File "/usr/local/lib/python3.10/site-packages/gunicorn/util.py", line 359, in import_app
    mod = importlib.import_module(module)
  File "/usr/local/lib/python3.10/importlib/__init__.py", line 126, in import_module
    return _bootstrap._gcd_import(name[level:], package, level)
  File "<frozen importlib._bootstrap>", line 1050, in _gcd_import
  File "<frozen importlib._bootstrap>", line 1027, in _find_and_load
  File "<frozen importlib._bootstrap>", line 992, in _find_and_load_unlocked
  File "<frozen importlib._bootstrap>", line 241, in _call_with_frames_removed
  File "<frozen importlib._bootstrap>", line 1050, in _gcd_import
  File "<frozen importlib._bootstrap>", line 1027, in _find_and_load
  File "<frozen importlib._bootstrap>", line 1004, in _find_and_load_unlocked
ModuleNotFoundError: No module named 'dashboard'
[2025-08-09 17:27:41 +0000] [15] [INFO] Worker exiting (pid: 15)
[2025-08-09 17:27:41 +0000] [14] [INFO] Shutting down: Master
[2025-08-09 17:27:41 +0000] [14] [INFO] Reason: Worker failed to boot.
[2025-08-09 17:27:42 +0000] [16] [INFO] Starting gunicorn 20.1.0
[2025-08-09 17:27:42 +0000] [16] [INFO] Listening at: http://0.0.0.0:8000 (16)
[2025-08-09 17:27:42 +0000] [16] [INFO] Using worker: sync
[2025-08-09 17:27:42 +0000] [17] [INFO] Booting worker with pid: 17
[2025-08-09 17:27:42 +0000] [17] [ERROR] Exception in worker process
Traceback (most recent call last):
  File "/usr/local/lib/python3.10/site-packages/gunicorn/arbiter.py", line 589, in spawn_worker
    worker.init_process()
  File "/usr/local/lib/python3.10/site-packages/gunicorn/workers/base.py", line 134, in init_process
    self.load_wsgi()
  File "/usr/local/lib/python3.10/site-packages/gunicorn/workers/base.py", line 146, in load_wsgi
    self.wsgi = self.app.wsgi()
  File "/usr/local/lib/python3.10/site-packages/gunicorn/app/base.py", line 67, in wsgi
    self.callable = self.load()
  File "/usr/local/lib/python3.10/site-packages/gunicorn/app/wsgiapp.py", line 58, in load
    return self.load_wsgiapp()
  File "/usr/local/lib/python3.10/site-packages/gunicorn/app/wsgiapp.py", line 48, in load_wsgiapp
    return util.import_app(self.app_uri)
  File "/usr/local/lib/python3.10/site-packages/gunicorn/util.py", line 359, in import_app
    mod = importlib.import_module(module)
  File "/usr/local/lib/python3.10/importlib/__init__.py", line 126, in import_module
    return _bootstrap._gcd_import(name[level:], package, level)
  File "<frozen importlib._bootstrap>", line 1050, in _gcd_import
  File "<frozen importlib._bootstrap>", line 1027, in _find_and_load
  File "<frozen importlib._bootstrap>", line 992, in _find_and_load_unlocked
  File "<frozen importlib._bootstrap>", line 241, in _call_with_frames_removed
  File "<frozen importlib._bootstrap>", line 1050, in _gcd_import
  File "<frozen importlib._bootstrap>", line 1027, in _find_and_load
  File "<frozen importlib._bootstrap>", line 1004, in _find_and_load_unlocked
ModuleNotFoundError: No module named 'dashboard'
[2025-08-09 17:27:42 +0000] [17] [INFO] Worker exiting (pid: 17)
[2025-08-09 17:27:42 +0000] [16] [INFO] Shutting down: Master
[2025-08-09 17:27:42 +0000] [16] [INFO] Reason: Worker failed to boot.
[2025-08-09 17:27:44 +0000] [18] [INFO] Starting gunicorn 20.1.0
[2025-08-09 17:27:44 +0000] [18] [INFO] Listening at: http://0.0.0.0:8000 (18)
[2025-08-09 17:27:44 +0000] [18] [INFO] Using worker: sync
[2025-08-09 17:27:44 +0000] [19] [INFO] Booting worker with pid: 19
[2025-08-09 17:27:44 +0000] [19] [ERROR] Exception in worker process
Traceback (most recent call last):
  File "/usr/local/lib/python3.10/site-packages/gunicorn/arbiter.py", line 589, in spawn_worker
    worker.init_process()
  File "/usr/local/lib/python3.10/site-packages/gunicorn/workers/base.py", line 134, in init_process
    self.load_wsgi()
  File "/usr/local/lib/python3.10/site-packages/gunicorn/workers/base.py", line 146, in load_wsgi
    self.wsgi = self.app.wsgi()
  File "/usr/local/lib/python3.10/site-packages/gunicorn/app/base.py", line 67, in wsgi
    self.callable = self.load()
  File "/usr/local/lib/python3.10/site-packages/gunicorn/app/wsgiapp.py", line 58, in load
    return self.load_wsgiapp()
  File "/usr/local/lib/python3.10/site-packages/gunicorn/app/wsgiapp.py", line 48, in load_wsgiapp
    return util.import_app(self.app_uri)
  File "/usr/local/lib/python3.10/site-packages/gunicorn/util.py", line 359, in import_app
    mod = importlib.import_module(module)
  File "/usr/local/lib/python3.10/importlib/__init__.py", line 126, in import_module
    return _bootstrap._gcd_import(name[level:], package, level)
  File "<frozen importlib._bootstrap>", line 1050, in _gcd_import
  File "<frozen importlib._bootstrap>", line 1027, in _find_and_load
  File "<frozen importlib._bootstrap>", line 992, in _find_and_load_unlocked
  File "<frozen importlib._bootstrap>", line 241, in _call_with_frames_removed
  File "<frozen importlib._bootstrap>", line 1050, in _gcd_import
  File "<frozen importlib._bootstrap>", line 1027, in _find_and_load
  File "<frozen importlib._bootstrap>", line 1004, in _find_and_load_unlocked
ModuleNotFoundError: No module named 'dashboard'
[2025-08-09 17:27:44 +0000] [19] [INFO] Worker exiting (pid: 19)
[2025-08-09 17:27:44 +0000] [20] [INFO] Booting worker with pid: 20
[2025-08-09 17:27:44 +0000] [20] [ERROR] Exception in worker process
Traceback (most recent call last):
  File "/usr/local/lib/python3.10/site-packages/gunicorn/arbiter.py", line 589, in spawn_worker
    worker.init_process()
  File "/usr/local/lib/python3.10/site-packages/gunicorn/workers/base.py", line 134, in init_process
    self.load_wsgi()
  File "/usr/local/lib/python3.10/site-packages/gunicorn/workers/base.py", line 146, in load_wsgi
    self.wsgi = self.app.wsgi()
  File "/usr/local/lib/python3.10/site-packages/gunicorn/app/base.py", line 67, in wsgi
    self.callable = self.load()
  File "/usr/local/lib/python3.10/site-packages/gunicorn/app/wsgiapp.py", line 58, in load
    return self.load_wsgiapp()
  File "/usr/local/lib/python3.10/site-packages/gunicorn/app/wsgiapp.py", line 48, in load_wsgiapp
    return util.import_app(self.app_uri)
  File "/usr/local/lib/python3.10/site-packages/gunicorn/util.py", line 359, in import_app
    mod = importlib.import_module(module)
  File "/usr/local/lib/python3.10/importlib/__init__.py", line 126, in import_module
    return _bootstrap._gcd_import(name[level:], package, level)
  File "<frozen importlib._bootstrap>", line 1050, in _gcd_import
  File "<frozen importlib._bootstrap>", line 1027, in _find_and_load
  File "<frozen importlib._bootstrap>", line 992, in _find_and_load_unlocked
  File "<frozen importlib._bootstrap>", line 241, in _call_with_frames_removed
  File "<frozen importlib._bootstrap>", line 1050, in _gcd_import
  File "<frozen importlib._bootstrap>", line 1027, in _find_and_load
  File "<frozen importlib._bootstrap>", line 1004, in _find_and_load_unlocked
ModuleNotFoundError: No module named 'dashboard'
[2025-08-09 17:27:44 +0000] [20] [INFO] Worker exiting (pid: 20)
[2025-08-09 17:27:44 +0000] [18] [WARNING] Worker with pid 20 was terminated due to signal 15
[2025-08-09 17:27:44 +0000] [18] [INFO] Shutting down: Master
[2025-08-09 17:27:44 +0000] [18] [INFO] Reason: Worker failed to boot.
[2025-08-09 17:27:48 +0000] [21] [INFO] Starting gunicorn 20.1.0
[2025-08-09 17:27:48 +0000] [21] [INFO] Listening at: http://0.0.0.0:8000 (21)
[2025-08-09 17:27:48 +0000] [21] [INFO] Using worker: sync
[2025-08-09 17:27:48 +0000] [22] [INFO] Booting worker with pid: 22
[2025-08-09 17:27:48 +0000] [22] [ERROR] Exception in worker process
Traceback (most recent call last):
  File "/usr/local/lib/python3.10/site-packages/gunicorn/arbiter.py", line 589, in spawn_worker
    worker.init_process()
  File "/usr/local/lib/python3.10/site-packages/gunicorn/workers/base.py", line 134, in init_process
    self.load_wsgi()
  File "/usr/local/lib/python3.10/site-packages/gunicorn/workers/base.py", line 146, in load_wsgi
    self.wsgi = self.app.wsgi()
  File "/usr/local/lib/python3.10/site-packages/gunicorn/app/base.py", line 67, in wsgi
    self.callable = self.load()
  File "/usr/local/lib/python3.10/site-packages/gunicorn/app/wsgiapp.py", line 58, in load
    return self.load_wsgiapp()
  File "/usr/local/lib/python3.10/site-packages/gunicorn/app/wsgiapp.py", line 48, in load_wsgiapp
    return util.import_app(self.app_uri)
  File "/usr/local/lib/python3.10/site-packages/gunicorn/util.py", line 359, in import_app
    mod = importlib.import_module(module)
  File "/usr/local/lib/python3.10/importlib/__init__.py", line 126, in import_module
    return _bootstrap._gcd_import(name[level:], package, level)
  File "<frozen importlib._bootstrap>", line 1050, in _gcd_import
  File "<frozen importlib._bootstrap>", line 1027, in _find_and_load
  File "<frozen importlib._bootstrap>", line 992, in _find_and_load_unlocked
  File "<frozen importlib._bootstrap>", line 241, in _call_with_frames_removed
  File "<frozen importlib._bootstrap>", line 1050, in _gcd_import
  File "<frozen importlib._bootstrap>", line 1027, in _find_and_load
  File "<frozen importlib._bootstrap>", line 1004, in _find_and_load_unlocked
ModuleNotFoundError: No module named 'dashboard'
[2025-08-09 17:27:48 +0000] [22] [INFO] Worker exiting (pid: 22)
[2025-08-09 17:27:48 +0000] [23] [INFO] Booting worker with pid: 23
[2025-08-09 17:27:48 +0000] [23] [ERROR] Exception in worker process
Traceback (most recent call last):
  File "/usr/local/lib/python3.10/site-packages/gunicorn/arbiter.py", line 589, in spawn_worker
    worker.init_process()
  File "/usr/local/lib/python3.10/site-packages/gunicorn/workers/base.py", line 134, in init_process
    self.load_wsgi()
  File "/usr/local/lib/python3.10/site-packages/gunicorn/workers/base.py", line 146, in load_wsgi
    self.wsgi = self.app.wsgi()
  File "/usr/local/lib/python3.10/site-packages/gunicorn/app/base.py", line 67, in wsgi
    self.callable = self.load()
  File "/usr/local/lib/python3.10/site-packages/gunicorn/app/wsgiapp.py", line 58, in load
    return self.load_wsgiapp()
  File "/usr/local/lib/python3.10/site-packages/gunicorn/app/wsgiapp.py", line 48, in load_wsgiapp
    return util.import_app(self.app_uri)
  File "/usr/local/lib/python3.10/site-packages/gunicorn/util.py", line 359, in import_app
    mod = importlib.import_module(module)
  File "/usr/local/lib/python3.10/importlib/__init__.py", line 126, in import_module
    return _bootstrap._gcd_import(name[level:], package, level)
  File "<frozen importlib._bootstrap>", line 1050, in _gcd_import
  File "<frozen importlib._bootstrap>", line 1027, in _find_and_load
  File "<frozen importlib._bootstrap>", line 992, in _find_and_load_unlocked
  File "<frozen importlib._bootstrap>", line 241, in _call_with_frames_removed
  File "<frozen importlib._bootstrap>", line 1050, in _gcd_import
  File "<frozen importlib._bootstrap>", line 1027, in _find_and_load
  File "<frozen importlib._bootstrap>", line 1004, in _find_and_load_unlocked
ModuleNotFoundError: No module named 'dashboard'
[2025-08-09 17:27:48 +0000] [23] [INFO] Worker exiting (pid: 23)
[2025-08-09 17:27:48 +0000] [21] [WARNING] Worker with pid 23 was terminated due to signal 15
[2025-08-09 17:27:48 +0000] [21] [INFO] Shutting down: Master
[2025-08-09 17:27:48 +0000] [21] [INFO] Reason: Worker failed to boot.
[2025-08-09 17:29:44 +0000] [10] [INFO] Starting gunicorn 20.1.0
[2025-08-09 17:29:44 +0000] [10] [INFO] Listening at: http://0.0.0.0:8000 (10)
[2025-08-09 17:29:44 +0000] [10] [INFO] Using worker: sync
[2025-08-09 17:29:44 +0000] [11] [INFO] Booting worker with pid: 11
[2025-08-09 17:29:44 +0000] [12] [INFO] Booting worker with pid: 12
[2025-08-09 14:30:56 -0300] [12] [INFO] Worker reloading: /app/src/apps/core/models.py modified
[2025-08-09 14:30:56 -0300] [12] [INFO] Worker exiting (pid: 12)
[2025-08-09 14:30:56 -0300] [11] [INFO] Worker reloading: /app/src/apps/core/models.py modified
[2025-08-09 14:30:56 -0300] [11] [INFO] Worker exiting (pid: 11)
[2025-08-09 17:30:56 +0000] [15] [INFO] Booting worker with pid: 15
[2025-08-09 17:30:56 +0000] [16] [INFO] Booting worker with pid: 16
[2025-08-09 14:31:02 -0300] [15] [INFO] Worker reloading: /app/src/apps/core/models.py modified
[2025-08-09 14:31:02 -0300] [15] [INFO] Worker exiting (pid: 15)
[2025-08-09 14:31:02 -0300] [16] [INFO] Worker reloading: /app/src/apps/core/models.py modified
[2025-08-09 14:31:02 -0300] [16] [INFO] Worker exiting (pid: 16)
[2025-08-09 17:31:02 +0000] [19] [INFO] Booting worker with pid: 19
[2025-08-09 17:31:02 +0000] [20] [INFO] Booting worker with pid: 20
[2025-08-09 14:31:02 -0300] [19] [ERROR] Exception in worker process
Traceback (most recent call last):
  File "/usr/local/lib/python3.10/site-packages/gunicorn/arbiter.py", line 589, in spawn_worker
    worker.init_process()
  File "/usr/local/lib/python3.10/site-packages/gunicorn/workers/base.py", line 134, in init_process
    self.load_wsgi()
  File "/usr/local/lib/python3.10/site-packages/gunicorn/workers/base.py", line 146, in load_wsgi
    self.wsgi = self.app.wsgi()
  File "/usr/local/lib/python3.10/site-packages/gunicorn/app/base.py", line 67, in wsgi
    self.callable = self.load()
  File "/usr/local/lib/python3.10/site-packages/gunicorn/app/wsgiapp.py", line 58, in load
    return self.load_wsgiapp()
  File "/usr/local/lib/python3.10/site-packages/gunicorn/app/wsgiapp.py", line 48, in load_wsgiapp
    return util.import_app(self.app_uri)
  File "/usr/local/lib/python3.10/site-packages/gunicorn/util.py", line 359, in import_app
    mod = importlib.import_module(module)
  File "/usr/local/lib/python3.10/importlib/__init__.py", line 126, in import_module
    return _bootstrap._gcd_import(name[level:], package, level)
  File "<frozen importlib._bootstrap>", line 1050, in _gcd_import
  File "<frozen importlib._bootstrap>", line 1027, in _find_and_load
  File "<frozen importlib._bootstrap>", line 1006, in _find_and_load_unlocked
  File "<frozen importlib._bootstrap>", line 688, in _load_unlocked
  File "<frozen importlib._bootstrap_external>", line 883, in exec_module
  File "<frozen importlib._bootstrap>", line 241, in _call_with_frames_removed
  File "/app/src/zeppelin/wsgi.py", line 16, in <module>
    application = get_wsgi_application()
  File "/usr/local/lib/python3.10/site-packages/django/core/wsgi.py", line 12, in get_wsgi_application
    django.setup(set_prefix=False)
  File "/usr/local/lib/python3.10/site-packages/django/__init__.py", line 24, in setup
    apps.populate(settings.INSTALLED_APPS)
  File "/usr/local/lib/python3.10/site-packages/django/apps/registry.py", line 116, in populate
    app_config.import_models()
  File "/usr/local/lib/python3.10/site-packages/django/apps/config.py", line 269, in import_models
    self.models_module = import_module(models_module_name)
  File "/usr/local/lib/python3.10/importlib/__init__.py", line 126, in import_module
    return _bootstrap._gcd_import(name[level:], package, level)
  File "<frozen importlib._bootstrap>", line 1050, in _gcd_import
  File "<frozen importlib._bootstrap>", line 1027, in _find_and_load
  File "<frozen importlib._bootstrap>", line 1006, in _find_and_load_unlocked
  File "<frozen importlib._bootstrap>", line 688, in _load_unlocked
  File "<frozen importlib._bootstrap_external>", line 883, in exec_module
  File "<frozen importlib._bootstrap>", line 241, in _call_with_frames_removed
  File "/app/src/apps/core/models.py", line 18, in <module>
    class Base(Historical):
  File "/usr/local/lib/python3.10/site-packages/polymorphic/base.py", line 74, in __new__
    new_class = self.call_superclass_new_method(model_name, bases, attrs, **kwargs)
  File "/usr/local/lib/python3.10/site-packages/polymorphic/base.py", line 114, in call_superclass_new_method
    new_class = super().__new__(self, model_name, bases, attrs, **kwargs)
  File "/usr/local/lib/python3.10/site-packages/django/db/models/base.py", line 261, in __new__
    raise FieldError(
django.core.exceptions.FieldError: Local field 'create_at' in class 'Base' clashes with field of the same name from base class 'Historical'.
[2025-08-09 14:31:02 -0300] [19] [INFO] Worker exiting (pid: 19)
[2025-08-09 14:31:02 -0300] [20] [ERROR] Exception in worker process
Traceback (most recent call last):
  File "/usr/local/lib/python3.10/site-packages/gunicorn/arbiter.py", line 589, in spawn_worker
    worker.init_process()
  File "/usr/local/lib/python3.10/site-packages/gunicorn/workers/base.py", line 134, in init_process
    self.load_wsgi()
  File "/usr/local/lib/python3.10/site-packages/gunicorn/workers/base.py", line 146, in load_wsgi
    self.wsgi = self.app.wsgi()
  File "/usr/local/lib/python3.10/site-packages/gunicorn/app/base.py", line 67, in wsgi
    self.callable = self.load()
  File "/usr/local/lib/python3.10/site-packages/gunicorn/app/wsgiapp.py", line 58, in load
    return self.load_wsgiapp()
  File "/usr/local/lib/python3.10/site-packages/gunicorn/app/wsgiapp.py", line 48, in load_wsgiapp
    return util.import_app(self.app_uri)
  File "/usr/local/lib/python3.10/site-packages/gunicorn/util.py", line 359, in import_app
    mod = importlib.import_module(module)
  File "/usr/local/lib/python3.10/importlib/__init__.py", line 126, in import_module
    return _bootstrap._gcd_import(name[level:], package, level)
  File "<frozen importlib._bootstrap>", line 1050, in _gcd_import
  File "<frozen importlib._bootstrap>", line 1027, in _find_and_load
  File "<frozen importlib._bootstrap>", line 1006, in _find_and_load_unlocked
  File "<frozen importlib._bootstrap>", line 688, in _load_unlocked
  File "<frozen importlib._bootstrap_external>", line 883, in exec_module
  File "<frozen importlib._bootstrap>", line 241, in _call_with_frames_removed
  File "/app/src/zeppelin/wsgi.py", line 16, in <module>
    application = get_wsgi_application()
  File "/usr/local/lib/python3.10/site-packages/django/core/wsgi.py", line 12, in get_wsgi_application
    django.setup(set_prefix=False)
  File "/usr/local/lib/python3.10/site-packages/django/__init__.py", line 24, in setup
    apps.populate(settings.INSTALLED_APPS)
  File "/usr/local/lib/python3.10/site-packages/django/apps/registry.py", line 116, in populate
    app_config.import_models()
  File "/usr/local/lib/python3.10/site-packages/django/apps/config.py", line 269, in import_models
    self.models_module = import_module(models_module_name)
  File "/usr/local/lib/python3.10/importlib/__init__.py", line 126, in import_module
    return _bootstrap._gcd_import(name[level:], package, level)
  File "<frozen importlib._bootstrap>", line 1050, in _gcd_import
  File "<frozen importlib._bootstrap>", line 1027, in _find_and_load
  File "<frozen importlib._bootstrap>", line 1006, in _find_and_load_unlocked
  File "<frozen importlib._bootstrap>", line 688, in _load_unlocked
  File "<frozen importlib._bootstrap_external>", line 883, in exec_module
  File "<frozen importlib._bootstrap>", line 241, in _call_with_frames_removed
  File "/app/src/apps/core/models.py", line 18, in <module>
    class Base(Historical):
  File "/usr/local/lib/python3.10/site-packages/polymorphic/base.py", line 74, in __new__
    new_class = self.call_superclass_new_method(model_name, bases, attrs, **kwargs)
  File "/usr/local/lib/python3.10/site-packages/polymorphic/base.py", line 114, in call_superclass_new_method
    new_class = super().__new__(self, model_name, bases, attrs, **kwargs)
  File "/usr/local/lib/python3.10/site-packages/django/db/models/base.py", line 261, in __new__
    raise FieldError(
django.core.exceptions.FieldError: Local field 'create_at' in class 'Base' clashes with field of the same name from base class 'Historical'.
[2025-08-09 14:31:02 -0300] [20] [INFO] Worker exiting (pid: 20)
[2025-08-09 17:31:02 +0000] [10] [WARNING] Worker with pid 20 was terminated due to signal 15
[2025-08-09 17:31:02 +0000] [10] [INFO] Shutting down: Master
[2025-08-09 17:31:02 +0000] [10] [INFO] Reason: Worker failed to boot.
[2025-08-09 17:31:04 +0000] [21] [INFO] Starting gunicorn 20.1.0
[2025-08-09 17:31:04 +0000] [21] [INFO] Listening at: http://0.0.0.0:8000 (21)
[2025-08-09 17:31:04 +0000] [21] [INFO] Using worker: sync
[2025-08-09 17:31:04 +0000] [22] [INFO] Booting worker with pid: 22
[2025-08-09 17:31:04 +0000] [23] [INFO] Booting worker with pid: 23
[2025-08-09 14:31:04 -0300] [22] [ERROR] Exception in worker process
Traceback (most recent call last):
  File "/usr/local/lib/python3.10/site-packages/gunicorn/arbiter.py", line 589, in spawn_worker
    worker.init_process()
  File "/usr/local/lib/python3.10/site-packages/gunicorn/workers/base.py", line 134, in init_process
    self.load_wsgi()
  File "/usr/local/lib/python3.10/site-packages/gunicorn/workers/base.py", line 146, in load_wsgi
    self.wsgi = self.app.wsgi()
  File "/usr/local/lib/python3.10/site-packages/gunicorn/app/base.py", line 67, in wsgi
    self.callable = self.load()
  File "/usr/local/lib/python3.10/site-packages/gunicorn/app/wsgiapp.py", line 58, in load
    return self.load_wsgiapp()
  File "/usr/local/lib/python3.10/site-packages/gunicorn/app/wsgiapp.py", line 48, in load_wsgiapp
    return util.import_app(self.app_uri)
  File "/usr/local/lib/python3.10/site-packages/gunicorn/util.py", line 359, in import_app
    mod = importlib.import_module(module)
  File "/usr/local/lib/python3.10/importlib/__init__.py", line 126, in import_module
    return _bootstrap._gcd_import(name[level:], package, level)
  File "<frozen importlib._bootstrap>", line 1050, in _gcd_import
  File "<frozen importlib._bootstrap>", line 1027, in _find_and_load
  File "<frozen importlib._bootstrap>", line 1006, in _find_and_load_unlocked
  File "<frozen importlib._bootstrap>", line 688, in _load_unlocked
  File "<frozen importlib._bootstrap_external>", line 883, in exec_module
  File "<frozen importlib._bootstrap>", line 241, in _call_with_frames_removed
  File "/app/src/zeppelin/wsgi.py", line 16, in <module>
    application = get_wsgi_application()
  File "/usr/local/lib/python3.10/site-packages/django/core/wsgi.py", line 12, in get_wsgi_application
    django.setup(set_prefix=False)
  File "/usr/local/lib/python3.10/site-packages/django/__init__.py", line 24, in setup
    apps.populate(settings.INSTALLED_APPS)
  File "/usr/local/lib/python3.10/site-packages/django/apps/registry.py", line 116, in populate
    app_config.import_models()
  File "/usr/local/lib/python3.10/site-packages/django/apps/config.py", line 269, in import_models
    self.models_module = import_module(models_module_name)
  File "/usr/local/lib/python3.10/importlib/__init__.py", line 126, in import_module
    return _bootstrap._gcd_import(name[level:], package, level)
  File "<frozen importlib._bootstrap>", line 1050, in _gcd_import
  File "<frozen importlib._bootstrap>", line 1027, in _find_and_load
  File "<frozen importlib._bootstrap>", line 1006, in _find_and_load_unlocked
  File "<frozen importlib._bootstrap>", line 688, in _load_unlocked
  File "<frozen importlib._bootstrap_external>", line 883, in exec_module
  File "<frozen importlib._bootstrap>", line 241, in _call_with_frames_removed
  File "/app/src/apps/core/models.py", line 18, in <module>
    class Base(Historical):
  File "/usr/local/lib/python3.10/site-packages/polymorphic/base.py", line 74, in __new__
    new_class = self.call_superclass_new_method(model_name, bases, attrs, **kwargs)
  File "/usr/local/lib/python3.10/site-packages/polymorphic/base.py", line 114, in call_superclass_new_method
    new_class = super().__new__(self, model_name, bases, attrs, **kwargs)
  File "/usr/local/lib/python3.10/site-packages/django/db/models/base.py", line 261, in __new__
    raise FieldError(
django.core.exceptions.FieldError: Local field 'create_at' in class 'Base' clashes with field of the same name from base class 'Historical'.
[2025-08-09 14:31:04 -0300] [22] [INFO] Worker exiting (pid: 22)
[2025-08-09 14:31:04 -0300] [23] [ERROR] Exception in worker process
Traceback (most recent call last):
  File "/usr/local/lib/python3.10/site-packages/gunicorn/arbiter.py", line 589, in spawn_worker
    worker.init_process()
  File "/usr/local/lib/python3.10/site-packages/gunicorn/workers/base.py", line 134, in init_process
    self.load_wsgi()
  File "/usr/local/lib/python3.10/site-packages/gunicorn/workers/base.py", line 146, in load_wsgi
    self.wsgi = self.app.wsgi()
  File "/usr/local/lib/python3.10/site-packages/gunicorn/app/base.py", line 67, in wsgi
    self.callable = self.load()
  File "/usr/local/lib/python3.10/site-packages/gunicorn/app/wsgiapp.py", line 58, in load
    return self.load_wsgiapp()
  File "/usr/local/lib/python3.10/site-packages/gunicorn/app/wsgiapp.py", line 48, in load_wsgiapp
    return util.import_app(self.app_uri)
  File "/usr/local/lib/python3.10/site-packages/gunicorn/util.py", line 359, in import_app
    mod = importlib.import_module(module)
  File "/usr/local/lib/python3.10/importlib/__init__.py", line 126, in import_module
    return _bootstrap._gcd_import(name[level:], package, level)
  File "<frozen importlib._bootstrap>", line 1050, in _gcd_import
  File "<frozen importlib._bootstrap>", line 1027, in _find_and_load
  File "<frozen importlib._bootstrap>", line 1006, in _find_and_load_unlocked
  File "<frozen importlib._bootstrap>", line 688, in _load_unlocked
  File "<frozen importlib._bootstrap_external>", line 883, in exec_module
  File "<frozen importlib._bootstrap>", line 241, in _call_with_frames_removed
  File "/app/src/zeppelin/wsgi.py", line 16, in <module>
    application = get_wsgi_application()
  File "/usr/local/lib/python3.10/site-packages/django/core/wsgi.py", line 12, in get_wsgi_application
    django.setup(set_prefix=False)
  File "/usr/local/lib/python3.10/site-packages/django/__init__.py", line 24, in setup
    apps.populate(settings.INSTALLED_APPS)
  File "/usr/local/lib/python3.10/site-packages/django/apps/registry.py", line 116, in populate
    app_config.import_models()
  File "/usr/local/lib/python3.10/site-packages/django/apps/config.py", line 269, in import_models
    self.models_module = import_module(models_module_name)
  File "/usr/local/lib/python3.10/importlib/__init__.py", line 126, in import_module
    return _bootstrap._gcd_import(name[level:], package, level)
  File "<frozen importlib._bootstrap>", line 1050, in _gcd_import
  File "<frozen importlib._bootstrap>", line 1027, in _find_and_load
  File "<frozen importlib._bootstrap>", line 1006, in _find_and_load_unlocked
  File "<frozen importlib._bootstrap>", line 688, in _load_unlocked
  File "<frozen importlib._bootstrap_external>", line 883, in exec_module
  File "<frozen importlib._bootstrap>", line 241, in _call_with_frames_removed
  File "/app/src/apps/core/models.py", line 18, in <module>
    class Base(Historical):
  File "/usr/local/lib/python3.10/site-packages/polymorphic/base.py", line 74, in __new__
    new_class = self.call_superclass_new_method(model_name, bases, attrs, **kwargs)
  File "/usr/local/lib/python3.10/site-packages/polymorphic/base.py", line 114, in call_superclass_new_method
    new_class = super().__new__(self, model_name, bases, attrs, **kwargs)
  File "/usr/local/lib/python3.10/site-packages/django/db/models/base.py", line 261, in __new__
    raise FieldError(
django.core.exceptions.FieldError: Local field 'create_at' in class 'Base' clashes with field of the same name from base class 'Historical'.
[2025-08-09 14:31:04 -0300] [23] [INFO] Worker exiting (pid: 23)
Traceback (most recent call last):
  File "/usr/local/lib/python3.10/site-packages/gunicorn/arbiter.py", line 209, in run
    self.sleep()
  File "/usr/local/lib/python3.10/site-packages/gunicorn/arbiter.py", line 357, in sleep
    ready = select.select([self.PIPE[0]], [], [], 1.0)
  File "/usr/local/lib/python3.10/site-packages/gunicorn/arbiter.py", line 242, in handle_chld
    self.reap_workers()
  File "/usr/local/lib/python3.10/site-packages/gunicorn/arbiter.py", line 525, in reap_workers
    raise HaltServer(reason, self.WORKER_BOOT_ERROR)
gunicorn.errors.HaltServer: <HaltServer 'Worker failed to boot.' 3>

During handling of the above exception, another exception occurred:

Traceback (most recent call last):
  File "/usr/local/bin/gunicorn", line 8, in <module>
    sys.exit(run())
  File "/usr/local/lib/python3.10/site-packages/gunicorn/app/wsgiapp.py", line 67, in run
    WSGIApplication("%(prog)s [OPTIONS] [APP_MODULE]").run()
  File "/usr/local/lib/python3.10/site-packages/gunicorn/app/base.py", line 231, in run
    super().run()
  File "/usr/local/lib/python3.10/site-packages/gunicorn/app/base.py", line 72, in run
    Arbiter(self).run()
  File "/usr/local/lib/python3.10/site-packages/gunicorn/arbiter.py", line 229, in run
    self.halt(reason=inst.reason, exit_status=inst.exit_status)
  File "/usr/local/lib/python3.10/site-packages/gunicorn/arbiter.py", line 342, in halt
    self.stop()
  File "/usr/local/lib/python3.10/site-packages/gunicorn/arbiter.py", line 393, in stop
    time.sleep(0.1)
  File "/usr/local/lib/python3.10/site-packages/gunicorn/arbiter.py", line 242, in handle_chld
    self.reap_workers()
  File "/usr/local/lib/python3.10/site-packages/gunicorn/arbiter.py", line 525, in reap_workers
    raise HaltServer(reason, self.WORKER_BOOT_ERROR)
gunicorn.errors.HaltServer: <HaltServer 'Worker failed to boot.' 3>
[2025-08-09 17:31:05 +0000] [24] [INFO] Starting gunicorn 20.1.0
[2025-08-09 17:31:05 +0000] [24] [INFO] Listening at: http://0.0.0.0:8000 (24)
[2025-08-09 17:31:05 +0000] [24] [INFO] Using worker: sync
[2025-08-09 17:31:05 +0000] [25] [INFO] Booting worker with pid: 25
[2025-08-09 17:31:05 +0000] [26] [INFO] Booting worker with pid: 26
[2025-08-09 14:31:06 -0300] [25] [ERROR] Exception in worker process
Traceback (most recent call last):
  File "/usr/local/lib/python3.10/site-packages/gunicorn/arbiter.py", line 589, in spawn_worker
    worker.init_process()
  File "/usr/local/lib/python3.10/site-packages/gunicorn/workers/base.py", line 134, in init_process
    self.load_wsgi()
  File "/usr/local/lib/python3.10/site-packages/gunicorn/workers/base.py", line 146, in load_wsgi
    self.wsgi = self.app.wsgi()
  File "/usr/local/lib/python3.10/site-packages/gunicorn/app/base.py", line 67, in wsgi
    self.callable = self.load()
  File "/usr/local/lib/python3.10/site-packages/gunicorn/app/wsgiapp.py", line 58, in load
    return self.load_wsgiapp()
  File "/usr/local/lib/python3.10/site-packages/gunicorn/app/wsgiapp.py", line 48, in load_wsgiapp
    return util.import_app(self.app_uri)
  File "/usr/local/lib/python3.10/site-packages/gunicorn/util.py", line 359, in import_app
    mod = importlib.import_module(module)
  File "/usr/local/lib/python3.10/importlib/__init__.py", line 126, in import_module
    return _bootstrap._gcd_import(name[level:], package, level)
  File "<frozen importlib._bootstrap>", line 1050, in _gcd_import
  File "<frozen importlib._bootstrap>", line 1027, in _find_and_load
  File "<frozen importlib._bootstrap>", line 1006, in _find_and_load_unlocked
  File "<frozen importlib._bootstrap>", line 688, in _load_unlocked
  File "<frozen importlib._bootstrap_external>", line 883, in exec_module
  File "<frozen importlib._bootstrap>", line 241, in _call_with_frames_removed
  File "/app/src/zeppelin/wsgi.py", line 16, in <module>
    application = get_wsgi_application()
  File "/usr/local/lib/python3.10/site-packages/django/core/wsgi.py", line 12, in get_wsgi_application
    django.setup(set_prefix=False)
  File "/usr/local/lib/python3.10/site-packages/django/__init__.py", line 24, in setup
    apps.populate(settings.INSTALLED_APPS)
  File "/usr/local/lib/python3.10/site-packages/django/apps/registry.py", line 116, in populate
    app_config.import_models()
  File "/usr/local/lib/python3.10/site-packages/django/apps/config.py", line 269, in import_models
    self.models_module = import_module(models_module_name)
  File "/usr/local/lib/python3.10/importlib/__init__.py", line 126, in import_module
    return _bootstrap._gcd_import(name[level:], package, level)
  File "<frozen importlib._bootstrap>", line 1050, in _gcd_import
  File "<frozen importlib._bootstrap>", line 1027, in _find_and_load
  File "<frozen importlib._bootstrap>", line 1006, in _find_and_load_unlocked
  File "<frozen importlib._bootstrap>", line 688, in _load_unlocked
  File "<frozen importlib._bootstrap_external>", line 883, in exec_module
  File "<frozen importlib._bootstrap>", line 241, in _call_with_frames_removed
  File "/app/src/apps/core/models.py", line 18, in <module>
    class Base(Historical):
  File "/usr/local/lib/python3.10/site-packages/polymorphic/base.py", line 74, in __new__
    new_class = self.call_superclass_new_method(model_name, bases, attrs, **kwargs)
  File "/usr/local/lib/python3.10/site-packages/polymorphic/base.py", line 114, in call_superclass_new_method
    new_class = super().__new__(self, model_name, bases, attrs, **kwargs)
  File "/usr/local/lib/python3.10/site-packages/django/db/models/base.py", line 261, in __new__
    raise FieldError(
django.core.exceptions.FieldError: Local field 'create_at' in class 'Base' clashes with field of the same name from base class 'Historical'.
[2025-08-09 14:31:06 -0300] [25] [INFO] Worker exiting (pid: 25)
[2025-08-09 14:31:06 -0300] [26] [ERROR] Exception in worker process
Traceback (most recent call last):
  File "/usr/local/lib/python3.10/site-packages/gunicorn/arbiter.py", line 589, in spawn_worker
    worker.init_process()
  File "/usr/local/lib/python3.10/site-packages/gunicorn/workers/base.py", line 134, in init_process
    self.load_wsgi()
  File "/usr/local/lib/python3.10/site-packages/gunicorn/workers/base.py", line 146, in load_wsgi
    self.wsgi = self.app.wsgi()
  File "/usr/local/lib/python3.10/site-packages/gunicorn/app/base.py", line 67, in wsgi
    self.callable = self.load()
  File "/usr/local/lib/python3.10/site-packages/gunicorn/app/wsgiapp.py", line 58, in load
    return self.load_wsgiapp()
  File "/usr/local/lib/python3.10/site-packages/gunicorn/app/wsgiapp.py", line 48, in load_wsgiapp
    return util.import_app(self.app_uri)
  File "/usr/local/lib/python3.10/site-packages/gunicorn/util.py", line 359, in import_app
    mod = importlib.import_module(module)
  File "/usr/local/lib/python3.10/importlib/__init__.py", line 126, in import_module
    return _bootstrap._gcd_import(name[level:], package, level)
  File "<frozen importlib._bootstrap>", line 1050, in _gcd_import
  File "<frozen importlib._bootstrap>", line 1027, in _find_and_load
  File "<frozen importlib._bootstrap>", line 1006, in _find_and_load_unlocked
  File "<frozen importlib._bootstrap>", line 688, in _load_unlocked
  File "<frozen importlib._bootstrap_external>", line 883, in exec_module
  File "<frozen importlib._bootstrap>", line 241, in _call_with_frames_removed
  File "/app/src/zeppelin/wsgi.py", line 16, in <module>
    application = get_wsgi_application()
  File "/usr/local/lib/python3.10/site-packages/django/core/wsgi.py", line 12, in get_wsgi_application
    django.setup(set_prefix=False)
  File "/usr/local/lib/python3.10/site-packages/django/__init__.py", line 24, in setup
    apps.populate(settings.INSTALLED_APPS)
  File "/usr/local/lib/python3.10/site-packages/django/apps/registry.py", line 116, in populate
    app_config.import_models()
  File "/usr/local/lib/python3.10/site-packages/django/apps/config.py", line 269, in import_models
    self.models_module = import_module(models_module_name)
  File "/usr/local/lib/python3.10/importlib/__init__.py", line 126, in import_module
    return _bootstrap._gcd_import(name[level:], package, level)
  File "<frozen importlib._bootstrap>", line 1050, in _gcd_import
  File "<frozen importlib._bootstrap>", line 1027, in _find_and_load
  File "<frozen importlib._bootstrap>", line 1006, in _find_and_load_unlocked
  File "<frozen importlib._bootstrap>", line 688, in _load_unlocked
  File "<frozen importlib._bootstrap_external>", line 883, in exec_module
  File "<frozen importlib._bootstrap>", line 241, in _call_with_frames_removed
  File "/app/src/apps/core/models.py", line 18, in <module>
    class Base(Historical):
  File "/usr/local/lib/python3.10/site-packages/polymorphic/base.py", line 74, in __new__
    new_class = self.call_superclass_new_method(model_name, bases, attrs, **kwargs)
  File "/usr/local/lib/python3.10/site-packages/polymorphic/base.py", line 114, in call_superclass_new_method
    new_class = super().__new__(self, model_name, bases, attrs, **kwargs)
  File "/usr/local/lib/python3.10/site-packages/django/db/models/base.py", line 261, in __new__
    raise FieldError(
django.core.exceptions.FieldError: Local field 'create_at' in class 'Base' clashes with field of the same name from base class 'Historical'.
[2025-08-09 14:31:06 -0300] [26] [INFO] Worker exiting (pid: 26)
[2025-08-09 17:31:06 +0000] [24] [WARNING] Worker with pid 26 was terminated due to signal 15
[2025-08-09 17:31:06 +0000] [24] [INFO] Shutting down: Master
[2025-08-09 17:31:06 +0000] [24] [INFO] Reason: Worker failed to boot.
[2025-08-09 17:31:08 +0000] [27] [INFO] Starting gunicorn 20.1.0
[2025-08-09 17:31:08 +0000] [27] [INFO] Listening at: http://0.0.0.0:8000 (27)
[2025-08-09 17:31:08 +0000] [27] [INFO] Using worker: sync
[2025-08-09 17:31:08 +0000] [28] [INFO] Booting worker with pid: 28
[2025-08-09 17:31:08 +0000] [29] [INFO] Booting worker with pid: 29
[2025-08-09 14:31:22 -0300] [28] [INFO] Worker reloading: /app/src/apps/core/models.py modified
[2025-08-09 14:31:22 -0300] [28] [INFO] Worker exiting (pid: 28)
[2025-08-09 14:31:22 -0300] [29] [INFO] Worker reloading: /app/src/apps/core/models.py modified
[2025-08-09 14:31:22 -0300] [29] [INFO] Worker exiting (pid: 29)
[2025-08-09 17:31:22 +0000] [32] [INFO] Booting worker with pid: 32
[2025-08-09 17:31:22 +0000] [33] [INFO] Booting worker with pid: 33
[2025-08-09 14:31:22 -0300] [32] [ERROR] unexpected indent (models.py, line 23)
Traceback (most recent call last):
  File "/usr/local/lib/python3.10/site-packages/gunicorn/workers/base.py", line 146, in load_wsgi
    self.wsgi = self.app.wsgi()
  File "/usr/local/lib/python3.10/site-packages/gunicorn/app/base.py", line 67, in wsgi
    self.callable = self.load()
  File "/usr/local/lib/python3.10/site-packages/gunicorn/app/wsgiapp.py", line 58, in load
    return self.load_wsgiapp()
  File "/usr/local/lib/python3.10/site-packages/gunicorn/app/wsgiapp.py", line 48, in load_wsgiapp
    return util.import_app(self.app_uri)
  File "/usr/local/lib/python3.10/site-packages/gunicorn/util.py", line 359, in import_app
    mod = importlib.import_module(module)
  File "/usr/local/lib/python3.10/importlib/__init__.py", line 126, in import_module
    return _bootstrap._gcd_import(name[level:], package, level)
  File "<frozen importlib._bootstrap>", line 1050, in _gcd_import
  File "<frozen importlib._bootstrap>", line 1027, in _find_and_load
  File "<frozen importlib._bootstrap>", line 1006, in _find_and_load_unlocked
  File "<frozen importlib._bootstrap>", line 688, in _load_unlocked
  File "<frozen importlib._bootstrap_external>", line 883, in exec_module
  File "<frozen importlib._bootstrap>", line 241, in _call_with_frames_removed
  File "/app/src/zeppelin/wsgi.py", line 16, in <module>
    application = get_wsgi_application()
  File "/usr/local/lib/python3.10/site-packages/django/core/wsgi.py", line 12, in get_wsgi_application
    django.setup(set_prefix=False)
  File "/usr/local/lib/python3.10/site-packages/django/__init__.py", line 24, in setup
    apps.populate(settings.INSTALLED_APPS)
  File "/usr/local/lib/python3.10/site-packages/django/apps/registry.py", line 116, in populate
    app_config.import_models()
  File "/usr/local/lib/python3.10/site-packages/django/apps/config.py", line 269, in import_models
    self.models_module = import_module(models_module_name)
  File "/usr/local/lib/python3.10/importlib/__init__.py", line 126, in import_module
    return _bootstrap._gcd_import(name[level:], package, level)
  File "<frozen importlib._bootstrap>", line 1050, in _gcd_import
  File "<frozen importlib._bootstrap>", line 1027, in _find_and_load
  File "<frozen importlib._bootstrap>", line 1006, in _find_and_load_unlocked
  File "<frozen importlib._bootstrap>", line 688, in _load_unlocked
  File "<frozen importlib._bootstrap_external>", line 879, in exec_module
  File "<frozen importlib._bootstrap_external>", line 1017, in get_code
  File "<frozen importlib._bootstrap_external>", line 947, in source_to_code
  File "<frozen importlib._bootstrap>", line 241, in _call_with_frames_removed
  File "/app/src/apps/core/models.py", line 23
    created_at = models.DateTimeField(auto_now_add=True)  # melhor que blank=True
IndentationError: unexpected indent
[2025-08-09 14:31:22 -0300] [33] [ERROR] unexpected indent (models.py, line 23)
Traceback (most recent call last):
  File "/usr/local/lib/python3.10/site-packages/gunicorn/workers/base.py", line 146, in load_wsgi
    self.wsgi = self.app.wsgi()
  File "/usr/local/lib/python3.10/site-packages/gunicorn/app/base.py", line 67, in wsgi
    self.callable = self.load()
  File "/usr/local/lib/python3.10/site-packages/gunicorn/app/wsgiapp.py", line 58, in load
    return self.load_wsgiapp()
  File "/usr/local/lib/python3.10/site-packages/gunicorn/app/wsgiapp.py", line 48, in load_wsgiapp
    return util.import_app(self.app_uri)
  File "/usr/local/lib/python3.10/site-packages/gunicorn/util.py", line 359, in import_app
    mod = importlib.import_module(module)
  File "/usr/local/lib/python3.10/importlib/__init__.py", line 126, in import_module
    return _bootstrap._gcd_import(name[level:], package, level)
  File "<frozen importlib._bootstrap>", line 1050, in _gcd_import
  File "<frozen importlib._bootstrap>", line 1027, in _find_and_load
  File "<frozen importlib._bootstrap>", line 1006, in _find_and_load_unlocked
  File "<frozen importlib._bootstrap>", line 688, in _load_unlocked
  File "<frozen importlib._bootstrap_external>", line 883, in exec_module
  File "<frozen importlib._bootstrap>", line 241, in _call_with_frames_removed
  File "/app/src/zeppelin/wsgi.py", line 16, in <module>
    application = get_wsgi_application()
  File "/usr/local/lib/python3.10/site-packages/django/core/wsgi.py", line 12, in get_wsgi_application
    django.setup(set_prefix=False)
  File "/usr/local/lib/python3.10/site-packages/django/__init__.py", line 24, in setup
    apps.populate(settings.INSTALLED_APPS)
  File "/usr/local/lib/python3.10/site-packages/django/apps/registry.py", line 116, in populate
    app_config.import_models()
  File "/usr/local/lib/python3.10/site-packages/django/apps/config.py", line 269, in import_models
    self.models_module = import_module(models_module_name)
  File "/usr/local/lib/python3.10/importlib/__init__.py", line 126, in import_module
    return _bootstrap._gcd_import(name[level:], package, level)
  File "<frozen importlib._bootstrap>", line 1050, in _gcd_import
  File "<frozen importlib._bootstrap>", line 1027, in _find_and_load
  File "<frozen importlib._bootstrap>", line 1006, in _find_and_load_unlocked
  File "<frozen importlib._bootstrap>", line 688, in _load_unlocked
  File "<frozen importlib._bootstrap_external>", line 879, in exec_module
  File "<frozen importlib._bootstrap_external>", line 1017, in get_code
  File "<frozen importlib._bootstrap_external>", line 947, in source_to_code
  File "<frozen importlib._bootstrap>", line 241, in _call_with_frames_removed
  File "/app/src/apps/core/models.py", line 23
    created_at = models.DateTimeField(auto_now_add=True)  # melhor que blank=True
IndentationError: unexpected indent
[2025-08-09 14:31:24 -0300] [32] [INFO] Worker reloading: /app/src/apps/core/models.py modified
[2025-08-09 14:31:24 -0300] [32] [INFO] Worker exiting (pid: 32)
[2025-08-09 14:31:24 -0300] [33] [INFO] Worker reloading: /app/src/apps/core/models.py modified
[2025-08-09 14:31:24 -0300] [33] [INFO] Worker exiting (pid: 33)
[2025-08-09 17:31:24 +0000] [36] [INFO] Booting worker with pid: 36
[2025-08-09 17:31:24 +0000] [37] [INFO] Booting worker with pid: 37
[2025-08-09 14:31:28 -0300] [36] [INFO] Worker reloading: /app/src/apps/core/models.py modified
[2025-08-09 14:31:28 -0300] [36] [INFO] Worker exiting (pid: 36)
[2025-08-09 14:31:28 -0300] [37] [INFO] Worker reloading: /app/src/apps/core/models.py modified
[2025-08-09 14:31:28 -0300] [37] [INFO] Worker exiting (pid: 37)
[2025-08-09 17:31:28 +0000] [40] [INFO] Booting worker with pid: 40
[2025-08-09 17:31:28 +0000] [41] [INFO] Booting worker with pid: 41
[2025-08-09 14:31:28 -0300] [40] [ERROR] unexpected indent (models.py, line 9)
Traceback (most recent call last):
  File "/usr/local/lib/python3.10/site-packages/gunicorn/workers/base.py", line 146, in load_wsgi
    self.wsgi = self.app.wsgi()
  File "/usr/local/lib/python3.10/site-packages/gunicorn/app/base.py", line 67, in wsgi
    self.callable = self.load()
  File "/usr/local/lib/python3.10/site-packages/gunicorn/app/wsgiapp.py", line 58, in load
    return self.load_wsgiapp()
  File "/usr/local/lib/python3.10/site-packages/gunicorn/app/wsgiapp.py", line 48, in load_wsgiapp
    return util.import_app(self.app_uri)
  File "/usr/local/lib/python3.10/site-packages/gunicorn/util.py", line 359, in import_app
    mod = importlib.import_module(module)
  File "/usr/local/lib/python3.10/importlib/__init__.py", line 126, in import_module
    return _bootstrap._gcd_import(name[level:], package, level)
  File "<frozen importlib._bootstrap>", line 1050, in _gcd_import
  File "<frozen importlib._bootstrap>", line 1027, in _find_and_load
  File "<frozen importlib._bootstrap>", line 1006, in _find_and_load_unlocked
  File "<frozen importlib._bootstrap>", line 688, in _load_unlocked
  File "<frozen importlib._bootstrap_external>", line 883, in exec_module
  File "<frozen importlib._bootstrap>", line 241, in _call_with_frames_removed
  File "/app/src/zeppelin/wsgi.py", line 16, in <module>
    application = get_wsgi_application()
  File "/usr/local/lib/python3.10/site-packages/django/core/wsgi.py", line 12, in get_wsgi_application
    django.setup(set_prefix=False)
  File "/usr/local/lib/python3.10/site-packages/django/__init__.py", line 24, in setup
    apps.populate(settings.INSTALLED_APPS)
  File "/usr/local/lib/python3.10/site-packages/django/apps/registry.py", line 116, in populate
    app_config.import_models()
  File "/usr/local/lib/python3.10/site-packages/django/apps/config.py", line 269, in import_models
    self.models_module = import_module(models_module_name)
  File "/usr/local/lib/python3.10/importlib/__init__.py", line 126, in import_module
    return _bootstrap._gcd_import(name[level:], package, level)
  File "<frozen importlib._bootstrap>", line 1050, in _gcd_import
  File "<frozen importlib._bootstrap>", line 1027, in _find_and_load
  File "<frozen importlib._bootstrap>", line 1006, in _find_and_load_unlocked
  File "<frozen importlib._bootstrap>", line 688, in _load_unlocked
  File "<frozen importlib._bootstrap_external>", line 879, in exec_module
  File "<frozen importlib._bootstrap_external>", line 1017, in get_code
  File "<frozen importlib._bootstrap_external>", line 947, in source_to_code
  File "<frozen importlib._bootstrap>", line 241, in _call_with_frames_removed
  File "/app/src/apps/core/models.py", line 9
    created_at = models.DateTimeField(auto_now_add=True)  # melhor que blank=True
IndentationError: unexpected indent
[2025-08-09 14:31:28 -0300] [41] [ERROR] unexpected indent (models.py, line 9)
Traceback (most recent call last):
  File "/usr/local/lib/python3.10/site-packages/gunicorn/workers/base.py", line 146, in load_wsgi
    self.wsgi = self.app.wsgi()
  File "/usr/local/lib/python3.10/site-packages/gunicorn/app/base.py", line 67, in wsgi
    self.callable = self.load()
  File "/usr/local/lib/python3.10/site-packages/gunicorn/app/wsgiapp.py", line 58, in load
    return self.load_wsgiapp()
  File "/usr/local/lib/python3.10/site-packages/gunicorn/app/wsgiapp.py", line 48, in load_wsgiapp
    return util.import_app(self.app_uri)
  File "/usr/local/lib/python3.10/site-packages/gunicorn/util.py", line 359, in import_app
    mod = importlib.import_module(module)
  File "/usr/local/lib/python3.10/importlib/__init__.py", line 126, in import_module
    return _bootstrap._gcd_import(name[level:], package, level)
  File "<frozen importlib._bootstrap>", line 1050, in _gcd_import
  File "<frozen importlib._bootstrap>", line 1027, in _find_and_load
  File "<frozen importlib._bootstrap>", line 1006, in _find_and_load_unlocked
  File "<frozen importlib._bootstrap>", line 688, in _load_unlocked
  File "<frozen importlib._bootstrap_external>", line 883, in exec_module
  File "<frozen importlib._bootstrap>", line 241, in _call_with_frames_removed
  File "/app/src/zeppelin/wsgi.py", line 16, in <module>
    application = get_wsgi_application()
  File "/usr/local/lib/python3.10/site-packages/django/core/wsgi.py", line 12, in get_wsgi_application
    django.setup(set_prefix=False)
  File "/usr/local/lib/python3.10/site-packages/django/__init__.py", line 24, in setup
    apps.populate(settings.INSTALLED_APPS)
  File "/usr/local/lib/python3.10/site-packages/django/apps/registry.py", line 116, in populate
    app_config.import_models()
  File "/usr/local/lib/python3.10/site-packages/django/apps/config.py", line 269, in import_models
    self.models_module = import_module(models_module_name)
  File "/usr/local/lib/python3.10/importlib/__init__.py", line 126, in import_module
    return _bootstrap._gcd_import(name[level:], package, level)
  File "<frozen importlib._bootstrap>", line 1050, in _gcd_import
  File "<frozen importlib._bootstrap>", line 1027, in _find_and_load
  File "<frozen importlib._bootstrap>", line 1006, in _find_and_load_unlocked
  File "<frozen importlib._bootstrap>", line 688, in _load_unlocked
  File "<frozen importlib._bootstrap_external>", line 879, in exec_module
  File "<frozen importlib._bootstrap_external>", line 1017, in get_code
  File "<frozen importlib._bootstrap_external>", line 947, in source_to_code
  File "<frozen importlib._bootstrap>", line 241, in _call_with_frames_removed
  File "/app/src/apps/core/models.py", line 9
    created_at = models.DateTimeField(auto_now_add=True)  # melhor que blank=True
IndentationError: unexpected indent
[2025-08-09 14:31:29 -0300] [40] [INFO] Worker reloading: /app/src/apps/core/models.py modified
[2025-08-09 14:31:29 -0300] [40] [INFO] Worker exiting (pid: 40)
[2025-08-09 14:31:29 -0300] [41] [INFO] Worker reloading: /app/src/apps/core/models.py modified
[2025-08-09 14:31:29 -0300] [41] [INFO] Worker exiting (pid: 41)
[2025-08-09 17:31:29 +0000] [44] [INFO] Booting worker with pid: 44
[2025-08-09 17:31:29 +0000] [45] [INFO] Booting worker with pid: 45
[2025-08-09 17:31:30 +0000] [27] [INFO] Handling signal: term
[2025-08-09 14:31:30 -0300] [44] [INFO] Worker exiting (pid: 44)
[2025-08-09 14:31:30 -0300] [45] [INFO] Worker exiting (pid: 45)
[2025-08-09 17:31:31 +0000] [27] [INFO] Shutting down: Master
[2025-08-09 18:14:54 +0000] [12] [INFO] Starting gunicorn 20.1.0
[2025-08-09 18:14:54 +0000] [12] [INFO] Listening at: http://0.0.0.0:8000 (12)
[2025-08-09 18:14:54 +0000] [12] [INFO] Using worker: sync
[2025-08-09 18:14:54 +0000] [13] [INFO] Booting worker with pid: 13
[2025-08-09 18:14:54 +0000] [14] [INFO] Booting worker with pid: 14
[2025-08-09 15:16:50 -0300] [13] [INFO] Worker reloading: /app/src/apps/continuousstar/serializers.py modified
[2025-08-09 15:16:50 -0300] [13] [INFO] Worker exiting (pid: 13)
[2025-08-09 15:16:51 -0300] [14] [INFO] Worker reloading: /app/src/apps/continuousstar/serializers.py modified
[2025-08-09 15:16:51 -0300] [14] [INFO] Worker exiting (pid: 14)
[2025-08-09 18:16:51 +0000] [17] [INFO] Booting worker with pid: 17
[2025-08-09 18:16:51 +0000] [18] [INFO] Booting worker with pid: 18
[2025-08-09 15:17:20 -0300] [17] [INFO] Worker reloading: /app/src/apps/practitionerseye/models.py modified
[2025-08-09 15:17:20 -0300] [17] [INFO] Worker exiting (pid: 17)
[2025-08-09 15:17:20 -0300] [18] [INFO] Worker reloading: /app/src/apps/practitionerseye/models.py modified
[2025-08-09 15:17:20 -0300] [18] [INFO] Worker exiting (pid: 18)
[2025-08-09 18:17:20 +0000] [21] [INFO] Booting worker with pid: 21
[2025-08-09 18:17:21 +0000] [22] [INFO] Booting worker with pid: 22
[2025-08-09 15:17:27 -0300] [21] [INFO] Worker reloading: /app/src/apps/practitionerseye/models.py modified
[2025-08-09 15:17:27 -0300] [21] [INFO] Worker exiting (pid: 21)
[2025-08-09 15:17:27 -0300] [22] [INFO] Worker reloading: /app/src/apps/practitionerseye/models.py modified
[2025-08-09 15:17:27 -0300] [22] [INFO] Worker exiting (pid: 22)
[2025-08-09 18:17:27 +0000] [25] [INFO] Booting worker with pid: 25
[2025-08-09 18:17:27 +0000] [26] [INFO] Booting worker with pid: 26
[2025-08-09 15:18:32 -0300] [25] [INFO] Worker reloading: /app/src/apps/questionnaire/models.py modified
[2025-08-09 15:18:32 -0300] [26] [INFO] Worker reloading: /app/src/apps/questionnaire/models.py modified
[2025-08-09 15:18:32 -0300] [25] [INFO] Worker exiting (pid: 25)
[2025-08-09 15:18:32 -0300] [26] [INFO] Worker exiting (pid: 26)
[2025-08-09 18:18:32 +0000] [29] [INFO] Booting worker with pid: 29
[2025-08-09 18:18:32 +0000] [30] [INFO] Booting worker with pid: 30
[2025-08-09 15:18:39 -0300] [29] [INFO] Worker reloading: /app/src/zeppelin/settings/base.py modified
[2025-08-09 15:18:39 -0300] [29] [INFO] Worker exiting (pid: 29)
[2025-08-09 15:18:39 -0300] [30] [INFO] Worker reloading: /app/src/zeppelin/settings/base.py modified
[2025-08-09 15:18:39 -0300] [30] [INFO] Worker exiting (pid: 30)
[2025-08-09 18:18:39 +0000] [33] [INFO] Booting worker with pid: 33
[2025-08-09 18:18:40 +0000] [34] [INFO] Booting worker with pid: 34
[2025-08-09 18:18:41 +0000] [12] [INFO] Handling signal: term
[2025-08-09 15:18:41 -0300] [33] [INFO] Worker exiting (pid: 33)
[2025-08-09 15:18:41 -0300] [34] [INFO] Worker exiting (pid: 34)
[2025-08-09 18:18:41 +0000] [12] [INFO] Shutting down: Master
[2025-08-09 18:19:54 +0000] [12] [INFO] Starting gunicorn 20.1.0
[2025-08-09 18:19:54 +0000] [12] [INFO] Listening at: http://0.0.0.0:8000 (12)
[2025-08-09 18:19:54 +0000] [12] [INFO] Using worker: sync
[2025-08-09 18:19:54 +0000] [13] [INFO] Booting worker with pid: 13
[2025-08-09 18:19:54 +0000] [14] [INFO] Booting worker with pid: 14
[2025-08-09 15:21:06 -0300] [14] [INFO] Worker reloading: /app/src/apps/continuousstar/serializers.py modified
[2025-08-09 15:21:06 -0300] [14] [INFO] Worker exiting (pid: 14)
[2025-08-09 18:21:06 +0000] [17] [INFO] Booting worker with pid: 17
[2025-08-09 15:21:07 -0300] [13] [INFO] Worker reloading: /app/src/apps/continuousstar/serializers.py modified
[2025-08-09 15:21:07 -0300] [13] [INFO] Worker exiting (pid: 13)
[2025-08-09 18:21:07 +0000] [19] [INFO] Booting worker with pid: 19
[2025-08-09 15:21:27 -0300] [19] [INFO] Worker reloading: /app/src/apps/core/models.py modified
[2025-08-09 15:21:27 -0300] [19] [INFO] Worker exiting (pid: 19)
[2025-08-09 18:21:27 +0000] [21] [INFO] Booting worker with pid: 21
[2025-08-09 15:21:27 -0300] [17] [INFO] Worker reloading: /app/src/apps/core/models.py modified
[2025-08-09 15:21:27 -0300] [17] [INFO] Worker exiting (pid: 17)
[2025-08-09 18:21:27 +0000] [22] [INFO] Booting worker with pid: 22
[2025-08-09 15:21:33 -0300] [22] [INFO] Worker reloading: /app/src/apps/core/models.py modified
[2025-08-09 15:21:33 -0300] [22] [INFO] Worker exiting (pid: 22)
[2025-08-09 18:21:34 +0000] [25] [INFO] Booting worker with pid: 25
[2025-08-09 15:21:34 -0300] [25] [ERROR] unmatched ')' (models.py, line 6)
Traceback (most recent call last):
  File "/usr/local/lib/python3.10/site-packages/gunicorn/workers/base.py", line 146, in load_wsgi
    self.wsgi = self.app.wsgi()
  File "/usr/local/lib/python3.10/site-packages/gunicorn/app/base.py", line 67, in wsgi
    self.callable = self.load()
  File "/usr/local/lib/python3.10/site-packages/gunicorn/app/wsgiapp.py", line 58, in load
    return self.load_wsgiapp()
  File "/usr/local/lib/python3.10/site-packages/gunicorn/app/wsgiapp.py", line 48, in load_wsgiapp
    return util.import_app(self.app_uri)
  File "/usr/local/lib/python3.10/site-packages/gunicorn/util.py", line 359, in import_app
    mod = importlib.import_module(module)
  File "/usr/local/lib/python3.10/importlib/__init__.py", line 126, in import_module
    return _bootstrap._gcd_import(name[level:], package, level)
  File "<frozen importlib._bootstrap>", line 1050, in _gcd_import
  File "<frozen importlib._bootstrap>", line 1027, in _find_and_load
  File "<frozen importlib._bootstrap>", line 1006, in _find_and_load_unlocked
  File "<frozen importlib._bootstrap>", line 688, in _load_unlocked
  File "<frozen importlib._bootstrap_external>", line 883, in exec_module
  File "<frozen importlib._bootstrap>", line 241, in _call_with_frames_removed
  File "/app/src/zeppelin/wsgi.py", line 16, in <module>
    application = get_wsgi_application()
  File "/usr/local/lib/python3.10/site-packages/django/core/wsgi.py", line 12, in get_wsgi_application
    django.setup(set_prefix=False)
  File "/usr/local/lib/python3.10/site-packages/django/__init__.py", line 24, in setup
    apps.populate(settings.INSTALLED_APPS)
  File "/usr/local/lib/python3.10/site-packages/django/apps/registry.py", line 116, in populate
    app_config.import_models()
  File "/usr/local/lib/python3.10/site-packages/django/apps/config.py", line 269, in import_models
    self.models_module = import_module(models_module_name)
  File "/usr/local/lib/python3.10/importlib/__init__.py", line 126, in import_module
    return _bootstrap._gcd_import(name[level:], package, level)
  File "<frozen importlib._bootstrap>", line 1050, in _gcd_import
  File "<frozen importlib._bootstrap>", line 1027, in _find_and_load
  File "<frozen importlib._bootstrap>", line 1006, in _find_and_load_unlocked
  File "<frozen importlib._bootstrap>", line 688, in _load_unlocked
  File "<frozen importlib._bootstrap_external>", line 879, in exec_module
  File "<frozen importlib._bootstrap_external>", line 1017, in get_code
  File "<frozen importlib._bootstrap_external>", line 947, in source_to_code
  File "<frozen importlib._bootstrap>", line 241, in _call_with_frames_removed
  File "/app/src/apps/core/models.py", line 6
    class HistoricalPolymorphicModel,models.Model):
                                                 ^
SyntaxError: unmatched ')'
[2025-08-09 15:21:34 -0300] [21] [INFO] Worker reloading: /app/src/apps/core/models.py modified
[2025-08-09 15:21:34 -0300] [21] [INFO] Worker exiting (pid: 21)
[2025-08-09 18:21:35 +0000] [27] [INFO] Booting worker with pid: 27
[2025-08-09 15:21:35 -0300] [27] [ERROR] unmatched ')' (models.py, line 6)
Traceback (most recent call last):
  File "/usr/local/lib/python3.10/site-packages/gunicorn/workers/base.py", line 146, in load_wsgi
    self.wsgi = self.app.wsgi()
  File "/usr/local/lib/python3.10/site-packages/gunicorn/app/base.py", line 67, in wsgi
    self.callable = self.load()
  File "/usr/local/lib/python3.10/site-packages/gunicorn/app/wsgiapp.py", line 58, in load
    return self.load_wsgiapp()
  File "/usr/local/lib/python3.10/site-packages/gunicorn/app/wsgiapp.py", line 48, in load_wsgiapp
    return util.import_app(self.app_uri)
  File "/usr/local/lib/python3.10/site-packages/gunicorn/util.py", line 359, in import_app
    mod = importlib.import_module(module)
  File "/usr/local/lib/python3.10/importlib/__init__.py", line 126, in import_module
    return _bootstrap._gcd_import(name[level:], package, level)
  File "<frozen importlib._bootstrap>", line 1050, in _gcd_import
  File "<frozen importlib._bootstrap>", line 1027, in _find_and_load
  File "<frozen importlib._bootstrap>", line 1006, in _find_and_load_unlocked
  File "<frozen importlib._bootstrap>", line 688, in _load_unlocked
  File "<frozen importlib._bootstrap_external>", line 883, in exec_module
  File "<frozen importlib._bootstrap>", line 241, in _call_with_frames_removed
  File "/app/src/zeppelin/wsgi.py", line 16, in <module>
    application = get_wsgi_application()
  File "/usr/local/lib/python3.10/site-packages/django/core/wsgi.py", line 12, in get_wsgi_application
    django.setup(set_prefix=False)
  File "/usr/local/lib/python3.10/site-packages/django/__init__.py", line 24, in setup
    apps.populate(settings.INSTALLED_APPS)
  File "/usr/local/lib/python3.10/site-packages/django/apps/registry.py", line 116, in populate
    app_config.import_models()
  File "/usr/local/lib/python3.10/site-packages/django/apps/config.py", line 269, in import_models
    self.models_module = import_module(models_module_name)
  File "/usr/local/lib/python3.10/importlib/__init__.py", line 126, in import_module
    return _bootstrap._gcd_import(name[level:], package, level)
  File "<frozen importlib._bootstrap>", line 1050, in _gcd_import
  File "<frozen importlib._bootstrap>", line 1027, in _find_and_load
  File "<frozen importlib._bootstrap>", line 1006, in _find_and_load_unlocked
  File "<frozen importlib._bootstrap>", line 688, in _load_unlocked
  File "<frozen importlib._bootstrap_external>", line 879, in exec_module
  File "<frozen importlib._bootstrap_external>", line 1017, in get_code
  File "<frozen importlib._bootstrap_external>", line 947, in source_to_code
  File "<frozen importlib._bootstrap>", line 241, in _call_with_frames_removed
  File "/app/src/apps/core/models.py", line 6
    class HistoricalPolymorphicModel,models.Model):
                                                 ^
SyntaxError: unmatched ')'
[2025-08-09 15:21:36 -0300] [25] [INFO] Worker reloading: /app/src/apps/core/models.py modified
[2025-08-09 15:21:36 -0300] [25] [INFO] Worker exiting (pid: 25)
[2025-08-09 18:21:36 +0000] [29] [INFO] Booting worker with pid: 29
[2025-08-09 15:21:37 -0300] [27] [INFO] Worker reloading: /app/src/apps/core/models.py modified
[2025-08-09 15:21:37 -0300] [27] [INFO] Worker exiting (pid: 27)
[2025-08-09 18:21:37 +0000] [31] [INFO] Booting worker with pid: 31
[2025-08-09 18:21:38 +0000] [12] [INFO] Handling signal: term
[2025-08-09 15:21:38 -0300] [31] [INFO] Worker exiting (pid: 31)
[2025-08-09 15:21:38 -0300] [29] [INFO] Worker exiting (pid: 29)
[2025-08-09 18:23:01 +0000] [14] [INFO] Starting gunicorn 20.1.0
[2025-08-09 18:23:01 +0000] [14] [INFO] Listening at: http://0.0.0.0:8000 (14)
[2025-08-09 18:23:01 +0000] [14] [INFO] Using worker: sync
[2025-08-09 18:23:01 +0000] [15] [INFO] Booting worker with pid: 15
[2025-08-09 18:23:01 +0000] [16] [INFO] Booting worker with pid: 16
[2025-08-09 18:31:43 +0000] [14] [INFO] Handling signal: term
[2025-08-09 15:31:43 -0300] [16] [INFO] Worker exiting (pid: 16)
[2025-08-09 15:31:43 -0300] [15] [INFO] Worker exiting (pid: 15)
[2025-08-09 18:31:44 +0000] [14] [INFO] Shutting down: Master
[2025-08-10 11:52:06 +0000] [14] [INFO] Starting gunicorn 20.1.0
[2025-08-10 11:52:06 +0000] [14] [INFO] Listening at: http://0.0.0.0:8000 (14)
[2025-08-10 11:52:06 +0000] [14] [INFO] Using worker: sync
[2025-08-10 11:52:06 +0000] [15] [INFO] Booting worker with pid: 15
[2025-08-10 11:52:06 +0000] [16] [INFO] Booting worker with pid: 16
[2025-08-10 11:52:10 +0000] [14] [INFO] Handling signal: term
[2025-08-10 08:52:10 -0300] [15] [INFO] Worker exiting (pid: 15)
[2025-08-10 08:52:10 -0300] [16] [INFO] Worker exiting (pid: 16)
[2025-08-10 11:52:10 +0000] [14] [INFO] Shutting down: Master
[2025-08-10 11:52:23 +0000] [12] [INFO] Starting gunicorn 20.1.0
[2025-08-10 11:52:23 +0000] [12] [INFO] Listening at: http://0.0.0.0:8000 (12)
[2025-08-10 11:52:23 +0000] [12] [INFO] Using worker: sync
[2025-08-10 11:52:23 +0000] [13] [INFO] Booting worker with pid: 13
[2025-08-10 11:52:23 +0000] [14] [INFO] Booting worker with pid: 14
[2025-08-10 11:54:20 +0000] [14] [INFO] Starting gunicorn 20.1.0
[2025-08-10 11:54:20 +0000] [14] [INFO] Listening at: http://0.0.0.0:8000 (14)
[2025-08-10 11:54:20 +0000] [14] [INFO] Using worker: sync
[2025-08-10 11:54:20 +0000] [15] [INFO] Booting worker with pid: 15
[2025-08-10 11:54:20 +0000] [16] [INFO] Booting worker with pid: 16
[2025-08-10 11:54:42 +0000] [14] [INFO] Handling signal: term
[2025-08-10 08:54:42 -0300] [16] [INFO] Worker exiting (pid: 16)
[2025-08-10 08:54:42 -0300] [15] [INFO] Worker exiting (pid: 15)
[2025-08-10 11:54:42 +0000] [14] [INFO] Shutting down: Master
[2025-08-10 11:58:39 +0000] [14] [INFO] Starting gunicorn 20.1.0
[2025-08-10 11:58:39 +0000] [14] [INFO] Listening at: http://0.0.0.0:8000 (14)
[2025-08-10 11:58:39 +0000] [14] [INFO] Using worker: sync
[2025-08-10 11:58:39 +0000] [15] [INFO] Booting worker with pid: 15
[2025-08-10 11:58:39 +0000] [16] [INFO] Booting worker with pid: 16
[2025-08-10 09:00:12 -0300] [15] [INFO] Worker reloading: /app/src/zeppelin/settings/base.py modified
[2025-08-10 09:00:12 -0300] [15] [INFO] Worker exiting (pid: 15)
[2025-08-10 09:00:12 -0300] [16] [INFO] Worker reloading: /app/src/zeppelin/settings/base.py modified
[2025-08-10 09:00:12 -0300] [16] [INFO] Worker exiting (pid: 16)
[2025-08-10 12:00:12 +0000] [25] [INFO] Booting worker with pid: 25
[2025-08-10 12:00:12 +0000] [26] [INFO] Booting worker with pid: 26
[2025-08-10 09:00:15 -0300] [25] [INFO] Worker reloading: /app/src/zeppelin/settings/base.py modified
[2025-08-10 09:00:15 -0300] [26] [INFO] Worker reloading: /app/src/zeppelin/settings/base.py modified
[2025-08-10 09:00:15 -0300] [25] [INFO] Worker exiting (pid: 25)
[2025-08-10 09:00:15 -0300] [26] [INFO] Worker exiting (pid: 26)
[2025-08-10 12:00:15 +0000] [29] [INFO] Booting worker with pid: 29
[2025-08-10 12:00:15 +0000] [30] [INFO] Booting worker with pid: 30
[2025-08-10 09:00:18 -0300] [29] [INFO] Worker reloading: /app/src/zeppelin/settings/base.py modified
[2025-08-10 09:00:18 -0300] [29] [INFO] Worker exiting (pid: 29)
[2025-08-10 09:00:18 -0300] [30] [INFO] Worker reloading: /app/src/zeppelin/settings/base.py modified
[2025-08-10 09:00:18 -0300] [30] [INFO] Worker exiting (pid: 30)
[2025-08-10 12:00:18 +0000] [33] [INFO] Booting worker with pid: 33
[2025-08-10 12:00:18 +0000] [34] [INFO] Booting worker with pid: 34
[2025-08-10 12:00:18 +0000] [33] [ERROR] unterminated string literal (detected at line 57) (base.py, line 57)
Traceback (most recent call last):
  File "/usr/local/lib/python3.10/site-packages/gunicorn/workers/base.py", line 146, in load_wsgi
    self.wsgi = self.app.wsgi()
  File "/usr/local/lib/python3.10/site-packages/gunicorn/app/base.py", line 67, in wsgi
    self.callable = self.load()
  File "/usr/local/lib/python3.10/site-packages/gunicorn/app/wsgiapp.py", line 58, in load
    return self.load_wsgiapp()
  File "/usr/local/lib/python3.10/site-packages/gunicorn/app/wsgiapp.py", line 48, in load_wsgiapp
    return util.import_app(self.app_uri)
  File "/usr/local/lib/python3.10/site-packages/gunicorn/util.py", line 359, in import_app
    mod = importlib.import_module(module)
  File "/usr/local/lib/python3.10/importlib/__init__.py", line 126, in import_module
    return _bootstrap._gcd_import(name[level:], package, level)
  File "<frozen importlib._bootstrap>", line 1050, in _gcd_import
  File "<frozen importlib._bootstrap>", line 1027, in _find_and_load
  File "<frozen importlib._bootstrap>", line 1006, in _find_and_load_unlocked
  File "<frozen importlib._bootstrap>", line 688, in _load_unlocked
  File "<frozen importlib._bootstrap_external>", line 883, in exec_module
  File "<frozen importlib._bootstrap>", line 241, in _call_with_frames_removed
  File "/app/src/zeppelin/wsgi.py", line 16, in <module>
    application = get_wsgi_application()
  File "/usr/local/lib/python3.10/site-packages/django/core/wsgi.py", line 12, in get_wsgi_application
    django.setup(set_prefix=False)
  File "/usr/local/lib/python3.10/site-packages/django/__init__.py", line 19, in setup
    configure_logging(settings.LOGGING_CONFIG, settings.LOGGING)
  File "/usr/local/lib/python3.10/site-packages/django/conf/__init__.py", line 92, in __getattr__
    self._setup(name)
  File "/usr/local/lib/python3.10/site-packages/django/conf/__init__.py", line 79, in _setup
    self._wrapped = Settings(settings_module)
  File "/usr/local/lib/python3.10/site-packages/django/conf/__init__.py", line 190, in __init__
    mod = importlib.import_module(self.SETTINGS_MODULE)
  File "/usr/local/lib/python3.10/importlib/__init__.py", line 126, in import_module
    return _bootstrap._gcd_import(name[level:], package, level)
  File "<frozen importlib._bootstrap>", line 1050, in _gcd_import
  File "<frozen importlib._bootstrap>", line 1027, in _find_and_load
  File "<frozen importlib._bootstrap>", line 1006, in _find_and_load_unlocked
  File "<frozen importlib._bootstrap>", line 688, in _load_unlocked
  File "<frozen importlib._bootstrap_external>", line 883, in exec_module
  File "<frozen importlib._bootstrap>", line 241, in _call_with_frames_removed
  File "/app/src/zeppelin/settings/local.py", line 1, in <module>
    from .base import *
  File "/app/src/zeppelin/settings/base.py", line 57
    'django_celery_beat",
    ^
SyntaxError: unterminated string literal (detected at line 57)
[2025-08-10 12:00:19 +0000] [34] [ERROR] unterminated string literal (detected at line 57) (base.py, line 57)
Traceback (most recent call last):
  File "/usr/local/lib/python3.10/site-packages/gunicorn/workers/base.py", line 146, in load_wsgi
    self.wsgi = self.app.wsgi()
  File "/usr/local/lib/python3.10/site-packages/gunicorn/app/base.py", line 67, in wsgi
    self.callable = self.load()
  File "/usr/local/lib/python3.10/site-packages/gunicorn/app/wsgiapp.py", line 58, in load
    return self.load_wsgiapp()
  File "/usr/local/lib/python3.10/site-packages/gunicorn/app/wsgiapp.py", line 48, in load_wsgiapp
    return util.import_app(self.app_uri)
  File "/usr/local/lib/python3.10/site-packages/gunicorn/util.py", line 359, in import_app
    mod = importlib.import_module(module)
  File "/usr/local/lib/python3.10/importlib/__init__.py", line 126, in import_module
    return _bootstrap._gcd_import(name[level:], package, level)
  File "<frozen importlib._bootstrap>", line 1050, in _gcd_import
  File "<frozen importlib._bootstrap>", line 1027, in _find_and_load
  File "<frozen importlib._bootstrap>", line 1006, in _find_and_load_unlocked
  File "<frozen importlib._bootstrap>", line 688, in _load_unlocked
  File "<frozen importlib._bootstrap_external>", line 883, in exec_module
  File "<frozen importlib._bootstrap>", line 241, in _call_with_frames_removed
  File "/app/src/zeppelin/wsgi.py", line 16, in <module>
    application = get_wsgi_application()
  File "/usr/local/lib/python3.10/site-packages/django/core/wsgi.py", line 12, in get_wsgi_application
    django.setup(set_prefix=False)
  File "/usr/local/lib/python3.10/site-packages/django/__init__.py", line 19, in setup
    configure_logging(settings.LOGGING_CONFIG, settings.LOGGING)
  File "/usr/local/lib/python3.10/site-packages/django/conf/__init__.py", line 92, in __getattr__
    self._setup(name)
  File "/usr/local/lib/python3.10/site-packages/django/conf/__init__.py", line 79, in _setup
    self._wrapped = Settings(settings_module)
  File "/usr/local/lib/python3.10/site-packages/django/conf/__init__.py", line 190, in __init__
    mod = importlib.import_module(self.SETTINGS_MODULE)
  File "/usr/local/lib/python3.10/importlib/__init__.py", line 126, in import_module
    return _bootstrap._gcd_import(name[level:], package, level)
  File "<frozen importlib._bootstrap>", line 1050, in _gcd_import
  File "<frozen importlib._bootstrap>", line 1027, in _find_and_load
  File "<frozen importlib._bootstrap>", line 1006, in _find_and_load_unlocked
  File "<frozen importlib._bootstrap>", line 688, in _load_unlocked
  File "<frozen importlib._bootstrap_external>", line 883, in exec_module
  File "<frozen importlib._bootstrap>", line 241, in _call_with_frames_removed
  File "/app/src/zeppelin/settings/local.py", line 1, in <module>
    from .base import *
  File "/app/src/zeppelin/settings/base.py", line 57
    'django_celery_beat",
    ^
SyntaxError: unterminated string literal (detected at line 57)
[2025-08-10 12:00:21 +0000] [33] [INFO] Worker reloading: /app/src/zeppelin/settings/base.py modified
[2025-08-10 12:00:21 +0000] [33] [INFO] Worker exiting (pid: 33)
[2025-08-10 12:00:21 +0000] [34] [INFO] Worker reloading: /app/src/zeppelin/settings/base.py modified
[2025-08-10 12:00:21 +0000] [34] [INFO] Worker exiting (pid: 34)
[2025-08-10 12:00:21 +0000] [37] [INFO] Booting worker with pid: 37
[2025-08-10 12:00:21 +0000] [38] [INFO] Booting worker with pid: 38
[2025-08-10 09:01:04 -0300] [37] [INFO] Worker reloading: /app/src/zeppelin/settings/base.py modified
[2025-08-10 09:01:04 -0300] [37] [INFO] Worker exiting (pid: 37)
[2025-08-10 09:01:04 -0300] [38] [INFO] Worker reloading: /app/src/zeppelin/settings/base.py modified
[2025-08-10 09:01:04 -0300] [38] [INFO] Worker exiting (pid: 38)
[2025-08-10 12:01:05 +0000] [41] [INFO] Booting worker with pid: 41
[2025-08-10 12:01:05 +0000] [42] [INFO] Booting worker with pid: 42
[2025-08-10 09:02:51 -0300] [42] [INFO] Worker reloading: /app/src/zeppelin/settings/__init__.py modified
[2025-08-10 09:02:51 -0300] [42] [INFO] Worker exiting (pid: 42)
[2025-08-10 12:02:51 +0000] [45] [INFO] Booting worker with pid: 45
[2025-08-10 12:02:51 +0000] [45] [ERROR] Exception in worker process
Traceback (most recent call last):
  File "/usr/local/lib/python3.10/site-packages/gunicorn/arbiter.py", line 589, in spawn_worker
    worker.init_process()
  File "/usr/local/lib/python3.10/site-packages/gunicorn/workers/base.py", line 134, in init_process
    self.load_wsgi()
  File "/usr/local/lib/python3.10/site-packages/gunicorn/workers/base.py", line 146, in load_wsgi
    self.wsgi = self.app.wsgi()
  File "/usr/local/lib/python3.10/site-packages/gunicorn/app/base.py", line 67, in wsgi
    self.callable = self.load()
  File "/usr/local/lib/python3.10/site-packages/gunicorn/app/wsgiapp.py", line 58, in load
    return self.load_wsgiapp()
  File "/usr/local/lib/python3.10/site-packages/gunicorn/app/wsgiapp.py", line 48, in load_wsgiapp
    return util.import_app(self.app_uri)
  File "/usr/local/lib/python3.10/site-packages/gunicorn/util.py", line 359, in import_app
    mod = importlib.import_module(module)
  File "/usr/local/lib/python3.10/importlib/__init__.py", line 126, in import_module
    return _bootstrap._gcd_import(name[level:], package, level)
  File "<frozen importlib._bootstrap>", line 1050, in _gcd_import
  File "<frozen importlib._bootstrap>", line 1027, in _find_and_load
  File "<frozen importlib._bootstrap>", line 1006, in _find_and_load_unlocked
  File "<frozen importlib._bootstrap>", line 688, in _load_unlocked
  File "<frozen importlib._bootstrap_external>", line 883, in exec_module
  File "<frozen importlib._bootstrap>", line 241, in _call_with_frames_removed
  File "/app/src/zeppelin/wsgi.py", line 16, in <module>
    application = get_wsgi_application()
  File "/usr/local/lib/python3.10/site-packages/django/core/wsgi.py", line 12, in get_wsgi_application
    django.setup(set_prefix=False)
  File "/usr/local/lib/python3.10/site-packages/django/__init__.py", line 19, in setup
    configure_logging(settings.LOGGING_CONFIG, settings.LOGGING)
  File "/usr/local/lib/python3.10/site-packages/django/conf/__init__.py", line 92, in __getattr__
    self._setup(name)
  File "/usr/local/lib/python3.10/site-packages/django/conf/__init__.py", line 79, in _setup
    self._wrapped = Settings(settings_module)
  File "/usr/local/lib/python3.10/site-packages/django/conf/__init__.py", line 190, in __init__
    mod = importlib.import_module(self.SETTINGS_MODULE)
  File "/usr/local/lib/python3.10/importlib/__init__.py", line 126, in import_module
    return _bootstrap._gcd_import(name[level:], package, level)
  File "<frozen importlib._bootstrap>", line 1050, in _gcd_import
  File "<frozen importlib._bootstrap>", line 1027, in _find_and_load
  File "<frozen importlib._bootstrap>", line 992, in _find_and_load_unlocked
  File "<frozen importlib._bootstrap>", line 241, in _call_with_frames_removed
  File "<frozen importlib._bootstrap>", line 1050, in _gcd_import
  File "<frozen importlib._bootstrap>", line 1027, in _find_and_load
  File "<frozen importlib._bootstrap>", line 1006, in _find_and_load_unlocked
  File "<frozen importlib._bootstrap>", line 688, in _load_unlocked
  File "<frozen importlib._bootstrap_external>", line 883, in exec_module
  File "<frozen importlib._bootstrap>", line 241, in _call_with_frames_removed
  File "/app/src/zeppelin/settings/__init__.py", line 1, in <module>
    from .celery import app as celery_app
ModuleNotFoundError: No module named 'zeppelin.settings.celery'
[2025-08-10 12:02:51 +0000] [45] [INFO] Worker exiting (pid: 45)
[2025-08-10 09:02:51 -0300] [41] [INFO] Worker exiting (pid: 41)
[2025-08-10 12:02:52 +0000] [14] [INFO] Shutting down: Master
[2025-08-10 12:02:52 +0000] [14] [INFO] Reason: Worker failed to boot.
[2025-08-10 12:02:53 +0000] [46] [INFO] Starting gunicorn 20.1.0
[2025-08-10 12:02:53 +0000] [46] [INFO] Listening at: http://0.0.0.0:8000 (46)
[2025-08-10 12:02:53 +0000] [46] [INFO] Using worker: sync
[2025-08-10 12:02:53 +0000] [47] [INFO] Booting worker with pid: 47
[2025-08-10 12:02:53 +0000] [48] [INFO] Booting worker with pid: 48
[2025-08-10 12:02:53 +0000] [47] [ERROR] Exception in worker process
Traceback (most recent call last):
  File "/usr/local/lib/python3.10/site-packages/gunicorn/arbiter.py", line 589, in spawn_worker
    worker.init_process()
  File "/usr/local/lib/python3.10/site-packages/gunicorn/workers/base.py", line 134, in init_process
    self.load_wsgi()
  File "/usr/local/lib/python3.10/site-packages/gunicorn/workers/base.py", line 146, in load_wsgi
    self.wsgi = self.app.wsgi()
  File "/usr/local/lib/python3.10/site-packages/gunicorn/app/base.py", line 67, in wsgi
    self.callable = self.load()
  File "/usr/local/lib/python3.10/site-packages/gunicorn/app/wsgiapp.py", line 58, in load
    return self.load_wsgiapp()
  File "/usr/local/lib/python3.10/site-packages/gunicorn/app/wsgiapp.py", line 48, in load_wsgiapp
    return util.import_app(self.app_uri)
  File "/usr/local/lib/python3.10/site-packages/gunicorn/util.py", line 359, in import_app
    mod = importlib.import_module(module)
  File "/usr/local/lib/python3.10/importlib/__init__.py", line 126, in import_module
    return _bootstrap._gcd_import(name[level:], package, level)
  File "<frozen importlib._bootstrap>", line 1050, in _gcd_import
  File "<frozen importlib._bootstrap>", line 1027, in _find_and_load
  File "<frozen importlib._bootstrap>", line 1006, in _find_and_load_unlocked
  File "<frozen importlib._bootstrap>", line 688, in _load_unlocked
  File "<frozen importlib._bootstrap_external>", line 883, in exec_module
  File "<frozen importlib._bootstrap>", line 241, in _call_with_frames_removed
  File "/app/src/zeppelin/wsgi.py", line 16, in <module>
    application = get_wsgi_application()
  File "/usr/local/lib/python3.10/site-packages/django/core/wsgi.py", line 12, in get_wsgi_application
    django.setup(set_prefix=False)
  File "/usr/local/lib/python3.10/site-packages/django/__init__.py", line 19, in setup
    configure_logging(settings.LOGGING_CONFIG, settings.LOGGING)
  File "/usr/local/lib/python3.10/site-packages/django/conf/__init__.py", line 92, in __getattr__
    self._setup(name)
  File "/usr/local/lib/python3.10/site-packages/django/conf/__init__.py", line 79, in _setup
    self._wrapped = Settings(settings_module)
  File "/usr/local/lib/python3.10/site-packages/django/conf/__init__.py", line 190, in __init__
    mod = importlib.import_module(self.SETTINGS_MODULE)
  File "/usr/local/lib/python3.10/importlib/__init__.py", line 126, in import_module
    return _bootstrap._gcd_import(name[level:], package, level)
  File "<frozen importlib._bootstrap>", line 1050, in _gcd_import
  File "<frozen importlib._bootstrap>", line 1027, in _find_and_load
  File "<frozen importlib._bootstrap>", line 992, in _find_and_load_unlocked
  File "<frozen importlib._bootstrap>", line 241, in _call_with_frames_removed
  File "<frozen importlib._bootstrap>", line 1050, in _gcd_import
  File "<frozen importlib._bootstrap>", line 1027, in _find_and_load
  File "<frozen importlib._bootstrap>", line 1006, in _find_and_load_unlocked
  File "<frozen importlib._bootstrap>", line 688, in _load_unlocked
  File "<frozen importlib._bootstrap_external>", line 883, in exec_module
  File "<frozen importlib._bootstrap>", line 241, in _call_with_frames_removed
  File "/app/src/zeppelin/settings/__init__.py", line 1, in <module>
    from .celery import app as celery_app
ModuleNotFoundError: No module named 'zeppelin.settings.celery'
[2025-08-10 12:02:53 +0000] [47] [INFO] Worker exiting (pid: 47)
[2025-08-10 12:02:53 +0000] [48] [ERROR] Exception in worker process
Traceback (most recent call last):
  File "/usr/local/lib/python3.10/site-packages/gunicorn/arbiter.py", line 589, in spawn_worker
    worker.init_process()
  File "/usr/local/lib/python3.10/site-packages/gunicorn/workers/base.py", line 134, in init_process
    self.load_wsgi()
  File "/usr/local/lib/python3.10/site-packages/gunicorn/workers/base.py", line 146, in load_wsgi
    self.wsgi = self.app.wsgi()
  File "/usr/local/lib/python3.10/site-packages/gunicorn/app/base.py", line 67, in wsgi
    self.callable = self.load()
  File "/usr/local/lib/python3.10/site-packages/gunicorn/app/wsgiapp.py", line 58, in load
    return self.load_wsgiapp()
  File "/usr/local/lib/python3.10/site-packages/gunicorn/app/wsgiapp.py", line 48, in load_wsgiapp
    return util.import_app(self.app_uri)
  File "/usr/local/lib/python3.10/site-packages/gunicorn/util.py", line 359, in import_app
    mod = importlib.import_module(module)
  File "/usr/local/lib/python3.10/importlib/__init__.py", line 126, in import_module
    return _bootstrap._gcd_import(name[level:], package, level)
  File "<frozen importlib._bootstrap>", line 1050, in _gcd_import
  File "<frozen importlib._bootstrap>", line 1027, in _find_and_load
  File "<frozen importlib._bootstrap>", line 1006, in _find_and_load_unlocked
  File "<frozen importlib._bootstrap>", line 688, in _load_unlocked
  File "<frozen importlib._bootstrap_external>", line 883, in exec_module
  File "<frozen importlib._bootstrap>", line 241, in _call_with_frames_removed
  File "/app/src/zeppelin/wsgi.py", line 16, in <module>
    application = get_wsgi_application()
  File "/usr/local/lib/python3.10/site-packages/django/core/wsgi.py", line 12, in get_wsgi_application
    django.setup(set_prefix=False)
  File "/usr/local/lib/python3.10/site-packages/django/__init__.py", line 19, in setup
    configure_logging(settings.LOGGING_CONFIG, settings.LOGGING)
  File "/usr/local/lib/python3.10/site-packages/django/conf/__init__.py", line 92, in __getattr__
    self._setup(name)
  File "/usr/local/lib/python3.10/site-packages/django/conf/__init__.py", line 79, in _setup
    self._wrapped = Settings(settings_module)
  File "/usr/local/lib/python3.10/site-packages/django/conf/__init__.py", line 190, in __init__
    mod = importlib.import_module(self.SETTINGS_MODULE)
  File "/usr/local/lib/python3.10/importlib/__init__.py", line 126, in import_module
    return _bootstrap._gcd_import(name[level:], package, level)
  File "<frozen importlib._bootstrap>", line 1050, in _gcd_import
  File "<frozen importlib._bootstrap>", line 1027, in _find_and_load
  File "<frozen importlib._bootstrap>", line 992, in _find_and_load_unlocked
  File "<frozen importlib._bootstrap>", line 241, in _call_with_frames_removed
  File "<frozen importlib._bootstrap>", line 1050, in _gcd_import
  File "<frozen importlib._bootstrap>", line 1027, in _find_and_load
  File "<frozen importlib._bootstrap>", line 1006, in _find_and_load_unlocked
  File "<frozen importlib._bootstrap>", line 688, in _load_unlocked
  File "<frozen importlib._bootstrap_external>", line 883, in exec_module
  File "<frozen importlib._bootstrap>", line 241, in _call_with_frames_removed
  File "/app/src/zeppelin/settings/__init__.py", line 1, in <module>
    from .celery import app as celery_app
ModuleNotFoundError: No module named 'zeppelin.settings.celery'
[2025-08-10 12:02:53 +0000] [48] [INFO] Worker exiting (pid: 48)
Traceback (most recent call last):
  File "/usr/local/lib/python3.10/site-packages/gunicorn/arbiter.py", line 209, in run
    self.sleep()
  File "/usr/local/lib/python3.10/site-packages/gunicorn/arbiter.py", line 357, in sleep
    ready = select.select([self.PIPE[0]], [], [], 1.0)
  File "/usr/local/lib/python3.10/site-packages/gunicorn/arbiter.py", line 242, in handle_chld
    self.reap_workers()
  File "/usr/local/lib/python3.10/site-packages/gunicorn/arbiter.py", line 525, in reap_workers
    raise HaltServer(reason, self.WORKER_BOOT_ERROR)
gunicorn.errors.HaltServer: <HaltServer 'Worker failed to boot.' 3>

During handling of the above exception, another exception occurred:

Traceback (most recent call last):
  File "/usr/local/bin/gunicorn", line 8, in <module>
    sys.exit(run())
  File "/usr/local/lib/python3.10/site-packages/gunicorn/app/wsgiapp.py", line 67, in run
    WSGIApplication("%(prog)s [OPTIONS] [APP_MODULE]").run()
  File "/usr/local/lib/python3.10/site-packages/gunicorn/app/base.py", line 231, in run
    super().run()
  File "/usr/local/lib/python3.10/site-packages/gunicorn/app/base.py", line 72, in run
    Arbiter(self).run()
  File "/usr/local/lib/python3.10/site-packages/gunicorn/arbiter.py", line 229, in run
    self.halt(reason=inst.reason, exit_status=inst.exit_status)
  File "/usr/local/lib/python3.10/site-packages/gunicorn/arbiter.py", line 342, in halt
    self.stop()
  File "/usr/local/lib/python3.10/site-packages/gunicorn/arbiter.py", line 382, in stop
    sock.close_sockets(self.LISTENERS, unlink)
  File "/usr/local/lib/python3.10/site-packages/gunicorn/sock.py", line 209, in close_sockets
    sock_name = sock.getsockname()
  File "/usr/local/lib/python3.10/site-packages/gunicorn/sock.py", line 36, in __getattr__
    def __getattr__(self, name):
  File "/usr/local/lib/python3.10/site-packages/gunicorn/arbiter.py", line 242, in handle_chld
    self.reap_workers()
  File "/usr/local/lib/python3.10/site-packages/gunicorn/arbiter.py", line 525, in reap_workers
    raise HaltServer(reason, self.WORKER_BOOT_ERROR)
gunicorn.errors.HaltServer: <HaltServer 'Worker failed to boot.' 3>
[2025-08-10 12:02:54 +0000] [49] [INFO] Starting gunicorn 20.1.0
[2025-08-10 12:02:54 +0000] [49] [INFO] Listening at: http://0.0.0.0:8000 (49)
[2025-08-10 12:02:54 +0000] [49] [INFO] Using worker: sync
[2025-08-10 12:02:54 +0000] [50] [INFO] Booting worker with pid: 50
[2025-08-10 12:02:54 +0000] [51] [INFO] Booting worker with pid: 51
[2025-08-10 12:02:54 +0000] [50] [ERROR] Exception in worker process
Traceback (most recent call last):
  File "/usr/local/lib/python3.10/site-packages/gunicorn/arbiter.py", line 589, in spawn_worker
    worker.init_process()
  File "/usr/local/lib/python3.10/site-packages/gunicorn/workers/base.py", line 134, in init_process
    self.load_wsgi()
  File "/usr/local/lib/python3.10/site-packages/gunicorn/workers/base.py", line 146, in load_wsgi
    self.wsgi = self.app.wsgi()
  File "/usr/local/lib/python3.10/site-packages/gunicorn/app/base.py", line 67, in wsgi
    self.callable = self.load()
  File "/usr/local/lib/python3.10/site-packages/gunicorn/app/wsgiapp.py", line 58, in load
    return self.load_wsgiapp()
  File "/usr/local/lib/python3.10/site-packages/gunicorn/app/wsgiapp.py", line 48, in load_wsgiapp
    return util.import_app(self.app_uri)
  File "/usr/local/lib/python3.10/site-packages/gunicorn/util.py", line 359, in import_app
    mod = importlib.import_module(module)
  File "/usr/local/lib/python3.10/importlib/__init__.py", line 126, in import_module
    return _bootstrap._gcd_import(name[level:], package, level)
  File "<frozen importlib._bootstrap>", line 1050, in _gcd_import
  File "<frozen importlib._bootstrap>", line 1027, in _find_and_load
  File "<frozen importlib._bootstrap>", line 1006, in _find_and_load_unlocked
  File "<frozen importlib._bootstrap>", line 688, in _load_unlocked
  File "<frozen importlib._bootstrap_external>", line 883, in exec_module
  File "<frozen importlib._bootstrap>", line 241, in _call_with_frames_removed
  File "/app/src/zeppelin/wsgi.py", line 16, in <module>
    application = get_wsgi_application()
  File "/usr/local/lib/python3.10/site-packages/django/core/wsgi.py", line 12, in get_wsgi_application
    django.setup(set_prefix=False)
  File "/usr/local/lib/python3.10/site-packages/django/__init__.py", line 19, in setup
    configure_logging(settings.LOGGING_CONFIG, settings.LOGGING)
  File "/usr/local/lib/python3.10/site-packages/django/conf/__init__.py", line 92, in __getattr__
    self._setup(name)
  File "/usr/local/lib/python3.10/site-packages/django/conf/__init__.py", line 79, in _setup
    self._wrapped = Settings(settings_module)
  File "/usr/local/lib/python3.10/site-packages/django/conf/__init__.py", line 190, in __init__
    mod = importlib.import_module(self.SETTINGS_MODULE)
  File "/usr/local/lib/python3.10/importlib/__init__.py", line 126, in import_module
    return _bootstrap._gcd_import(name[level:], package, level)
  File "<frozen importlib._bootstrap>", line 1050, in _gcd_import
  File "<frozen importlib._bootstrap>", line 1027, in _find_and_load
  File "<frozen importlib._bootstrap>", line 992, in _find_and_load_unlocked
  File "<frozen importlib._bootstrap>", line 241, in _call_with_frames_removed
  File "<frozen importlib._bootstrap>", line 1050, in _gcd_import
  File "<frozen importlib._bootstrap>", line 1027, in _find_and_load
  File "<frozen importlib._bootstrap>", line 1006, in _find_and_load_unlocked
  File "<frozen importlib._bootstrap>", line 688, in _load_unlocked
  File "<frozen importlib._bootstrap_external>", line 883, in exec_module
  File "<frozen importlib._bootstrap>", line 241, in _call_with_frames_removed
  File "/app/src/zeppelin/settings/__init__.py", line 1, in <module>
    from .celery import app as celery_app
ModuleNotFoundError: No module named 'zeppelin.settings.celery'
[2025-08-10 12:02:54 +0000] [50] [INFO] Worker exiting (pid: 50)
[2025-08-10 12:02:54 +0000] [51] [ERROR] Exception in worker process
Traceback (most recent call last):
  File "/usr/local/lib/python3.10/site-packages/gunicorn/arbiter.py", line 589, in spawn_worker
    worker.init_process()
  File "/usr/local/lib/python3.10/site-packages/gunicorn/workers/base.py", line 134, in init_process
    self.load_wsgi()
  File "/usr/local/lib/python3.10/site-packages/gunicorn/workers/base.py", line 146, in load_wsgi
    self.wsgi = self.app.wsgi()
  File "/usr/local/lib/python3.10/site-packages/gunicorn/app/base.py", line 67, in wsgi
    self.callable = self.load()
  File "/usr/local/lib/python3.10/site-packages/gunicorn/app/wsgiapp.py", line 58, in load
    return self.load_wsgiapp()
  File "/usr/local/lib/python3.10/site-packages/gunicorn/app/wsgiapp.py", line 48, in load_wsgiapp
    return util.import_app(self.app_uri)
  File "/usr/local/lib/python3.10/site-packages/gunicorn/util.py", line 359, in import_app
    mod = importlib.import_module(module)
  File "/usr/local/lib/python3.10/importlib/__init__.py", line 126, in import_module
    return _bootstrap._gcd_import(name[level:], package, level)
  File "<frozen importlib._bootstrap>", line 1050, in _gcd_import
  File "<frozen importlib._bootstrap>", line 1027, in _find_and_load
  File "<frozen importlib._bootstrap>", line 1006, in _find_and_load_unlocked
  File "<frozen importlib._bootstrap>", line 688, in _load_unlocked
  File "<frozen importlib._bootstrap_external>", line 883, in exec_module
  File "<frozen importlib._bootstrap>", line 241, in _call_with_frames_removed
  File "/app/src/zeppelin/wsgi.py", line 16, in <module>
    application = get_wsgi_application()
  File "/usr/local/lib/python3.10/site-packages/django/core/wsgi.py", line 12, in get_wsgi_application
    django.setup(set_prefix=False)
  File "/usr/local/lib/python3.10/site-packages/django/__init__.py", line 19, in setup
    configure_logging(settings.LOGGING_CONFIG, settings.LOGGING)
  File "/usr/local/lib/python3.10/site-packages/django/conf/__init__.py", line 92, in __getattr__
    self._setup(name)
  File "/usr/local/lib/python3.10/site-packages/django/conf/__init__.py", line 79, in _setup
    self._wrapped = Settings(settings_module)
  File "/usr/local/lib/python3.10/site-packages/django/conf/__init__.py", line 190, in __init__
    mod = importlib.import_module(self.SETTINGS_MODULE)
  File "/usr/local/lib/python3.10/importlib/__init__.py", line 126, in import_module
    return _bootstrap._gcd_import(name[level:], package, level)
  File "<frozen importlib._bootstrap>", line 1050, in _gcd_import
  File "<frozen importlib._bootstrap>", line 1027, in _find_and_load
  File "<frozen importlib._bootstrap>", line 992, in _find_and_load_unlocked
  File "<frozen importlib._bootstrap>", line 241, in _call_with_frames_removed
  File "<frozen importlib._bootstrap>", line 1050, in _gcd_import
  File "<frozen importlib._bootstrap>", line 1027, in _find_and_load
  File "<frozen importlib._bootstrap>", line 1006, in _find_and_load_unlocked
  File "<frozen importlib._bootstrap>", line 688, in _load_unlocked
  File "<frozen importlib._bootstrap_external>", line 883, in exec_module
  File "<frozen importlib._bootstrap>", line 241, in _call_with_frames_removed
  File "/app/src/zeppelin/settings/__init__.py", line 1, in <module>
    from .celery import app as celery_app
ModuleNotFoundError: No module named 'zeppelin.settings.celery'
[2025-08-10 12:02:54 +0000] [51] [INFO] Worker exiting (pid: 51)
[2025-08-10 12:02:54 +0000] [49] [WARNING] Worker with pid 51 was terminated due to signal 15
[2025-08-10 12:02:55 +0000] [49] [INFO] Shutting down: Master
[2025-08-10 12:02:55 +0000] [49] [INFO] Reason: Worker failed to boot.
[2025-08-10 12:02:57 +0000] [52] [INFO] Starting gunicorn 20.1.0
[2025-08-10 12:02:57 +0000] [52] [INFO] Listening at: http://0.0.0.0:8000 (52)
[2025-08-10 12:02:57 +0000] [52] [INFO] Using worker: sync
[2025-08-10 12:02:57 +0000] [53] [INFO] Booting worker with pid: 53
[2025-08-10 12:02:57 +0000] [54] [INFO] Booting worker with pid: 54
[2025-08-10 12:02:57 +0000] [53] [ERROR] Exception in worker process
Traceback (most recent call last):
  File "/usr/local/lib/python3.10/site-packages/gunicorn/arbiter.py", line 589, in spawn_worker
    worker.init_process()
  File "/usr/local/lib/python3.10/site-packages/gunicorn/workers/base.py", line 134, in init_process
    self.load_wsgi()
  File "/usr/local/lib/python3.10/site-packages/gunicorn/workers/base.py", line 146, in load_wsgi
    self.wsgi = self.app.wsgi()
  File "/usr/local/lib/python3.10/site-packages/gunicorn/app/base.py", line 67, in wsgi
    self.callable = self.load()
  File "/usr/local/lib/python3.10/site-packages/gunicorn/app/wsgiapp.py", line 58, in load
    return self.load_wsgiapp()
  File "/usr/local/lib/python3.10/site-packages/gunicorn/app/wsgiapp.py", line 48, in load_wsgiapp
    return util.import_app(self.app_uri)
  File "/usr/local/lib/python3.10/site-packages/gunicorn/util.py", line 359, in import_app
    mod = importlib.import_module(module)
  File "/usr/local/lib/python3.10/importlib/__init__.py", line 126, in import_module
    return _bootstrap._gcd_import(name[level:], package, level)
  File "<frozen importlib._bootstrap>", line 1050, in _gcd_import
  File "<frozen importlib._bootstrap>", line 1027, in _find_and_load
  File "<frozen importlib._bootstrap>", line 1006, in _find_and_load_unlocked
  File "<frozen importlib._bootstrap>", line 688, in _load_unlocked
  File "<frozen importlib._bootstrap_external>", line 883, in exec_module
  File "<frozen importlib._bootstrap>", line 241, in _call_with_frames_removed
  File "/app/src/zeppelin/wsgi.py", line 16, in <module>
    application = get_wsgi_application()
  File "/usr/local/lib/python3.10/site-packages/django/core/wsgi.py", line 12, in get_wsgi_application
    django.setup(set_prefix=False)
  File "/usr/local/lib/python3.10/site-packages/django/__init__.py", line 19, in setup
    configure_logging(settings.LOGGING_CONFIG, settings.LOGGING)
  File "/usr/local/lib/python3.10/site-packages/django/conf/__init__.py", line 92, in __getattr__
    self._setup(name)
  File "/usr/local/lib/python3.10/site-packages/django/conf/__init__.py", line 79, in _setup
    self._wrapped = Settings(settings_module)
  File "/usr/local/lib/python3.10/site-packages/django/conf/__init__.py", line 190, in __init__
    mod = importlib.import_module(self.SETTINGS_MODULE)
  File "/usr/local/lib/python3.10/importlib/__init__.py", line 126, in import_module
    return _bootstrap._gcd_import(name[level:], package, level)
  File "<frozen importlib._bootstrap>", line 1050, in _gcd_import
  File "<frozen importlib._bootstrap>", line 1027, in _find_and_load
  File "<frozen importlib._bootstrap>", line 992, in _find_and_load_unlocked
  File "<frozen importlib._bootstrap>", line 241, in _call_with_frames_removed
  File "<frozen importlib._bootstrap>", line 1050, in _gcd_import
  File "<frozen importlib._bootstrap>", line 1027, in _find_and_load
  File "<frozen importlib._bootstrap>", line 1006, in _find_and_load_unlocked
  File "<frozen importlib._bootstrap>", line 688, in _load_unlocked
  File "<frozen importlib._bootstrap_external>", line 883, in exec_module
  File "<frozen importlib._bootstrap>", line 241, in _call_with_frames_removed
  File "/app/src/zeppelin/settings/__init__.py", line 1, in <module>
    from .celery import app as celery_app
ModuleNotFoundError: No module named 'zeppelin.settings.celery'
[2025-08-10 12:02:57 +0000] [53] [INFO] Worker exiting (pid: 53)
[2025-08-10 12:02:57 +0000] [54] [ERROR] Exception in worker process
Traceback (most recent call last):
  File "/usr/local/lib/python3.10/site-packages/gunicorn/arbiter.py", line 589, in spawn_worker
    worker.init_process()
  File "/usr/local/lib/python3.10/site-packages/gunicorn/workers/base.py", line 134, in init_process
    self.load_wsgi()
  File "/usr/local/lib/python3.10/site-packages/gunicorn/workers/base.py", line 146, in load_wsgi
    self.wsgi = self.app.wsgi()
  File "/usr/local/lib/python3.10/site-packages/gunicorn/app/base.py", line 67, in wsgi
    self.callable = self.load()
  File "/usr/local/lib/python3.10/site-packages/gunicorn/app/wsgiapp.py", line 58, in load
    return self.load_wsgiapp()
  File "/usr/local/lib/python3.10/site-packages/gunicorn/app/wsgiapp.py", line 48, in load_wsgiapp
    return util.import_app(self.app_uri)
  File "/usr/local/lib/python3.10/site-packages/gunicorn/util.py", line 359, in import_app
    mod = importlib.import_module(module)
  File "/usr/local/lib/python3.10/importlib/__init__.py", line 126, in import_module
    return _bootstrap._gcd_import(name[level:], package, level)
  File "<frozen importlib._bootstrap>", line 1050, in _gcd_import
  File "<frozen importlib._bootstrap>", line 1027, in _find_and_load
  File "<frozen importlib._bootstrap>", line 1006, in _find_and_load_unlocked
  File "<frozen importlib._bootstrap>", line 688, in _load_unlocked
  File "<frozen importlib._bootstrap_external>", line 883, in exec_module
  File "<frozen importlib._bootstrap>", line 241, in _call_with_frames_removed
  File "/app/src/zeppelin/wsgi.py", line 16, in <module>
    application = get_wsgi_application()
  File "/usr/local/lib/python3.10/site-packages/django/core/wsgi.py", line 12, in get_wsgi_application
    django.setup(set_prefix=False)
  File "/usr/local/lib/python3.10/site-packages/django/__init__.py", line 19, in setup
    configure_logging(settings.LOGGING_CONFIG, settings.LOGGING)
  File "/usr/local/lib/python3.10/site-packages/django/conf/__init__.py", line 92, in __getattr__
    self._setup(name)
  File "/usr/local/lib/python3.10/site-packages/django/conf/__init__.py", line 79, in _setup
    self._wrapped = Settings(settings_module)
  File "/usr/local/lib/python3.10/site-packages/django/conf/__init__.py", line 190, in __init__
    mod = importlib.import_module(self.SETTINGS_MODULE)
  File "/usr/local/lib/python3.10/importlib/__init__.py", line 126, in import_module
    return _bootstrap._gcd_import(name[level:], package, level)
  File "<frozen importlib._bootstrap>", line 1050, in _gcd_import
  File "<frozen importlib._bootstrap>", line 1027, in _find_and_load
  File "<frozen importlib._bootstrap>", line 992, in _find_and_load_unlocked
  File "<frozen importlib._bootstrap>", line 241, in _call_with_frames_removed
  File "<frozen importlib._bootstrap>", line 1050, in _gcd_import
  File "<frozen importlib._bootstrap>", line 1027, in _find_and_load
  File "<frozen importlib._bootstrap>", line 1006, in _find_and_load_unlocked
  File "<frozen importlib._bootstrap>", line 688, in _load_unlocked
  File "<frozen importlib._bootstrap_external>", line 883, in exec_module
  File "<frozen importlib._bootstrap>", line 241, in _call_with_frames_removed
  File "/app/src/zeppelin/settings/__init__.py", line 1, in <module>
    from .celery import app as celery_app
ModuleNotFoundError: No module named 'zeppelin.settings.celery'
[2025-08-10 12:02:57 +0000] [54] [INFO] Worker exiting (pid: 54)
[2025-08-10 12:02:57 +0000] [52] [WARNING] Worker with pid 54 was terminated due to signal 15
[2025-08-10 12:02:57 +0000] [52] [INFO] Shutting down: Master
[2025-08-10 12:02:57 +0000] [52] [INFO] Reason: Worker failed to boot.
[2025-08-10 12:03:00 +0000] [55] [INFO] Starting gunicorn 20.1.0
[2025-08-10 12:03:00 +0000] [55] [INFO] Listening at: http://0.0.0.0:8000 (55)
[2025-08-10 12:03:00 +0000] [55] [INFO] Using worker: sync
[2025-08-10 12:03:00 +0000] [56] [INFO] Booting worker with pid: 56
[2025-08-10 12:03:00 +0000] [57] [INFO] Booting worker with pid: 57
[2025-08-10 12:03:01 +0000] [56] [ERROR] Exception in worker process
Traceback (most recent call last):
  File "/usr/local/lib/python3.10/site-packages/gunicorn/arbiter.py", line 589, in spawn_worker
    worker.init_process()
  File "/usr/local/lib/python3.10/site-packages/gunicorn/workers/base.py", line 134, in init_process
    self.load_wsgi()
  File "/usr/local/lib/python3.10/site-packages/gunicorn/workers/base.py", line 146, in load_wsgi
    self.wsgi = self.app.wsgi()
  File "/usr/local/lib/python3.10/site-packages/gunicorn/app/base.py", line 67, in wsgi
    self.callable = self.load()
  File "/usr/local/lib/python3.10/site-packages/gunicorn/app/wsgiapp.py", line 58, in load
    return self.load_wsgiapp()
  File "/usr/local/lib/python3.10/site-packages/gunicorn/app/wsgiapp.py", line 48, in load_wsgiapp
    return util.import_app(self.app_uri)
  File "/usr/local/lib/python3.10/site-packages/gunicorn/util.py", line 359, in import_app
    mod = importlib.import_module(module)
  File "/usr/local/lib/python3.10/importlib/__init__.py", line 126, in import_module
    return _bootstrap._gcd_import(name[level:], package, level)
  File "<frozen importlib._bootstrap>", line 1050, in _gcd_import
  File "<frozen importlib._bootstrap>", line 1027, in _find_and_load
  File "<frozen importlib._bootstrap>", line 1006, in _find_and_load_unlocked
  File "<frozen importlib._bootstrap>", line 688, in _load_unlocked
  File "<frozen importlib._bootstrap_external>", line 883, in exec_module
  File "<frozen importlib._bootstrap>", line 241, in _call_with_frames_removed
  File "/app/src/zeppelin/wsgi.py", line 16, in <module>
    application = get_wsgi_application()
  File "/usr/local/lib/python3.10/site-packages/django/core/wsgi.py", line 12, in get_wsgi_application
    django.setup(set_prefix=False)
  File "/usr/local/lib/python3.10/site-packages/django/__init__.py", line 19, in setup
    configure_logging(settings.LOGGING_CONFIG, settings.LOGGING)
  File "/usr/local/lib/python3.10/site-packages/django/conf/__init__.py", line 92, in __getattr__
    self._setup(name)
  File "/usr/local/lib/python3.10/site-packages/django/conf/__init__.py", line 79, in _setup
    self._wrapped = Settings(settings_module)
  File "/usr/local/lib/python3.10/site-packages/django/conf/__init__.py", line 190, in __init__
    mod = importlib.import_module(self.SETTINGS_MODULE)
  File "/usr/local/lib/python3.10/importlib/__init__.py", line 126, in import_module
    return _bootstrap._gcd_import(name[level:], package, level)
  File "<frozen importlib._bootstrap>", line 1050, in _gcd_import
  File "<frozen importlib._bootstrap>", line 1027, in _find_and_load
  File "<frozen importlib._bootstrap>", line 992, in _find_and_load_unlocked
  File "<frozen importlib._bootstrap>", line 241, in _call_with_frames_removed
  File "<frozen importlib._bootstrap>", line 1050, in _gcd_import
  File "<frozen importlib._bootstrap>", line 1027, in _find_and_load
  File "<frozen importlib._bootstrap>", line 1006, in _find_and_load_unlocked
  File "<frozen importlib._bootstrap>", line 688, in _load_unlocked
  File "<frozen importlib._bootstrap_external>", line 883, in exec_module
  File "<frozen importlib._bootstrap>", line 241, in _call_with_frames_removed
  File "/app/src/zeppelin/settings/__init__.py", line 1, in <module>
    from .celery import app as celery_app
ModuleNotFoundError: No module named 'zeppelin.settings.celery'
[2025-08-10 12:03:01 +0000] [56] [INFO] Worker exiting (pid: 56)
[2025-08-10 12:03:01 +0000] [57] [ERROR] Exception in worker process
Traceback (most recent call last):
  File "/usr/local/lib/python3.10/site-packages/gunicorn/arbiter.py", line 589, in spawn_worker
    worker.init_process()
  File "/usr/local/lib/python3.10/site-packages/gunicorn/workers/base.py", line 134, in init_process
    self.load_wsgi()
  File "/usr/local/lib/python3.10/site-packages/gunicorn/workers/base.py", line 146, in load_wsgi
    self.wsgi = self.app.wsgi()
  File "/usr/local/lib/python3.10/site-packages/gunicorn/app/base.py", line 67, in wsgi
    self.callable = self.load()
  File "/usr/local/lib/python3.10/site-packages/gunicorn/app/wsgiapp.py", line 58, in load
    return self.load_wsgiapp()
  File "/usr/local/lib/python3.10/site-packages/gunicorn/app/wsgiapp.py", line 48, in load_wsgiapp
    return util.import_app(self.app_uri)
  File "/usr/local/lib/python3.10/site-packages/gunicorn/util.py", line 359, in import_app
    mod = importlib.import_module(module)
  File "/usr/local/lib/python3.10/importlib/__init__.py", line 126, in import_module
    return _bootstrap._gcd_import(name[level:], package, level)
  File "<frozen importlib._bootstrap>", line 1050, in _gcd_import
  File "<frozen importlib._bootstrap>", line 1027, in _find_and_load
  File "<frozen importlib._bootstrap>", line 1006, in _find_and_load_unlocked
  File "<frozen importlib._bootstrap>", line 688, in _load_unlocked
  File "<frozen importlib._bootstrap_external>", line 883, in exec_module
  File "<frozen importlib._bootstrap>", line 241, in _call_with_frames_removed
  File "/app/src/zeppelin/wsgi.py", line 16, in <module>
    application = get_wsgi_application()
  File "/usr/local/lib/python3.10/site-packages/django/core/wsgi.py", line 12, in get_wsgi_application
    django.setup(set_prefix=False)
  File "/usr/local/lib/python3.10/site-packages/django/__init__.py", line 19, in setup
    configure_logging(settings.LOGGING_CONFIG, settings.LOGGING)
  File "/usr/local/lib/python3.10/site-packages/django/conf/__init__.py", line 92, in __getattr__
    self._setup(name)
  File "/usr/local/lib/python3.10/site-packages/django/conf/__init__.py", line 79, in _setup
    self._wrapped = Settings(settings_module)
  File "/usr/local/lib/python3.10/site-packages/django/conf/__init__.py", line 190, in __init__
    mod = importlib.import_module(self.SETTINGS_MODULE)
  File "/usr/local/lib/python3.10/importlib/__init__.py", line 126, in import_module
    return _bootstrap._gcd_import(name[level:], package, level)
  File "<frozen importlib._bootstrap>", line 1050, in _gcd_import
  File "<frozen importlib._bootstrap>", line 1027, in _find_and_load
  File "<frozen importlib._bootstrap>", line 992, in _find_and_load_unlocked
  File "<frozen importlib._bootstrap>", line 241, in _call_with_frames_removed
  File "<frozen importlib._bootstrap>", line 1050, in _gcd_import
  File "<frozen importlib._bootstrap>", line 1027, in _find_and_load
  File "<frozen importlib._bootstrap>", line 1006, in _find_and_load_unlocked
  File "<frozen importlib._bootstrap>", line 688, in _load_unlocked
  File "<frozen importlib._bootstrap_external>", line 883, in exec_module
  File "<frozen importlib._bootstrap>", line 241, in _call_with_frames_removed
  File "/app/src/zeppelin/settings/__init__.py", line 1, in <module>
    from .celery import app as celery_app
ModuleNotFoundError: No module named 'zeppelin.settings.celery'
[2025-08-10 12:03:01 +0000] [57] [INFO] Worker exiting (pid: 57)
Traceback (most recent call last):
  File "/usr/local/lib/python3.10/site-packages/gunicorn/arbiter.py", line 209, in run
    self.sleep()
  File "/usr/local/lib/python3.10/site-packages/gunicorn/arbiter.py", line 357, in sleep
    ready = select.select([self.PIPE[0]], [], [], 1.0)
  File "/usr/local/lib/python3.10/site-packages/gunicorn/arbiter.py", line 242, in handle_chld
    self.reap_workers()
  File "/usr/local/lib/python3.10/site-packages/gunicorn/arbiter.py", line 525, in reap_workers
    raise HaltServer(reason, self.WORKER_BOOT_ERROR)
gunicorn.errors.HaltServer: <HaltServer 'Worker failed to boot.' 3>

During handling of the above exception, another exception occurred:

Traceback (most recent call last):
  File "/usr/local/bin/gunicorn", line 8, in <module>
    sys.exit(run())
  File "/usr/local/lib/python3.10/site-packages/gunicorn/app/wsgiapp.py", line 67, in run
    WSGIApplication("%(prog)s [OPTIONS] [APP_MODULE]").run()
  File "/usr/local/lib/python3.10/site-packages/gunicorn/app/base.py", line 231, in run
    super().run()
  File "/usr/local/lib/python3.10/site-packages/gunicorn/app/base.py", line 72, in run
    Arbiter(self).run()
  File "/usr/local/lib/python3.10/site-packages/gunicorn/arbiter.py", line 229, in run
    self.halt(reason=inst.reason, exit_status=inst.exit_status)
  File "/usr/local/lib/python3.10/site-packages/gunicorn/arbiter.py", line 342, in halt
    self.stop()
  File "/usr/local/lib/python3.10/site-packages/gunicorn/arbiter.py", line 393, in stop
    time.sleep(0.1)
  File "/usr/local/lib/python3.10/site-packages/gunicorn/arbiter.py", line 242, in handle_chld
    self.reap_workers()
  File "/usr/local/lib/python3.10/site-packages/gunicorn/arbiter.py", line 525, in reap_workers
    raise HaltServer(reason, self.WORKER_BOOT_ERROR)
gunicorn.errors.HaltServer: <HaltServer 'Worker failed to boot.' 3>
[2025-08-10 12:10:07 +0000] [14] [INFO] Starting gunicorn 20.1.0
[2025-08-10 12:10:07 +0000] [14] [INFO] Listening at: http://0.0.0.0:8000 (14)
[2025-08-10 12:10:07 +0000] [14] [INFO] Using worker: sync
[2025-08-10 12:10:07 +0000] [15] [INFO] Booting worker with pid: 15
[2025-08-10 12:10:07 +0000] [16] [INFO] Booting worker with pid: 16
[2025-08-10 12:16:26 +0000] [14] [INFO] Starting gunicorn 20.1.0
[2025-08-10 12:16:26 +0000] [14] [INFO] Listening at: http://0.0.0.0:8000 (14)
[2025-08-10 12:16:26 +0000] [14] [INFO] Using worker: sync
[2025-08-10 12:16:26 +0000] [15] [INFO] Booting worker with pid: 15
[2025-08-10 12:16:26 +0000] [16] [INFO] Booting worker with pid: 16
