[2025-09-04 17:30:30 +0000] [16] [INFO] Starting gunicorn 20.1.0
[2025-09-04 17:30:30 +0000] [16] [INFO] Listening at: http://0.0.0.0:8000 (16)
[2025-09-04 17:30:30 +0000] [16] [INFO] Using worker: sync
[2025-09-04 17:30:30 +0000] [17] [INFO] Booting worker with pid: 17
[2025-09-04 17:30:30 +0000] [18] [INFO] Booting worker with pid: 18
[2025-09-04 17:30:57 +0000] [16] [INFO] Handling signal: term
[2025-09-04 14:30:57 -0300] [18] [INFO] Worker exiting (pid: 18)
[2025-09-04 14:30:57 -0300] [17] [INFO] Worker exiting (pid: 17)
[2025-09-04 17:33:35 +0000] [14] [INFO] Starting gunicorn 20.1.0
[2025-09-04 17:33:35 +0000] [14] [INFO] Listening at: http://0.0.0.0:8000 (14)
[2025-09-04 17:33:35 +0000] [14] [INFO] Using worker: sync
[2025-09-04 17:33:35 +0000] [15] [INFO] Booting worker with pid: 15
[2025-09-04 17:33:35 +0000] [16] [INFO] Booting worker with pid: 16
[2025-09-04 17:34:33 +0000] [14] [INFO] Handling signal: term
[2025-09-04 14:34:33 -0300] [15] [INFO] Worker exiting (pid: 15)
[2025-09-04 14:34:33 -0300] [16] [INFO] Worker exiting (pid: 16)
[2025-09-04 17:34:34 +0000] [14] [INFO] Shutting down: Master
[2025-09-04 17:39:19 +0000] [16] [INFO] Starting gunicorn 20.1.0
[2025-09-04 17:39:19 +0000] [16] [INFO] Listening at: http://0.0.0.0:8000 (16)
[2025-09-04 17:39:19 +0000] [16] [INFO] Using worker: sync
[2025-09-04 17:39:19 +0000] [17] [INFO] Booting worker with pid: 17
[2025-09-04 17:39:19 +0000] [18] [INFO] Booting worker with pid: 18
[2025-09-04 17:39:47 +0000] [16] [INFO] Handling signal: term
[2025-09-04 14:39:47 -0300] [17] [INFO] Worker exiting (pid: 17)
[2025-09-04 14:39:47 -0300] [18] [INFO] Worker exiting (pid: 18)
[2025-09-04 17:45:09 +0000] [16] [INFO] Starting gunicorn 20.1.0
[2025-09-04 17:45:09 +0000] [16] [INFO] Listening at: http://0.0.0.0:8000 (16)
[2025-09-04 17:45:09 +0000] [16] [INFO] Using worker: sync
[2025-09-04 17:45:09 +0000] [17] [INFO] Booting worker with pid: 17
[2025-09-04 17:45:09 +0000] [18] [INFO] Booting worker with pid: 18
[2025-09-04 17:46:42 +0000] [16] [INFO] Handling signal: term
[2025-09-04 14:46:42 -0300] [18] [INFO] Worker exiting (pid: 18)
[2025-09-04 14:46:42 -0300] [17] [INFO] Worker exiting (pid: 17)
[2025-09-04 17:46:42 +0000] [16] [INFO] Shutting down: Master
[2025-09-04 17:48:50 +0000] [14] [INFO] Starting gunicorn 20.1.0
[2025-09-04 17:48:50 +0000] [14] [INFO] Listening at: http://0.0.0.0:8000 (14)
[2025-09-04 17:48:50 +0000] [14] [INFO] Using worker: sync
[2025-09-04 17:48:50 +0000] [15] [INFO] Booting worker with pid: 15
[2025-09-04 17:48:50 +0000] [16] [INFO] Booting worker with pid: 16
[2025-09-04 14:49:38 -0300] [15] [INFO] Worker reloading: /app/src/zeppelin/urls.py modified
[2025-09-04 14:49:38 -0300] [15] [INFO] Worker exiting (pid: 15)
[2025-09-04 17:49:39 +0000] [36] [INFO] Booting worker with pid: 36
[2025-09-04 14:50:00 -0300] [36] [INFO] Worker reloading: /app/src/zeppelin/settings/base.py modified
[2025-09-04 14:50:00 -0300] [36] [INFO] Worker exiting (pid: 36)
[2025-09-04 17:50:01 +0000] [38] [INFO] Booting worker with pid: 38
[2025-09-04 14:50:01 -0300] [16] [INFO] Worker reloading: /app/src/zeppelin/settings/base.py modified
[2025-09-04 14:50:01 -0300] [16] [INFO] Worker exiting (pid: 16)
[2025-09-04 17:50:01 +0000] [39] [INFO] Booting worker with pid: 39
[2025-09-04 14:50:02 -0300] [38] [ERROR] Exception in worker process
Traceback (most recent call last):
  File "/usr/local/lib/python3.10/site-packages/gunicorn/arbiter.py", line 589, in spawn_worker
    worker.init_process()
  File "/usr/local/lib/python3.10/site-packages/gunicorn/workers/base.py", line 134, in init_process
    self.load_wsgi()
  File "/usr/local/lib/python3.10/site-packages/gunicorn/workers/base.py", line 146, in load_wsgi
    self.wsgi = self.app.wsgi()
  File "/usr/local/lib/python3.10/site-packages/gunicorn/app/base.py", line 67, in wsgi
    self.callable = self.load()
  File "/usr/local/lib/python3.10/site-packages/gunicorn/app/wsgiapp.py", line 58, in load
    return self.load_wsgiapp()
  File "/usr/local/lib/python3.10/site-packages/gunicorn/app/wsgiapp.py", line 48, in load_wsgiapp
    return util.import_app(self.app_uri)
  File "/usr/local/lib/python3.10/site-packages/gunicorn/util.py", line 359, in import_app
    mod = importlib.import_module(module)
  File "/usr/local/lib/python3.10/importlib/__init__.py", line 126, in import_module
    return _bootstrap._gcd_import(name[level:], package, level)
  File "<frozen importlib._bootstrap>", line 1050, in _gcd_import
  File "<frozen importlib._bootstrap>", line 1027, in _find_and_load
  File "<frozen importlib._bootstrap>", line 1006, in _find_and_load_unlocked
  File "<frozen importlib._bootstrap>", line 688, in _load_unlocked
  File "<frozen importlib._bootstrap_external>", line 883, in exec_module
  File "<frozen importlib._bootstrap>", line 241, in _call_with_frames_removed
  File "/app/src/zeppelin/wsgi.py", line 16, in <module>
    application = get_wsgi_application()
  File "/usr/local/lib/python3.10/site-packages/django/core/wsgi.py", line 12, in get_wsgi_application
    django.setup(set_prefix=False)
  File "/usr/local/lib/python3.10/site-packages/django/__init__.py", line 24, in setup
    apps.populate(settings.INSTALLED_APPS)
  File "/usr/local/lib/python3.10/site-packages/django/apps/registry.py", line 124, in populate
    app_config.ready()
  File "/app/src/apps/questionnaire/apps.py", line 8, in ready
    import apps.questionnaire.signals
ModuleNotFoundError: No module named 'apps.questionnaire.signals'
[2025-09-04 14:50:02 -0300] [38] [INFO] Worker exiting (pid: 38)
[2025-09-04 14:50:02 -0300] [39] [ERROR] Exception in worker process
Traceback (most recent call last):
  File "/usr/local/lib/python3.10/site-packages/gunicorn/arbiter.py", line 589, in spawn_worker
    worker.init_process()
  File "/usr/local/lib/python3.10/site-packages/gunicorn/workers/base.py", line 134, in init_process
    self.load_wsgi()
  File "/usr/local/lib/python3.10/site-packages/gunicorn/workers/base.py", line 146, in load_wsgi
    self.wsgi = self.app.wsgi()
  File "/usr/local/lib/python3.10/site-packages/gunicorn/app/base.py", line 67, in wsgi
    self.callable = self.load()
  File "/usr/local/lib/python3.10/site-packages/gunicorn/app/wsgiapp.py", line 58, in load
    return self.load_wsgiapp()
  File "/usr/local/lib/python3.10/site-packages/gunicorn/app/wsgiapp.py", line 48, in load_wsgiapp
    return util.import_app(self.app_uri)
  File "/usr/local/lib/python3.10/site-packages/gunicorn/util.py", line 359, in import_app
    mod = importlib.import_module(module)
  File "/usr/local/lib/python3.10/importlib/__init__.py", line 126, in import_module
    return _bootstrap._gcd_import(name[level:], package, level)
  File "<frozen importlib._bootstrap>", line 1050, in _gcd_import
  File "<frozen importlib._bootstrap>", line 1027, in _find_and_load
  File "<frozen importlib._bootstrap>", line 1006, in _find_and_load_unlocked
  File "<frozen importlib._bootstrap>", line 688, in _load_unlocked
  File "<frozen importlib._bootstrap_external>", line 883, in exec_module
  File "<frozen importlib._bootstrap>", line 241, in _call_with_frames_removed
  File "/app/src/zeppelin/wsgi.py", line 16, in <module>
    application = get_wsgi_application()
  File "/usr/local/lib/python3.10/site-packages/django/core/wsgi.py", line 12, in get_wsgi_application
    django.setup(set_prefix=False)
  File "/usr/local/lib/python3.10/site-packages/django/__init__.py", line 24, in setup
    apps.populate(settings.INSTALLED_APPS)
  File "/usr/local/lib/python3.10/site-packages/django/apps/registry.py", line 124, in populate
    app_config.ready()
  File "/app/src/apps/questionnaire/apps.py", line 8, in ready
    import apps.questionnaire.signals
ModuleNotFoundError: No module named 'apps.questionnaire.signals'
[2025-09-04 14:50:02 -0300] [39] [INFO] Worker exiting (pid: 39)
Traceback (most recent call last):
  File "/usr/local/lib/python3.10/site-packages/gunicorn/arbiter.py", line 209, in run
    self.sleep()
  File "/usr/local/lib/python3.10/site-packages/gunicorn/arbiter.py", line 357, in sleep
    ready = select.select([self.PIPE[0]], [], [], 1.0)
  File "/usr/local/lib/python3.10/site-packages/gunicorn/arbiter.py", line 242, in handle_chld
    self.reap_workers()
  File "/usr/local/lib/python3.10/site-packages/gunicorn/arbiter.py", line 525, in reap_workers
    raise HaltServer(reason, self.WORKER_BOOT_ERROR)
gunicorn.errors.HaltServer: <HaltServer 'Worker failed to boot.' 3>

During handling of the above exception, another exception occurred:

Traceback (most recent call last):
  File "/usr/local/bin/gunicorn", line 8, in <module>
    sys.exit(run())
  File "/usr/local/lib/python3.10/site-packages/gunicorn/app/wsgiapp.py", line 67, in run
    WSGIApplication("%(prog)s [OPTIONS] [APP_MODULE]").run()
  File "/usr/local/lib/python3.10/site-packages/gunicorn/app/base.py", line 231, in run
    super().run()
  File "/usr/local/lib/python3.10/site-packages/gunicorn/app/base.py", line 72, in run
    Arbiter(self).run()
  File "/usr/local/lib/python3.10/site-packages/gunicorn/arbiter.py", line 229, in run
    self.halt(reason=inst.reason, exit_status=inst.exit_status)
  File "/usr/local/lib/python3.10/site-packages/gunicorn/arbiter.py", line 342, in halt
    self.stop()
  File "/usr/local/lib/python3.10/site-packages/gunicorn/arbiter.py", line 393, in stop
    time.sleep(0.1)
  File "/usr/local/lib/python3.10/site-packages/gunicorn/arbiter.py", line 242, in handle_chld
    self.reap_workers()
  File "/usr/local/lib/python3.10/site-packages/gunicorn/arbiter.py", line 525, in reap_workers
    raise HaltServer(reason, self.WORKER_BOOT_ERROR)
gunicorn.errors.HaltServer: <HaltServer 'Worker failed to boot.' 3>
[2025-09-04 17:50:03 +0000] [40] [INFO] Starting gunicorn 20.1.0
[2025-09-04 17:50:03 +0000] [40] [INFO] Listening at: http://0.0.0.0:8000 (40)
[2025-09-04 17:50:03 +0000] [40] [INFO] Using worker: sync
[2025-09-04 17:50:03 +0000] [41] [INFO] Booting worker with pid: 41
[2025-09-04 17:50:03 +0000] [42] [INFO] Booting worker with pid: 42
[2025-09-04 17:50:04 +0000] [40] [INFO] Handling signal: term
[2025-09-04 14:50:04 -0300] [41] [ERROR] Exception in worker process
Traceback (most recent call last):
  File "/usr/local/lib/python3.10/site-packages/gunicorn/arbiter.py", line 589, in spawn_worker
    worker.init_process()
  File "/usr/local/lib/python3.10/site-packages/gunicorn/workers/base.py", line 134, in init_process
    self.load_wsgi()
  File "/usr/local/lib/python3.10/site-packages/gunicorn/workers/base.py", line 146, in load_wsgi
    self.wsgi = self.app.wsgi()
  File "/usr/local/lib/python3.10/site-packages/gunicorn/app/base.py", line 67, in wsgi
    self.callable = self.load()
  File "/usr/local/lib/python3.10/site-packages/gunicorn/app/wsgiapp.py", line 58, in load
    return self.load_wsgiapp()
  File "/usr/local/lib/python3.10/site-packages/gunicorn/app/wsgiapp.py", line 48, in load_wsgiapp
    return util.import_app(self.app_uri)
  File "/usr/local/lib/python3.10/site-packages/gunicorn/util.py", line 359, in import_app
    mod = importlib.import_module(module)
  File "/usr/local/lib/python3.10/importlib/__init__.py", line 126, in import_module
    return _bootstrap._gcd_import(name[level:], package, level)
  File "<frozen importlib._bootstrap>", line 1050, in _gcd_import
  File "<frozen importlib._bootstrap>", line 1027, in _find_and_load
  File "<frozen importlib._bootstrap>", line 1006, in _find_and_load_unlocked
  File "<frozen importlib._bootstrap>", line 688, in _load_unlocked
  File "<frozen importlib._bootstrap_external>", line 883, in exec_module
  File "<frozen importlib._bootstrap>", line 241, in _call_with_frames_removed
  File "/app/src/zeppelin/wsgi.py", line 16, in <module>
    application = get_wsgi_application()
  File "/usr/local/lib/python3.10/site-packages/django/core/wsgi.py", line 12, in get_wsgi_application
    django.setup(set_prefix=False)
  File "/usr/local/lib/python3.10/site-packages/django/__init__.py", line 24, in setup
    apps.populate(settings.INSTALLED_APPS)
  File "/usr/local/lib/python3.10/site-packages/django/apps/registry.py", line 124, in populate
    app_config.ready()
  File "/app/src/apps/questionnaire/apps.py", line 8, in ready
    import apps.questionnaire.signals
ModuleNotFoundError: No module named 'apps.questionnaire.signals'
[2025-09-04 14:50:04 -0300] [41] [INFO] Worker exiting (pid: 41)
Traceback (most recent call last):
  File "/usr/local/lib/python3.10/site-packages/gunicorn/arbiter.py", line 224, in run
    handler()
  File "/usr/local/lib/python3.10/site-packages/gunicorn/arbiter.py", line 257, in handle_term
    raise StopIteration
StopIteration

During handling of the above exception, another exception occurred:

Traceback (most recent call last):
  File "/usr/local/bin/gunicorn", line 8, in <module>
    sys.exit(run())
  File "/usr/local/lib/python3.10/site-packages/gunicorn/app/wsgiapp.py", line 67, in run
    WSGIApplication("%(prog)s [OPTIONS] [APP_MODULE]").run()
  File "/usr/local/lib/python3.10/site-packages/gunicorn/app/base.py", line 231, in run
    super().run()
  File "/usr/local/lib/python3.10/site-packages/gunicorn/app/base.py", line 72, in run
    Arbiter(self).run()
  File "/usr/local/lib/python3.10/site-packages/gunicorn/arbiter.py", line 227, in run
    self.halt()
  File "/usr/local/lib/python3.10/site-packages/gunicorn/arbiter.py", line 342, in halt
    self.stop()
  File "/usr/local/lib/python3.10/site-packages/gunicorn/arbiter.py", line 393, in stop
    time.sleep(0.1)
  File "/usr/local/lib/python3.10/site-packages/gunicorn/arbiter.py", line 242, in handle_chld
    self.reap_workers()
  File "/usr/local/lib/python3.10/site-packages/gunicorn/arbiter.py", line 525, in reap_workers
    raise HaltServer(reason, self.WORKER_BOOT_ERROR)
gunicorn.errors.HaltServer: <HaltServer 'Worker failed to boot.' 3>
[2025-09-04 14:50:04 -0300] [42] [ERROR] Exception in worker process
Traceback (most recent call last):
  File "/usr/local/lib/python3.10/site-packages/gunicorn/arbiter.py", line 589, in spawn_worker
    worker.init_process()
  File "/usr/local/lib/python3.10/site-packages/gunicorn/workers/base.py", line 134, in init_process
    self.load_wsgi()
  File "/usr/local/lib/python3.10/site-packages/gunicorn/workers/base.py", line 146, in load_wsgi
    self.wsgi = self.app.wsgi()
  File "/usr/local/lib/python3.10/site-packages/gunicorn/app/base.py", line 67, in wsgi
    self.callable = self.load()
  File "/usr/local/lib/python3.10/site-packages/gunicorn/app/wsgiapp.py", line 58, in load
    return self.load_wsgiapp()
  File "/usr/local/lib/python3.10/site-packages/gunicorn/app/wsgiapp.py", line 48, in load_wsgiapp
    return util.import_app(self.app_uri)
  File "/usr/local/lib/python3.10/site-packages/gunicorn/util.py", line 359, in import_app
    mod = importlib.import_module(module)
  File "/usr/local/lib/python3.10/importlib/__init__.py", line 126, in import_module
    return _bootstrap._gcd_import(name[level:], package, level)
  File "<frozen importlib._bootstrap>", line 1050, in _gcd_import
  File "<frozen importlib._bootstrap>", line 1027, in _find_and_load
  File "<frozen importlib._bootstrap>", line 1006, in _find_and_load_unlocked
  File "<frozen importlib._bootstrap>", line 688, in _load_unlocked
  File "<frozen importlib._bootstrap_external>", line 883, in exec_module
  File "<frozen importlib._bootstrap>", line 241, in _call_with_frames_removed
  File "/app/src/zeppelin/wsgi.py", line 16, in <module>
    application = get_wsgi_application()
  File "/usr/local/lib/python3.10/site-packages/django/core/wsgi.py", line 12, in get_wsgi_application
    django.setup(set_prefix=False)
  File "/usr/local/lib/python3.10/site-packages/django/__init__.py", line 24, in setup
    apps.populate(settings.INSTALLED_APPS)
  File "/usr/local/lib/python3.10/site-packages/django/apps/registry.py", line 124, in populate
    app_config.ready()
  File "/app/src/apps/questionnaire/apps.py", line 8, in ready
    import apps.questionnaire.signals
ModuleNotFoundError: No module named 'apps.questionnaire.signals'
[2025-09-04 14:50:04 -0300] [42] [INFO] Worker exiting (pid: 42)
[2025-09-04 21:50:20 +0000] [14] [INFO] Starting gunicorn 20.1.0
[2025-09-04 21:50:20 +0000] [14] [INFO] Listening at: http://0.0.0.0:8000 (14)
[2025-09-04 21:50:20 +0000] [14] [INFO] Using worker: sync
[2025-09-04 21:50:20 +0000] [15] [INFO] Booting worker with pid: 15
[2025-09-04 21:50:20 +0000] [16] [INFO] Booting worker with pid: 16
[2025-09-04 21:50:42 +0000] [14] [INFO] Handling signal: term
[2025-09-04 18:50:42 -0300] [16] [INFO] Worker exiting (pid: 16)
[2025-09-04 18:50:42 -0300] [15] [INFO] Worker exiting (pid: 15)
[2025-09-04 21:50:42 +0000] [14] [INFO] Shutting down: Master
[2025-09-04 21:52:32 +0000] [14] [INFO] Starting gunicorn 20.1.0
[2025-09-04 21:52:32 +0000] [14] [INFO] Listening at: http://0.0.0.0:8000 (14)
[2025-09-04 21:52:32 +0000] [14] [INFO] Using worker: sync
[2025-09-04 21:52:32 +0000] [15] [INFO] Booting worker with pid: 15
[2025-09-04 21:52:32 +0000] [16] [INFO] Booting worker with pid: 16
[2025-09-04 21:52:42 +0000] [14] [INFO] Handling signal: term
[2025-09-04 18:52:42 -0300] [16] [INFO] Worker exiting (pid: 16)
[2025-09-04 18:52:42 -0300] [15] [INFO] Worker exiting (pid: 15)
[2025-09-04 21:52:42 +0000] [14] [INFO] Shutting down: Master
[2025-09-04 21:54:06 +0000] [14] [INFO] Starting gunicorn 20.1.0
[2025-09-04 21:54:06 +0000] [14] [INFO] Listening at: http://0.0.0.0:8000 (14)
[2025-09-04 21:54:06 +0000] [14] [INFO] Using worker: sync
[2025-09-04 21:54:06 +0000] [15] [INFO] Booting worker with pid: 15
[2025-09-04 21:54:06 +0000] [16] [INFO] Booting worker with pid: 16
[2025-09-04 21:56:17 +0000] [14] [INFO] Starting gunicorn 20.1.0
[2025-09-04 21:56:17 +0000] [14] [INFO] Listening at: http://0.0.0.0:8000 (14)
[2025-09-04 21:56:17 +0000] [14] [INFO] Using worker: sync
[2025-09-04 21:56:17 +0000] [15] [INFO] Booting worker with pid: 15
[2025-09-04 21:56:17 +0000] [16] [INFO] Booting worker with pid: 16
[2025-09-04 21:58:41 +0000] [14] [INFO] Handling signal: term
[2025-09-04 18:58:41 -0300] [15] [INFO] Worker exiting (pid: 15)
[2025-09-04 18:58:41 -0300] [16] [INFO] Worker exiting (pid: 16)
[2025-09-04 21:58:42 +0000] [14] [INFO] Shutting down: Master
[2025-09-04 21:59:40 +0000] [14] [INFO] Starting gunicorn 20.1.0
[2025-09-04 21:59:40 +0000] [14] [INFO] Listening at: http://0.0.0.0:8000 (14)
[2025-09-04 21:59:40 +0000] [14] [INFO] Using worker: sync
[2025-09-04 21:59:40 +0000] [15] [INFO] Booting worker with pid: 15
[2025-09-04 21:59:40 +0000] [16] [INFO] Booting worker with pid: 16
[2025-09-04 19:00:46 -0300] [15] [INFO] Worker reloading: /app/src/apps/questionnaire/signals.py modified
[2025-09-04 19:00:46 -0300] [15] [INFO] Worker exiting (pid: 15)
[2025-09-04 19:00:46 -0300] [16] [INFO] Worker reloading: /app/src/apps/questionnaire/signals.py modified
[2025-09-04 19:00:46 -0300] [16] [INFO] Worker exiting (pid: 16)
[2025-09-04 22:00:46 +0000] [36] [INFO] Booting worker with pid: 36
[2025-09-04 22:00:46 +0000] [37] [INFO] Booting worker with pid: 37
[2025-09-04 19:00:46 -0300] [36] [ERROR] Exception in worker process
Traceback (most recent call last):
  File "/usr/local/lib/python3.10/site-packages/gunicorn/arbiter.py", line 589, in spawn_worker
    worker.init_process()
  File "/usr/local/lib/python3.10/site-packages/gunicorn/workers/base.py", line 134, in init_process
    self.load_wsgi()
  File "/usr/local/lib/python3.10/site-packages/gunicorn/workers/base.py", line 146, in load_wsgi
    self.wsgi = self.app.wsgi()
  File "/usr/local/lib/python3.10/site-packages/gunicorn/app/base.py", line 67, in wsgi
    self.callable = self.load()
  File "/usr/local/lib/python3.10/site-packages/gunicorn/app/wsgiapp.py", line 58, in load
    return self.load_wsgiapp()
  File "/usr/local/lib/python3.10/site-packages/gunicorn/app/wsgiapp.py", line 48, in load_wsgiapp
    return util.import_app(self.app_uri)
  File "/usr/local/lib/python3.10/site-packages/gunicorn/util.py", line 359, in import_app
    mod = importlib.import_module(module)
  File "/usr/local/lib/python3.10/importlib/__init__.py", line 126, in import_module
    return _bootstrap._gcd_import(name[level:], package, level)
  File "<frozen importlib._bootstrap>", line 1050, in _gcd_import
  File "<frozen importlib._bootstrap>", line 1027, in _find_and_load
  File "<frozen importlib._bootstrap>", line 1006, in _find_and_load_unlocked
  File "<frozen importlib._bootstrap>", line 688, in _load_unlocked
  File "<frozen importlib._bootstrap_external>", line 883, in exec_module
  File "<frozen importlib._bootstrap>", line 241, in _call_with_frames_removed
  File "/app/src/zeppelin/wsgi.py", line 16, in <module>
    application = get_wsgi_application()
  File "/usr/local/lib/python3.10/site-packages/django/core/wsgi.py", line 12, in get_wsgi_application
    django.setup(set_prefix=False)
  File "/usr/local/lib/python3.10/site-packages/django/__init__.py", line 24, in setup
    apps.populate(settings.INSTALLED_APPS)
  File "/usr/local/lib/python3.10/site-packages/django/apps/registry.py", line 124, in populate
    app_config.ready()
  File "/app/src/apps/questionnaire/apps.py", line 8, in ready
    import apps.questionnaire.signals
  File "/app/src/apps/questionnaire/signals.py", line 1, in <module>
    from .models import  QuestionnaireExcel, QuestionnaireGoogleForms
ImportError: cannot import name 'QuestionnaireGoogleForms' from 'apps.questionnaire.models' (/app/src/apps/questionnaire/models.py)
[2025-09-04 19:00:46 -0300] [36] [INFO] Worker exiting (pid: 36)
[2025-09-04 19:00:46 -0300] [37] [ERROR] Exception in worker process
Traceback (most recent call last):
  File "/usr/local/lib/python3.10/site-packages/gunicorn/arbiter.py", line 589, in spawn_worker
    worker.init_process()
  File "/usr/local/lib/python3.10/site-packages/gunicorn/workers/base.py", line 134, in init_process
    self.load_wsgi()
  File "/usr/local/lib/python3.10/site-packages/gunicorn/workers/base.py", line 146, in load_wsgi
    self.wsgi = self.app.wsgi()
  File "/usr/local/lib/python3.10/site-packages/gunicorn/app/base.py", line 67, in wsgi
    self.callable = self.load()
  File "/usr/local/lib/python3.10/site-packages/gunicorn/app/wsgiapp.py", line 58, in load
    return self.load_wsgiapp()
  File "/usr/local/lib/python3.10/site-packages/gunicorn/app/wsgiapp.py", line 48, in load_wsgiapp
    return util.import_app(self.app_uri)
  File "/usr/local/lib/python3.10/site-packages/gunicorn/util.py", line 359, in import_app
    mod = importlib.import_module(module)
  File "/usr/local/lib/python3.10/importlib/__init__.py", line 126, in import_module
    return _bootstrap._gcd_import(name[level:], package, level)
  File "<frozen importlib._bootstrap>", line 1050, in _gcd_import
  File "<frozen importlib._bootstrap>", line 1027, in _find_and_load
  File "<frozen importlib._bootstrap>", line 1006, in _find_and_load_unlocked
  File "<frozen importlib._bootstrap>", line 688, in _load_unlocked
  File "<frozen importlib._bootstrap_external>", line 883, in exec_module
  File "<frozen importlib._bootstrap>", line 241, in _call_with_frames_removed
  File "/app/src/zeppelin/wsgi.py", line 16, in <module>
    application = get_wsgi_application()
  File "/usr/local/lib/python3.10/site-packages/django/core/wsgi.py", line 12, in get_wsgi_application
    django.setup(set_prefix=False)
  File "/usr/local/lib/python3.10/site-packages/django/__init__.py", line 24, in setup
    apps.populate(settings.INSTALLED_APPS)
  File "/usr/local/lib/python3.10/site-packages/django/apps/registry.py", line 124, in populate
    app_config.ready()
  File "/app/src/apps/questionnaire/apps.py", line 8, in ready
    import apps.questionnaire.signals
  File "/app/src/apps/questionnaire/signals.py", line 1, in <module>
    from .models import  QuestionnaireExcel, QuestionnaireGoogleForms
ImportError: cannot import name 'QuestionnaireGoogleForms' from 'apps.questionnaire.models' (/app/src/apps/questionnaire/models.py)
[2025-09-04 19:00:46 -0300] [37] [INFO] Worker exiting (pid: 37)
[2025-09-04 22:00:47 +0000] [14] [WARNING] Worker with pid 37 was terminated due to signal 15
[2025-09-04 22:00:47 +0000] [14] [INFO] Shutting down: Master
[2025-09-04 22:00:47 +0000] [14] [INFO] Reason: Worker failed to boot.
[2025-09-04 22:00:48 +0000] [38] [INFO] Starting gunicorn 20.1.0
[2025-09-04 22:00:48 +0000] [38] [INFO] Listening at: http://0.0.0.0:8000 (38)
[2025-09-04 22:00:48 +0000] [38] [INFO] Using worker: sync
[2025-09-04 22:00:48 +0000] [39] [INFO] Booting worker with pid: 39
[2025-09-04 22:00:48 +0000] [40] [INFO] Booting worker with pid: 40
[2025-09-04 19:00:48 -0300] [39] [ERROR] Exception in worker process
Traceback (most recent call last):
  File "/usr/local/lib/python3.10/site-packages/gunicorn/arbiter.py", line 589, in spawn_worker
    worker.init_process()
  File "/usr/local/lib/python3.10/site-packages/gunicorn/workers/base.py", line 134, in init_process
    self.load_wsgi()
  File "/usr/local/lib/python3.10/site-packages/gunicorn/workers/base.py", line 146, in load_wsgi
    self.wsgi = self.app.wsgi()
  File "/usr/local/lib/python3.10/site-packages/gunicorn/app/base.py", line 67, in wsgi
    self.callable = self.load()
  File "/usr/local/lib/python3.10/site-packages/gunicorn/app/wsgiapp.py", line 58, in load
    return self.load_wsgiapp()
  File "/usr/local/lib/python3.10/site-packages/gunicorn/app/wsgiapp.py", line 48, in load_wsgiapp
    return util.import_app(self.app_uri)
  File "/usr/local/lib/python3.10/site-packages/gunicorn/util.py", line 359, in import_app
    mod = importlib.import_module(module)
  File "/usr/local/lib/python3.10/importlib/__init__.py", line 126, in import_module
    return _bootstrap._gcd_import(name[level:], package, level)
  File "<frozen importlib._bootstrap>", line 1050, in _gcd_import
  File "<frozen importlib._bootstrap>", line 1027, in _find_and_load
  File "<frozen importlib._bootstrap>", line 1006, in _find_and_load_unlocked
  File "<frozen importlib._bootstrap>", line 688, in _load_unlocked
  File "<frozen importlib._bootstrap_external>", line 883, in exec_module
  File "<frozen importlib._bootstrap>", line 241, in _call_with_frames_removed
  File "/app/src/zeppelin/wsgi.py", line 16, in <module>
    application = get_wsgi_application()
  File "/usr/local/lib/python3.10/site-packages/django/core/wsgi.py", line 12, in get_wsgi_application
    django.setup(set_prefix=False)
  File "/usr/local/lib/python3.10/site-packages/django/__init__.py", line 24, in setup
    apps.populate(settings.INSTALLED_APPS)
  File "/usr/local/lib/python3.10/site-packages/django/apps/registry.py", line 124, in populate
    app_config.ready()
  File "/app/src/apps/questionnaire/apps.py", line 8, in ready
    import apps.questionnaire.signals
  File "/app/src/apps/questionnaire/signals.py", line 1, in <module>
    from .models import  QuestionnaireExcel, QuestionnaireGoogleForms
ImportError: cannot import name 'QuestionnaireGoogleForms' from 'apps.questionnaire.models' (/app/src/apps/questionnaire/models.py)
[2025-09-04 19:00:48 -0300] [39] [INFO] Worker exiting (pid: 39)
[2025-09-04 19:00:48 -0300] [40] [ERROR] Exception in worker process
Traceback (most recent call last):
  File "/usr/local/lib/python3.10/site-packages/gunicorn/arbiter.py", line 589, in spawn_worker
    worker.init_process()
  File "/usr/local/lib/python3.10/site-packages/gunicorn/workers/base.py", line 134, in init_process
    self.load_wsgi()
  File "/usr/local/lib/python3.10/site-packages/gunicorn/workers/base.py", line 146, in load_wsgi
    self.wsgi = self.app.wsgi()
  File "/usr/local/lib/python3.10/site-packages/gunicorn/app/base.py", line 67, in wsgi
    self.callable = self.load()
  File "/usr/local/lib/python3.10/site-packages/gunicorn/app/wsgiapp.py", line 58, in load
    return self.load_wsgiapp()
  File "/usr/local/lib/python3.10/site-packages/gunicorn/app/wsgiapp.py", line 48, in load_wsgiapp
    return util.import_app(self.app_uri)
  File "/usr/local/lib/python3.10/site-packages/gunicorn/util.py", line 359, in import_app
    mod = importlib.import_module(module)
  File "/usr/local/lib/python3.10/importlib/__init__.py", line 126, in import_module
    return _bootstrap._gcd_import(name[level:], package, level)
  File "<frozen importlib._bootstrap>", line 1050, in _gcd_import
  File "<frozen importlib._bootstrap>", line 1027, in _find_and_load
  File "<frozen importlib._bootstrap>", line 1006, in _find_and_load_unlocked
  File "<frozen importlib._bootstrap>", line 688, in _load_unlocked
  File "<frozen importlib._bootstrap_external>", line 883, in exec_module
  File "<frozen importlib._bootstrap>", line 241, in _call_with_frames_removed
  File "/app/src/zeppelin/wsgi.py", line 16, in <module>
    application = get_wsgi_application()
  File "/usr/local/lib/python3.10/site-packages/django/core/wsgi.py", line 12, in get_wsgi_application
    django.setup(set_prefix=False)
  File "/usr/local/lib/python3.10/site-packages/django/__init__.py", line 24, in setup
    apps.populate(settings.INSTALLED_APPS)
  File "/usr/local/lib/python3.10/site-packages/django/apps/registry.py", line 124, in populate
    app_config.ready()
  File "/app/src/apps/questionnaire/apps.py", line 8, in ready
    import apps.questionnaire.signals
  File "/app/src/apps/questionnaire/signals.py", line 1, in <module>
    from .models import  QuestionnaireExcel, QuestionnaireGoogleForms
ImportError: cannot import name 'QuestionnaireGoogleForms' from 'apps.questionnaire.models' (/app/src/apps/questionnaire/models.py)
[2025-09-04 19:00:48 -0300] [40] [INFO] Worker exiting (pid: 40)
[2025-09-04 22:00:48 +0000] [38] [WARNING] Worker with pid 40 was terminated due to signal 15
[2025-09-04 22:00:48 +0000] [38] [INFO] Shutting down: Master
[2025-09-04 22:00:48 +0000] [38] [INFO] Reason: Worker failed to boot.
[2025-09-04 22:00:50 +0000] [41] [INFO] Starting gunicorn 20.1.0
[2025-09-04 22:00:50 +0000] [41] [INFO] Listening at: http://0.0.0.0:8000 (41)
[2025-09-04 22:00:50 +0000] [41] [INFO] Using worker: sync
[2025-09-04 22:00:50 +0000] [42] [INFO] Booting worker with pid: 42
[2025-09-04 22:00:50 +0000] [43] [INFO] Booting worker with pid: 43
[2025-09-04 19:00:50 -0300] [42] [ERROR] Exception in worker process
Traceback (most recent call last):
  File "/usr/local/lib/python3.10/site-packages/gunicorn/arbiter.py", line 589, in spawn_worker
    worker.init_process()
  File "/usr/local/lib/python3.10/site-packages/gunicorn/workers/base.py", line 134, in init_process
    self.load_wsgi()
  File "/usr/local/lib/python3.10/site-packages/gunicorn/workers/base.py", line 146, in load_wsgi
    self.wsgi = self.app.wsgi()
  File "/usr/local/lib/python3.10/site-packages/gunicorn/app/base.py", line 67, in wsgi
    self.callable = self.load()
  File "/usr/local/lib/python3.10/site-packages/gunicorn/app/wsgiapp.py", line 58, in load
    return self.load_wsgiapp()
  File "/usr/local/lib/python3.10/site-packages/gunicorn/app/wsgiapp.py", line 48, in load_wsgiapp
    return util.import_app(self.app_uri)
  File "/usr/local/lib/python3.10/site-packages/gunicorn/util.py", line 359, in import_app
    mod = importlib.import_module(module)
  File "/usr/local/lib/python3.10/importlib/__init__.py", line 126, in import_module
    return _bootstrap._gcd_import(name[level:], package, level)
  File "<frozen importlib._bootstrap>", line 1050, in _gcd_import
  File "<frozen importlib._bootstrap>", line 1027, in _find_and_load
  File "<frozen importlib._bootstrap>", line 1006, in _find_and_load_unlocked
  File "<frozen importlib._bootstrap>", line 688, in _load_unlocked
  File "<frozen importlib._bootstrap_external>", line 883, in exec_module
  File "<frozen importlib._bootstrap>", line 241, in _call_with_frames_removed
  File "/app/src/zeppelin/wsgi.py", line 16, in <module>
    application = get_wsgi_application()
  File "/usr/local/lib/python3.10/site-packages/django/core/wsgi.py", line 12, in get_wsgi_application
    django.setup(set_prefix=False)
  File "/usr/local/lib/python3.10/site-packages/django/__init__.py", line 24, in setup
    apps.populate(settings.INSTALLED_APPS)
  File "/usr/local/lib/python3.10/site-packages/django/apps/registry.py", line 124, in populate
    app_config.ready()
  File "/app/src/apps/questionnaire/apps.py", line 8, in ready
    import apps.questionnaire.signals
  File "/app/src/apps/questionnaire/signals.py", line 1, in <module>
    from .models import  QuestionnaireExcel, QuestionnaireGoogleForms
ImportError: cannot import name 'QuestionnaireGoogleForms' from 'apps.questionnaire.models' (/app/src/apps/questionnaire/models.py)
[2025-09-04 19:00:50 -0300] [42] [INFO] Worker exiting (pid: 42)
[2025-09-04 19:00:50 -0300] [43] [ERROR] Exception in worker process
Traceback (most recent call last):
  File "/usr/local/lib/python3.10/site-packages/gunicorn/arbiter.py", line 589, in spawn_worker
    worker.init_process()
  File "/usr/local/lib/python3.10/site-packages/gunicorn/workers/base.py", line 134, in init_process
    self.load_wsgi()
  File "/usr/local/lib/python3.10/site-packages/gunicorn/workers/base.py", line 146, in load_wsgi
    self.wsgi = self.app.wsgi()
  File "/usr/local/lib/python3.10/site-packages/gunicorn/app/base.py", line 67, in wsgi
    self.callable = self.load()
  File "/usr/local/lib/python3.10/site-packages/gunicorn/app/wsgiapp.py", line 58, in load
    return self.load_wsgiapp()
  File "/usr/local/lib/python3.10/site-packages/gunicorn/app/wsgiapp.py", line 48, in load_wsgiapp
    return util.import_app(self.app_uri)
  File "/usr/local/lib/python3.10/site-packages/gunicorn/util.py", line 359, in import_app
    mod = importlib.import_module(module)
  File "/usr/local/lib/python3.10/importlib/__init__.py", line 126, in import_module
    return _bootstrap._gcd_import(name[level:], package, level)
  File "<frozen importlib._bootstrap>", line 1050, in _gcd_import
  File "<frozen importlib._bootstrap>", line 1027, in _find_and_load
  File "<frozen importlib._bootstrap>", line 1006, in _find_and_load_unlocked
  File "<frozen importlib._bootstrap>", line 688, in _load_unlocked
  File "<frozen importlib._bootstrap_external>", line 883, in exec_module
  File "<frozen importlib._bootstrap>", line 241, in _call_with_frames_removed
  File "/app/src/zeppelin/wsgi.py", line 16, in <module>
    application = get_wsgi_application()
  File "/usr/local/lib/python3.10/site-packages/django/core/wsgi.py", line 12, in get_wsgi_application
    django.setup(set_prefix=False)
  File "/usr/local/lib/python3.10/site-packages/django/__init__.py", line 24, in setup
    apps.populate(settings.INSTALLED_APPS)
  File "/usr/local/lib/python3.10/site-packages/django/apps/registry.py", line 124, in populate
    app_config.ready()
  File "/app/src/apps/questionnaire/apps.py", line 8, in ready
    import apps.questionnaire.signals
  File "/app/src/apps/questionnaire/signals.py", line 1, in <module>
    from .models import  QuestionnaireExcel, QuestionnaireGoogleForms
ImportError: cannot import name 'QuestionnaireGoogleForms' from 'apps.questionnaire.models' (/app/src/apps/questionnaire/models.py)
[2025-09-04 19:00:50 -0300] [43] [INFO] Worker exiting (pid: 43)
[2025-09-04 22:00:50 +0000] [41] [WARNING] Worker with pid 43 was terminated due to signal 15
[2025-09-04 22:00:50 +0000] [41] [INFO] Shutting down: Master
[2025-09-04 22:00:50 +0000] [41] [INFO] Reason: Worker failed to boot.
[2025-09-04 22:00:52 +0000] [44] [INFO] Starting gunicorn 20.1.0
[2025-09-04 22:00:52 +0000] [44] [INFO] Listening at: http://0.0.0.0:8000 (44)
[2025-09-04 22:00:52 +0000] [44] [INFO] Using worker: sync
[2025-09-04 22:00:52 +0000] [45] [INFO] Booting worker with pid: 45
[2025-09-04 22:00:52 +0000] [46] [INFO] Booting worker with pid: 46
[2025-09-04 19:00:53 -0300] [46] [ERROR] Exception in worker process
Traceback (most recent call last):
  File "/usr/local/lib/python3.10/site-packages/gunicorn/arbiter.py", line 589, in spawn_worker
    worker.init_process()
  File "/usr/local/lib/python3.10/site-packages/gunicorn/workers/base.py", line 134, in init_process
    self.load_wsgi()
  File "/usr/local/lib/python3.10/site-packages/gunicorn/workers/base.py", line 146, in load_wsgi
    self.wsgi = self.app.wsgi()
  File "/usr/local/lib/python3.10/site-packages/gunicorn/app/base.py", line 67, in wsgi
    self.callable = self.load()
  File "/usr/local/lib/python3.10/site-packages/gunicorn/app/wsgiapp.py", line 58, in load
    return self.load_wsgiapp()
  File "/usr/local/lib/python3.10/site-packages/gunicorn/app/wsgiapp.py", line 48, in load_wsgiapp
    return util.import_app(self.app_uri)
  File "/usr/local/lib/python3.10/site-packages/gunicorn/util.py", line 359, in import_app
    mod = importlib.import_module(module)
  File "/usr/local/lib/python3.10/importlib/__init__.py", line 126, in import_module
    return _bootstrap._gcd_import(name[level:], package, level)
  File "<frozen importlib._bootstrap>", line 1050, in _gcd_import
  File "<frozen importlib._bootstrap>", line 1027, in _find_and_load
  File "<frozen importlib._bootstrap>", line 1006, in _find_and_load_unlocked
  File "<frozen importlib._bootstrap>", line 688, in _load_unlocked
  File "<frozen importlib._bootstrap_external>", line 883, in exec_module
  File "<frozen importlib._bootstrap>", line 241, in _call_with_frames_removed
  File "/app/src/zeppelin/wsgi.py", line 16, in <module>
    application = get_wsgi_application()
  File "/usr/local/lib/python3.10/site-packages/django/core/wsgi.py", line 12, in get_wsgi_application
    django.setup(set_prefix=False)
  File "/usr/local/lib/python3.10/site-packages/django/__init__.py", line 24, in setup
    apps.populate(settings.INSTALLED_APPS)
  File "/usr/local/lib/python3.10/site-packages/django/apps/registry.py", line 124, in populate
    app_config.ready()
  File "/app/src/apps/questionnaire/apps.py", line 8, in ready
    import apps.questionnaire.signals
  File "/app/src/apps/questionnaire/signals.py", line 1, in <module>
    from .models import  QuestionnaireExcel, QuestionnaireGoogleForms
ImportError: cannot import name 'QuestionnaireGoogleForms' from 'apps.questionnaire.models' (/app/src/apps/questionnaire/models.py)
[2025-09-04 19:00:53 -0300] [46] [INFO] Worker exiting (pid: 46)
[2025-09-04 19:00:53 -0300] [45] [ERROR] Exception in worker process
Traceback (most recent call last):
  File "/usr/local/lib/python3.10/site-packages/gunicorn/arbiter.py", line 589, in spawn_worker
    worker.init_process()
  File "/usr/local/lib/python3.10/site-packages/gunicorn/workers/base.py", line 134, in init_process
    self.load_wsgi()
  File "/usr/local/lib/python3.10/site-packages/gunicorn/workers/base.py", line 146, in load_wsgi
    self.wsgi = self.app.wsgi()
  File "/usr/local/lib/python3.10/site-packages/gunicorn/app/base.py", line 67, in wsgi
    self.callable = self.load()
  File "/usr/local/lib/python3.10/site-packages/gunicorn/app/wsgiapp.py", line 58, in load
    return self.load_wsgiapp()
  File "/usr/local/lib/python3.10/site-packages/gunicorn/app/wsgiapp.py", line 48, in load_wsgiapp
    return util.import_app(self.app_uri)
  File "/usr/local/lib/python3.10/site-packages/gunicorn/util.py", line 359, in import_app
    mod = importlib.import_module(module)
  File "/usr/local/lib/python3.10/importlib/__init__.py", line 126, in import_module
    return _bootstrap._gcd_import(name[level:], package, level)
  File "<frozen importlib._bootstrap>", line 1050, in _gcd_import
  File "<frozen importlib._bootstrap>", line 1027, in _find_and_load
  File "<frozen importlib._bootstrap>", line 1006, in _find_and_load_unlocked
  File "<frozen importlib._bootstrap>", line 688, in _load_unlocked
  File "<frozen importlib._bootstrap_external>", line 883, in exec_module
  File "<frozen importlib._bootstrap>", line 241, in _call_with_frames_removed
  File "/app/src/zeppelin/wsgi.py", line 16, in <module>
    application = get_wsgi_application()
  File "/usr/local/lib/python3.10/site-packages/django/core/wsgi.py", line 12, in get_wsgi_application
    django.setup(set_prefix=False)
  File "/usr/local/lib/python3.10/site-packages/django/__init__.py", line 24, in setup
    apps.populate(settings.INSTALLED_APPS)
  File "/usr/local/lib/python3.10/site-packages/django/apps/registry.py", line 124, in populate
    app_config.ready()
  File "/app/src/apps/questionnaire/apps.py", line 8, in ready
    import apps.questionnaire.signals
  File "/app/src/apps/questionnaire/signals.py", line 1, in <module>
    from .models import  QuestionnaireExcel, QuestionnaireGoogleForms
ImportError: cannot import name 'QuestionnaireGoogleForms' from 'apps.questionnaire.models' (/app/src/apps/questionnaire/models.py)
[2025-09-04 19:00:53 -0300] [45] [INFO] Worker exiting (pid: 45)
[2025-09-04 22:00:53 +0000] [44] [WARNING] Worker with pid 45 was terminated due to signal 15
[2025-09-04 22:00:53 +0000] [44] [INFO] Shutting down: Master
[2025-09-04 22:00:53 +0000] [44] [INFO] Reason: Worker failed to boot.
[2025-09-04 22:00:54 +0000] [47] [INFO] Starting gunicorn 20.1.0
[2025-09-04 22:00:54 +0000] [47] [INFO] Listening at: http://0.0.0.0:8000 (47)
[2025-09-04 22:00:54 +0000] [47] [INFO] Using worker: sync
[2025-09-04 22:00:54 +0000] [48] [INFO] Booting worker with pid: 48
[2025-09-04 22:00:54 +0000] [49] [INFO] Booting worker with pid: 49
[2025-09-04 19:00:55 -0300] [48] [ERROR] Exception in worker process
Traceback (most recent call last):
  File "/usr/local/lib/python3.10/site-packages/gunicorn/arbiter.py", line 589, in spawn_worker
    worker.init_process()
  File "/usr/local/lib/python3.10/site-packages/gunicorn/workers/base.py", line 134, in init_process
    self.load_wsgi()
  File "/usr/local/lib/python3.10/site-packages/gunicorn/workers/base.py", line 146, in load_wsgi
    self.wsgi = self.app.wsgi()
  File "/usr/local/lib/python3.10/site-packages/gunicorn/app/base.py", line 67, in wsgi
    self.callable = self.load()
  File "/usr/local/lib/python3.10/site-packages/gunicorn/app/wsgiapp.py", line 58, in load
    return self.load_wsgiapp()
  File "/usr/local/lib/python3.10/site-packages/gunicorn/app/wsgiapp.py", line 48, in load_wsgiapp
    return util.import_app(self.app_uri)
  File "/usr/local/lib/python3.10/site-packages/gunicorn/util.py", line 359, in import_app
    mod = importlib.import_module(module)
  File "/usr/local/lib/python3.10/importlib/__init__.py", line 126, in import_module
    return _bootstrap._gcd_import(name[level:], package, level)
  File "<frozen importlib._bootstrap>", line 1050, in _gcd_import
  File "<frozen importlib._bootstrap>", line 1027, in _find_and_load
  File "<frozen importlib._bootstrap>", line 1006, in _find_and_load_unlocked
  File "<frozen importlib._bootstrap>", line 688, in _load_unlocked
  File "<frozen importlib._bootstrap_external>", line 883, in exec_module
  File "<frozen importlib._bootstrap>", line 241, in _call_with_frames_removed
  File "/app/src/zeppelin/wsgi.py", line 16, in <module>
    application = get_wsgi_application()
  File "/usr/local/lib/python3.10/site-packages/django/core/wsgi.py", line 12, in get_wsgi_application
    django.setup(set_prefix=False)
  File "/usr/local/lib/python3.10/site-packages/django/__init__.py", line 24, in setup
    apps.populate(settings.INSTALLED_APPS)
  File "/usr/local/lib/python3.10/site-packages/django/apps/registry.py", line 124, in populate
    app_config.ready()
  File "/app/src/apps/questionnaire/apps.py", line 8, in ready
    import apps.questionnaire.signals
  File "/app/src/apps/questionnaire/signals.py", line 1, in <module>
    from .models import  QuestionnaireExcel, QuestionnaireGoogleForms
ImportError: cannot import name 'QuestionnaireGoogleForms' from 'apps.questionnaire.models' (/app/src/apps/questionnaire/models.py)
[2025-09-04 19:00:55 -0300] [48] [INFO] Worker exiting (pid: 48)
[2025-09-04 19:00:55 -0300] [49] [ERROR] Exception in worker process
Traceback (most recent call last):
  File "/usr/local/lib/python3.10/site-packages/gunicorn/arbiter.py", line 589, in spawn_worker
    worker.init_process()
  File "/usr/local/lib/python3.10/site-packages/gunicorn/workers/base.py", line 134, in init_process
    self.load_wsgi()
  File "/usr/local/lib/python3.10/site-packages/gunicorn/workers/base.py", line 146, in load_wsgi
    self.wsgi = self.app.wsgi()
  File "/usr/local/lib/python3.10/site-packages/gunicorn/app/base.py", line 67, in wsgi
    self.callable = self.load()
  File "/usr/local/lib/python3.10/site-packages/gunicorn/app/wsgiapp.py", line 58, in load
    return self.load_wsgiapp()
  File "/usr/local/lib/python3.10/site-packages/gunicorn/app/wsgiapp.py", line 48, in load_wsgiapp
    return util.import_app(self.app_uri)
  File "/usr/local/lib/python3.10/site-packages/gunicorn/util.py", line 359, in import_app
    mod = importlib.import_module(module)
  File "/usr/local/lib/python3.10/importlib/__init__.py", line 126, in import_module
    return _bootstrap._gcd_import(name[level:], package, level)
  File "<frozen importlib._bootstrap>", line 1050, in _gcd_import
  File "<frozen importlib._bootstrap>", line 1027, in _find_and_load
  File "<frozen importlib._bootstrap>", line 1006, in _find_and_load_unlocked
  File "<frozen importlib._bootstrap>", line 688, in _load_unlocked
  File "<frozen importlib._bootstrap_external>", line 883, in exec_module
  File "<frozen importlib._bootstrap>", line 241, in _call_with_frames_removed
  File "/app/src/zeppelin/wsgi.py", line 16, in <module>
    application = get_wsgi_application()
  File "/usr/local/lib/python3.10/site-packages/django/core/wsgi.py", line 12, in get_wsgi_application
    django.setup(set_prefix=False)
  File "/usr/local/lib/python3.10/site-packages/django/__init__.py", line 24, in setup
    apps.populate(settings.INSTALLED_APPS)
  File "/usr/local/lib/python3.10/site-packages/django/apps/registry.py", line 124, in populate
    app_config.ready()
  File "/app/src/apps/questionnaire/apps.py", line 8, in ready
    import apps.questionnaire.signals
  File "/app/src/apps/questionnaire/signals.py", line 1, in <module>
    from .models import  QuestionnaireExcel, QuestionnaireGoogleForms
ImportError: cannot import name 'QuestionnaireGoogleForms' from 'apps.questionnaire.models' (/app/src/apps/questionnaire/models.py)
[2025-09-04 19:00:55 -0300] [49] [INFO] Worker exiting (pid: 49)
[2025-09-04 22:00:55 +0000] [47] [WARNING] Worker with pid 49 was terminated due to signal 15
[2025-09-04 22:00:55 +0000] [47] [INFO] Shutting down: Master
[2025-09-04 22:00:55 +0000] [47] [INFO] Reason: Worker failed to boot.
[2025-09-04 22:00:56 +0000] [50] [INFO] Starting gunicorn 20.1.0
[2025-09-04 22:00:56 +0000] [50] [INFO] Listening at: http://0.0.0.0:8000 (50)
[2025-09-04 22:00:56 +0000] [50] [INFO] Using worker: sync
[2025-09-04 22:00:56 +0000] [51] [INFO] Booting worker with pid: 51
[2025-09-04 22:00:56 +0000] [52] [INFO] Booting worker with pid: 52
[2025-09-04 19:00:57 -0300] [51] [ERROR] Exception in worker process
Traceback (most recent call last):
  File "/usr/local/lib/python3.10/site-packages/gunicorn/arbiter.py", line 589, in spawn_worker
    worker.init_process()
  File "/usr/local/lib/python3.10/site-packages/gunicorn/workers/base.py", line 134, in init_process
    self.load_wsgi()
  File "/usr/local/lib/python3.10/site-packages/gunicorn/workers/base.py", line 146, in load_wsgi
    self.wsgi = self.app.wsgi()
  File "/usr/local/lib/python3.10/site-packages/gunicorn/app/base.py", line 67, in wsgi
    self.callable = self.load()
  File "/usr/local/lib/python3.10/site-packages/gunicorn/app/wsgiapp.py", line 58, in load
    return self.load_wsgiapp()
  File "/usr/local/lib/python3.10/site-packages/gunicorn/app/wsgiapp.py", line 48, in load_wsgiapp
    return util.import_app(self.app_uri)
  File "/usr/local/lib/python3.10/site-packages/gunicorn/util.py", line 359, in import_app
    mod = importlib.import_module(module)
  File "/usr/local/lib/python3.10/importlib/__init__.py", line 126, in import_module
    return _bootstrap._gcd_import(name[level:], package, level)
  File "<frozen importlib._bootstrap>", line 1050, in _gcd_import
  File "<frozen importlib._bootstrap>", line 1027, in _find_and_load
  File "<frozen importlib._bootstrap>", line 1006, in _find_and_load_unlocked
  File "<frozen importlib._bootstrap>", line 688, in _load_unlocked
  File "<frozen importlib._bootstrap_external>", line 883, in exec_module
  File "<frozen importlib._bootstrap>", line 241, in _call_with_frames_removed
  File "/app/src/zeppelin/wsgi.py", line 16, in <module>
    application = get_wsgi_application()
  File "/usr/local/lib/python3.10/site-packages/django/core/wsgi.py", line 12, in get_wsgi_application
    django.setup(set_prefix=False)
  File "/usr/local/lib/python3.10/site-packages/django/__init__.py", line 24, in setup
    apps.populate(settings.INSTALLED_APPS)
  File "/usr/local/lib/python3.10/site-packages/django/apps/registry.py", line 124, in populate
    app_config.ready()
  File "/app/src/apps/questionnaire/apps.py", line 8, in ready
    import apps.questionnaire.signals
  File "/app/src/apps/questionnaire/signals.py", line 1, in <module>
    from .models import  QuestionnaireExcel, QuestionnaireGoogleForms
ImportError: cannot import name 'QuestionnaireGoogleForms' from 'apps.questionnaire.models' (/app/src/apps/questionnaire/models.py)
[2025-09-04 19:00:57 -0300] [51] [INFO] Worker exiting (pid: 51)
[2025-09-04 19:00:57 -0300] [52] [ERROR] Exception in worker process
Traceback (most recent call last):
  File "/usr/local/lib/python3.10/site-packages/gunicorn/arbiter.py", line 589, in spawn_worker
    worker.init_process()
  File "/usr/local/lib/python3.10/site-packages/gunicorn/workers/base.py", line 134, in init_process
    self.load_wsgi()
  File "/usr/local/lib/python3.10/site-packages/gunicorn/workers/base.py", line 146, in load_wsgi
    self.wsgi = self.app.wsgi()
  File "/usr/local/lib/python3.10/site-packages/gunicorn/app/base.py", line 67, in wsgi
    self.callable = self.load()
  File "/usr/local/lib/python3.10/site-packages/gunicorn/app/wsgiapp.py", line 58, in load
    return self.load_wsgiapp()
  File "/usr/local/lib/python3.10/site-packages/gunicorn/app/wsgiapp.py", line 48, in load_wsgiapp
    return util.import_app(self.app_uri)
  File "/usr/local/lib/python3.10/site-packages/gunicorn/util.py", line 359, in import_app
    mod = importlib.import_module(module)
  File "/usr/local/lib/python3.10/importlib/__init__.py", line 126, in import_module
    return _bootstrap._gcd_import(name[level:], package, level)
  File "<frozen importlib._bootstrap>", line 1050, in _gcd_import
  File "<frozen importlib._bootstrap>", line 1027, in _find_and_load
  File "<frozen importlib._bootstrap>", line 1006, in _find_and_load_unlocked
  File "<frozen importlib._bootstrap>", line 688, in _load_unlocked
  File "<frozen importlib._bootstrap_external>", line 883, in exec_module
  File "<frozen importlib._bootstrap>", line 241, in _call_with_frames_removed
  File "/app/src/zeppelin/wsgi.py", line 16, in <module>
    application = get_wsgi_application()
  File "/usr/local/lib/python3.10/site-packages/django/core/wsgi.py", line 12, in get_wsgi_application
    django.setup(set_prefix=False)
  File "/usr/local/lib/python3.10/site-packages/django/__init__.py", line 24, in setup
    apps.populate(settings.INSTALLED_APPS)
  File "/usr/local/lib/python3.10/site-packages/django/apps/registry.py", line 124, in populate
    app_config.ready()
  File "/app/src/apps/questionnaire/apps.py", line 8, in ready
    import apps.questionnaire.signals
  File "/app/src/apps/questionnaire/signals.py", line 1, in <module>
    from .models import  QuestionnaireExcel, QuestionnaireGoogleForms
ImportError: cannot import name 'QuestionnaireGoogleForms' from 'apps.questionnaire.models' (/app/src/apps/questionnaire/models.py)
[2025-09-04 19:00:57 -0300] [52] [INFO] Worker exiting (pid: 52)
Traceback (most recent call last):
  File "/usr/local/lib/python3.10/site-packages/gunicorn/arbiter.py", line 209, in run
    self.sleep()
  File "/usr/local/lib/python3.10/site-packages/gunicorn/arbiter.py", line 357, in sleep
    ready = select.select([self.PIPE[0]], [], [], 1.0)
  File "/usr/local/lib/python3.10/site-packages/gunicorn/arbiter.py", line 242, in handle_chld
    self.reap_workers()
  File "/usr/local/lib/python3.10/site-packages/gunicorn/arbiter.py", line 525, in reap_workers
    raise HaltServer(reason, self.WORKER_BOOT_ERROR)
gunicorn.errors.HaltServer: <HaltServer 'Worker failed to boot.' 3>

During handling of the above exception, another exception occurred:

Traceback (most recent call last):
  File "/usr/local/bin/gunicorn", line 8, in <module>
    sys.exit(run())
  File "/usr/local/lib/python3.10/site-packages/gunicorn/app/wsgiapp.py", line 67, in run
    WSGIApplication("%(prog)s [OPTIONS] [APP_MODULE]").run()
  File "/usr/local/lib/python3.10/site-packages/gunicorn/app/base.py", line 231, in run
    super().run()
  File "/usr/local/lib/python3.10/site-packages/gunicorn/app/base.py", line 72, in run
    Arbiter(self).run()
  File "/usr/local/lib/python3.10/site-packages/gunicorn/arbiter.py", line 229, in run
    self.halt(reason=inst.reason, exit_status=inst.exit_status)
  File "/usr/local/lib/python3.10/site-packages/gunicorn/arbiter.py", line 342, in halt
    self.stop()
  File "/usr/local/lib/python3.10/site-packages/gunicorn/arbiter.py", line 393, in stop
    time.sleep(0.1)
  File "/usr/local/lib/python3.10/site-packages/gunicorn/arbiter.py", line 242, in handle_chld
    self.reap_workers()
  File "/usr/local/lib/python3.10/site-packages/gunicorn/arbiter.py", line 525, in reap_workers
    raise HaltServer(reason, self.WORKER_BOOT_ERROR)
gunicorn.errors.HaltServer: <HaltServer 'Worker failed to boot.' 3>
[2025-09-04 22:00:59 +0000] [53] [INFO] Starting gunicorn 20.1.0
[2025-09-04 22:00:59 +0000] [53] [INFO] Listening at: http://0.0.0.0:8000 (53)
[2025-09-04 22:00:59 +0000] [53] [INFO] Using worker: sync
[2025-09-04 22:00:59 +0000] [54] [INFO] Booting worker with pid: 54
[2025-09-04 22:00:59 +0000] [55] [INFO] Booting worker with pid: 55
[2025-09-04 19:00:59 -0300] [54] [ERROR] Exception in worker process
Traceback (most recent call last):
  File "/usr/local/lib/python3.10/site-packages/gunicorn/arbiter.py", line 589, in spawn_worker
    worker.init_process()
  File "/usr/local/lib/python3.10/site-packages/gunicorn/workers/base.py", line 134, in init_process
    self.load_wsgi()
  File "/usr/local/lib/python3.10/site-packages/gunicorn/workers/base.py", line 146, in load_wsgi
    self.wsgi = self.app.wsgi()
  File "/usr/local/lib/python3.10/site-packages/gunicorn/app/base.py", line 67, in wsgi
    self.callable = self.load()
  File "/usr/local/lib/python3.10/site-packages/gunicorn/app/wsgiapp.py", line 58, in load
    return self.load_wsgiapp()
  File "/usr/local/lib/python3.10/site-packages/gunicorn/app/wsgiapp.py", line 48, in load_wsgiapp
    return util.import_app(self.app_uri)
  File "/usr/local/lib/python3.10/site-packages/gunicorn/util.py", line 359, in import_app
    mod = importlib.import_module(module)
  File "/usr/local/lib/python3.10/importlib/__init__.py", line 126, in import_module
    return _bootstrap._gcd_import(name[level:], package, level)
  File "<frozen importlib._bootstrap>", line 1050, in _gcd_import
  File "<frozen importlib._bootstrap>", line 1027, in _find_and_load
  File "<frozen importlib._bootstrap>", line 1006, in _find_and_load_unlocked
  File "<frozen importlib._bootstrap>", line 688, in _load_unlocked
  File "<frozen importlib._bootstrap_external>", line 883, in exec_module
  File "<frozen importlib._bootstrap>", line 241, in _call_with_frames_removed
  File "/app/src/zeppelin/wsgi.py", line 16, in <module>
    application = get_wsgi_application()
  File "/usr/local/lib/python3.10/site-packages/django/core/wsgi.py", line 12, in get_wsgi_application
    django.setup(set_prefix=False)
  File "/usr/local/lib/python3.10/site-packages/django/__init__.py", line 24, in setup
    apps.populate(settings.INSTALLED_APPS)
  File "/usr/local/lib/python3.10/site-packages/django/apps/registry.py", line 124, in populate
    app_config.ready()
  File "/app/src/apps/questionnaire/apps.py", line 8, in ready
    import apps.questionnaire.signals
  File "/app/src/apps/questionnaire/signals.py", line 1, in <module>
    from .models import  QuestionnaireExcel, QuestionnaireGoogleForms
ImportError: cannot import name 'QuestionnaireGoogleForms' from 'apps.questionnaire.models' (/app/src/apps/questionnaire/models.py)
[2025-09-04 19:00:59 -0300] [54] [INFO] Worker exiting (pid: 54)
[2025-09-04 19:00:59 -0300] [55] [ERROR] Exception in worker process
Traceback (most recent call last):
  File "/usr/local/lib/python3.10/site-packages/gunicorn/arbiter.py", line 589, in spawn_worker
    worker.init_process()
  File "/usr/local/lib/python3.10/site-packages/gunicorn/workers/base.py", line 134, in init_process
    self.load_wsgi()
  File "/usr/local/lib/python3.10/site-packages/gunicorn/workers/base.py", line 146, in load_wsgi
    self.wsgi = self.app.wsgi()
  File "/usr/local/lib/python3.10/site-packages/gunicorn/app/base.py", line 67, in wsgi
    self.callable = self.load()
  File "/usr/local/lib/python3.10/site-packages/gunicorn/app/wsgiapp.py", line 58, in load
    return self.load_wsgiapp()
  File "/usr/local/lib/python3.10/site-packages/gunicorn/app/wsgiapp.py", line 48, in load_wsgiapp
    return util.import_app(self.app_uri)
  File "/usr/local/lib/python3.10/site-packages/gunicorn/util.py", line 359, in import_app
    mod = importlib.import_module(module)
  File "/usr/local/lib/python3.10/importlib/__init__.py", line 126, in import_module
    return _bootstrap._gcd_import(name[level:], package, level)
  File "<frozen importlib._bootstrap>", line 1050, in _gcd_import
  File "<frozen importlib._bootstrap>", line 1027, in _find_and_load
  File "<frozen importlib._bootstrap>", line 1006, in _find_and_load_unlocked
  File "<frozen importlib._bootstrap>", line 688, in _load_unlocked
  File "<frozen importlib._bootstrap_external>", line 883, in exec_module
  File "<frozen importlib._bootstrap>", line 241, in _call_with_frames_removed
  File "/app/src/zeppelin/wsgi.py", line 16, in <module>
    application = get_wsgi_application()
  File "/usr/local/lib/python3.10/site-packages/django/core/wsgi.py", line 12, in get_wsgi_application
    django.setup(set_prefix=False)
  File "/usr/local/lib/python3.10/site-packages/django/__init__.py", line 24, in setup
    apps.populate(settings.INSTALLED_APPS)
  File "/usr/local/lib/python3.10/site-packages/django/apps/registry.py", line 124, in populate
    app_config.ready()
  File "/app/src/apps/questionnaire/apps.py", line 8, in ready
    import apps.questionnaire.signals
  File "/app/src/apps/questionnaire/signals.py", line 1, in <module>
    from .models import  QuestionnaireExcel, QuestionnaireGoogleForms
ImportError: cannot import name 'QuestionnaireGoogleForms' from 'apps.questionnaire.models' (/app/src/apps/questionnaire/models.py)
[2025-09-04 19:00:59 -0300] [55] [INFO] Worker exiting (pid: 55)
[2025-09-04 22:01:00 +0000] [53] [WARNING] Worker with pid 55 was terminated due to signal 15
[2025-09-04 22:01:00 +0000] [53] [INFO] Shutting down: Master
[2025-09-04 22:01:00 +0000] [53] [INFO] Reason: Worker failed to boot.
[2025-09-04 22:01:03 +0000] [56] [INFO] Starting gunicorn 20.1.0
[2025-09-04 22:01:03 +0000] [56] [INFO] Listening at: http://0.0.0.0:8000 (56)
[2025-09-04 22:01:03 +0000] [56] [INFO] Using worker: sync
[2025-09-04 22:01:03 +0000] [57] [INFO] Booting worker with pid: 57
[2025-09-04 22:01:03 +0000] [58] [INFO] Booting worker with pid: 58
[2025-09-04 19:01:03 -0300] [57] [ERROR] Exception in worker process
Traceback (most recent call last):
  File "/usr/local/lib/python3.10/site-packages/gunicorn/arbiter.py", line 589, in spawn_worker
    worker.init_process()
  File "/usr/local/lib/python3.10/site-packages/gunicorn/workers/base.py", line 134, in init_process
    self.load_wsgi()
  File "/usr/local/lib/python3.10/site-packages/gunicorn/workers/base.py", line 146, in load_wsgi
    self.wsgi = self.app.wsgi()
  File "/usr/local/lib/python3.10/site-packages/gunicorn/app/base.py", line 67, in wsgi
    self.callable = self.load()
  File "/usr/local/lib/python3.10/site-packages/gunicorn/app/wsgiapp.py", line 58, in load
    return self.load_wsgiapp()
  File "/usr/local/lib/python3.10/site-packages/gunicorn/app/wsgiapp.py", line 48, in load_wsgiapp
    return util.import_app(self.app_uri)
  File "/usr/local/lib/python3.10/site-packages/gunicorn/util.py", line 359, in import_app
    mod = importlib.import_module(module)
  File "/usr/local/lib/python3.10/importlib/__init__.py", line 126, in import_module
    return _bootstrap._gcd_import(name[level:], package, level)
  File "<frozen importlib._bootstrap>", line 1050, in _gcd_import
  File "<frozen importlib._bootstrap>", line 1027, in _find_and_load
  File "<frozen importlib._bootstrap>", line 1006, in _find_and_load_unlocked
  File "<frozen importlib._bootstrap>", line 688, in _load_unlocked
  File "<frozen importlib._bootstrap_external>", line 883, in exec_module
  File "<frozen importlib._bootstrap>", line 241, in _call_with_frames_removed
  File "/app/src/zeppelin/wsgi.py", line 16, in <module>
    application = get_wsgi_application()
  File "/usr/local/lib/python3.10/site-packages/django/core/wsgi.py", line 12, in get_wsgi_application
    django.setup(set_prefix=False)
  File "/usr/local/lib/python3.10/site-packages/django/__init__.py", line 24, in setup
    apps.populate(settings.INSTALLED_APPS)
  File "/usr/local/lib/python3.10/site-packages/django/apps/registry.py", line 124, in populate
    app_config.ready()
  File "/app/src/apps/questionnaire/apps.py", line 8, in ready
    import apps.questionnaire.signals
  File "/app/src/apps/questionnaire/signals.py", line 1, in <module>
    from .models import  QuestionnaireExcel, QuestionnaireGoogleForms
ImportError: cannot import name 'QuestionnaireGoogleForms' from 'apps.questionnaire.models' (/app/src/apps/questionnaire/models.py)
[2025-09-04 19:01:03 -0300] [57] [INFO] Worker exiting (pid: 57)
[2025-09-04 19:01:03 -0300] [58] [ERROR] Exception in worker process
Traceback (most recent call last):
  File "/usr/local/lib/python3.10/site-packages/gunicorn/arbiter.py", line 589, in spawn_worker
    worker.init_process()
  File "/usr/local/lib/python3.10/site-packages/gunicorn/workers/base.py", line 134, in init_process
    self.load_wsgi()
  File "/usr/local/lib/python3.10/site-packages/gunicorn/workers/base.py", line 146, in load_wsgi
    self.wsgi = self.app.wsgi()
  File "/usr/local/lib/python3.10/site-packages/gunicorn/app/base.py", line 67, in wsgi
    self.callable = self.load()
  File "/usr/local/lib/python3.10/site-packages/gunicorn/app/wsgiapp.py", line 58, in load
    return self.load_wsgiapp()
  File "/usr/local/lib/python3.10/site-packages/gunicorn/app/wsgiapp.py", line 48, in load_wsgiapp
    return util.import_app(self.app_uri)
  File "/usr/local/lib/python3.10/site-packages/gunicorn/util.py", line 359, in import_app
    mod = importlib.import_module(module)
  File "/usr/local/lib/python3.10/importlib/__init__.py", line 126, in import_module
    return _bootstrap._gcd_import(name[level:], package, level)
  File "<frozen importlib._bootstrap>", line 1050, in _gcd_import
  File "<frozen importlib._bootstrap>", line 1027, in _find_and_load
  File "<frozen importlib._bootstrap>", line 1006, in _find_and_load_unlocked
  File "<frozen importlib._bootstrap>", line 688, in _load_unlocked
  File "<frozen importlib._bootstrap_external>", line 883, in exec_module
  File "<frozen importlib._bootstrap>", line 241, in _call_with_frames_removed
  File "/app/src/zeppelin/wsgi.py", line 16, in <module>
    application = get_wsgi_application()
  File "/usr/local/lib/python3.10/site-packages/django/core/wsgi.py", line 12, in get_wsgi_application
    django.setup(set_prefix=False)
  File "/usr/local/lib/python3.10/site-packages/django/__init__.py", line 24, in setup
    apps.populate(settings.INSTALLED_APPS)
  File "/usr/local/lib/python3.10/site-packages/django/apps/registry.py", line 124, in populate
    app_config.ready()
  File "/app/src/apps/questionnaire/apps.py", line 8, in ready
    import apps.questionnaire.signals
  File "/app/src/apps/questionnaire/signals.py", line 1, in <module>
    from .models import  QuestionnaireExcel, QuestionnaireGoogleForms
ImportError: cannot import name 'QuestionnaireGoogleForms' from 'apps.questionnaire.models' (/app/src/apps/questionnaire/models.py)
[2025-09-04 19:01:03 -0300] [58] [INFO] Worker exiting (pid: 58)
[2025-09-04 22:01:03 +0000] [56] [WARNING] Worker with pid 58 was terminated due to signal 15
[2025-09-04 22:01:03 +0000] [56] [INFO] Shutting down: Master
[2025-09-04 22:01:03 +0000] [56] [INFO] Reason: Worker failed to boot.
[2025-09-04 22:38:10 +0000] [12] [INFO] Starting gunicorn 20.1.0
[2025-09-04 22:38:10 +0000] [12] [INFO] Listening at: http://0.0.0.0:8000 (12)
[2025-09-04 22:38:10 +0000] [12] [INFO] Using worker: sync
[2025-09-04 22:38:10 +0000] [13] [INFO] Booting worker with pid: 13
[2025-09-04 22:38:10 +0000] [14] [INFO] Booting worker with pid: 14
[2025-09-04 19:40:47 -0300] [14] [INFO] Worker reloading: /app/src/apps/questionnaire/api_views.py modified
[2025-09-04 19:40:47 -0300] [13] [INFO] Worker reloading: /app/src/apps/questionnaire/api_views.py modified
[2025-09-04 19:40:47 -0300] [14] [INFO] Worker exiting (pid: 14)
[2025-09-04 19:40:47 -0300] [13] [INFO] Worker exiting (pid: 13)
[2025-09-04 22:40:47 +0000] [34] [INFO] Booting worker with pid: 34
[2025-09-04 22:40:47 +0000] [35] [INFO] Booting worker with pid: 35
[2025-09-04 22:42:54 +0000] [12] [INFO] Starting gunicorn 20.1.0
[2025-09-04 22:42:54 +0000] [12] [INFO] Listening at: http://0.0.0.0:8000 (12)
[2025-09-04 22:42:54 +0000] [12] [INFO] Using worker: sync
[2025-09-04 22:42:54 +0000] [13] [INFO] Booting worker with pid: 13
[2025-09-04 22:42:54 +0000] [14] [INFO] Booting worker with pid: 14
[2025-09-04 22:44:14 +0000] [12] [INFO] Handling signal: term
[2025-09-04 19:44:14 -0300] [13] [INFO] Worker exiting (pid: 13)
[2025-09-04 19:44:14 -0300] [14] [INFO] Worker exiting (pid: 14)
[2025-09-04 22:44:14 +0000] [12] [INFO] Shutting down: Master
